Workbook

Sheet Cover & Instructions
A1: MASTER ESTIMATE WORKBOOK - LINKED FIRST-PRINCIPLES MODEL - REV3 RISK TRUTH
A2: Permanent estimating template. Direct costs originate in Resource Build-Up and flow through QS Takeoff, Tender Build-Up, Summary and Cashflow. Risk Truth controls residual risk treatment and prevents duplicate risk cost paths.
A4: Project | D4: Location
A5: Scope | D5: Base direct estimate excl. GST | E5: ='Tender Build-Up'!B20 -> 0 | F5: Linked from Tender Build-Up
A6: Issue status | B6: MASTER TEMPLATE - populate the current job intake, documents, scope and evidence before pricing. | D6: Issue date | E6: 17-Aug-2026
A7: Estimate basis | B7: Estimate basis must be rebuilt from the current project's drawings, specifications, takeoff, quotes, resource rates, programme and approved backend tools. Do not carry project-specific quantities, assumptions, RFIs or quotations from another job.
A9: HOW THE WORKBOOK WORKS
A10: 1 | B10: Enter/confirm job scope, item codes, quantities and takeoff references in QS Takeoff.
A11: 2 | B11: For every active QS Code, allocate labour, plant, materials, cartage/testing or subcontract resources in Resource Build-Up.
A12: 3 | B12: Maintain reusable current rates and sources in Resource Rate Library; use Job Rate Override in Resource Build-Up for job-specific quotes/rates.
A13: 4 | B13: QS Rate and Amount calculate from Resource Build-Up. Do not enter a separate QS lump-sum rate.
A14: 5 | B14: Tender Build-Up pulls section totals from QS Takeoff. Commercial Inputs is the only source for below-the-line contingency/overhead and profit/GST/retention provisions.
A15: 6 | B15: Summary pulls the live Tender Build-Up and includes cost-chain integrity checks. All checks must read OK before issue.
A16: 7 | B16: Stage Cashflow pulls tender revenue and Summary direct costs. Only stage timing/%/retention selections are inputs.
A17: 8 | B17: Weather Risk links live weather-exposed labour/plant, programme duration and time-related cost drivers to the approved Weather Tool run, then feeds CA10. Rerun the tool when its input gate changes.
A18: CORE WORKING TABS - LINKED COST, PROGRAMME, WEATHER AND RISK CONTROLS
A19: Cover & Instructions | B19: Job basis, document register, assumptions/RFIs, risks and release QA
A20: Summary | B20: Client/management summary plus end-to-end cost-chain integrity
A21: QS Takeoff | B21: Measured items/quantities; rate and amount are linked outputs from Resource Build-Up
A22: Resource Build-Up | B22: Direct-cost source of truth by QS Code: methodology, productivity and every allocated resource
A23: Resource Rate Library | B23: Reusable company resource master. Retain all resources across jobs; update verified rates/sources centrally. Heavy-access, crane, rigging, cartage and testing resources are reusable library codes; job-specific rates remain job overrides.
A24: Tender Build-Up | B24: QS section totals plus formula-linked commercial build-up
A25: Commercial Inputs | B25: Below-the-line commercial/risk/overhead/profit/GST/retention controls. CA01/CA02 can select Risk Engine / PC Sum / %; CA10 can select Weather Engine / PC Sum / %. Include? is the on/off switch and engine outputs remain live for audit.
A26: Stage Cashflow | B26: Formula-linked stage revenue, direct cost allocation and cashflow
A27: Weather Risk | B27: Approved weather-tool integration, exposed-resource audit, programme/calendar effects, weather cost buckets and rerun gate
A28: Risk Truth | B28: Risk-control and reconciliation module: tender baseline, residual exposure, duplication controls, integration target and release gate
A29: Yellow | B29: Intended input cells.
A30: Green / linked | B30: Formula-controlled outputs. Stop validation blocks ordinary edits and directs the estimator to the upstream source.
... A33: Template rule | B33: Every direct cost must have a QS Code and resource origin. Every commercial allowance must have a selected method, stated basis and Include? status. Engine outputs remain separate from manual PC/% overrides so the evidence trail is never destroyed.
A35: STREAMLINED LINKED MODEL - WORKBOOK FLOW & JOB CONTROLS
A37: Cost chain | B37: Resource Rate Library -> Resource Build-Up -> QS Takeoff -> Tender Build-Up -> Summary
A38: Commercial chain | B38: Commercial Inputs -> Tender Build-Up -> Summary
A39: Cashflow chain | B39: Tender total -> Stage Cashflow
A40: Direct cost rule | B40: No direct-cost lump sum is typed into QS, Tender Build-Up or Summary. Every QS item cost must be created in Resource Build-Up using the same QS Code.
A41: Input rule | B41: Yellow cells are intended inputs. Green/grey linked cells are formula outputs. Method selectors choose the pricing source; Include? controls whether that source enters the tender.
A42: Allowances / quotes | B42: Allowances, PC sums and specialist quotes still require a Resource Build-Up row (normally Lump Sum / Quote mode) unless they are below-the-line Commercial Inputs.
A43: Issue gate | B43: Summary cost-chain checks must all read OK before tender issue.
A44: Risk Truth | B44: Risk-control and reconciliation module. Tracks baseline vs residual exposure, prevents duplicate cost paths and routes risk once to QS, CA01/CA02 or specialist engines.
A46: DRAWING / DOCUMENT REGISTER
A47: Document / Drawing | B47: Reference | C47: Estimate use
...

Sheet Summary
A1: MASTER ESTIMATE WORKBOOK - ESTIMATE SUMMARY - REV3 RISK TRUTH
A2: Base direct costs are linked from Resource Build-Up through QS Takeoff. Commercial provisions are controlled through Commercial Inputs. CA01/CA02 default to Risk Truth, CA10 defaults to Weather Risk, and explicit PC Sum / % overrides remain visible and auditable.
A3: Project
A4: Location
A5: Drawing set
A6: Issue status | B6: MASTER TEMPLATE - not for issue until current project inputs and release gates are complete.
A7: Issue date | B7: 17-Aug-2026
A8: Source file
A9: Prepared
A10: Prepared by
A11: Scope basis
A12: Key Quantities
A13: Category | B13: Key item | C13: Quantity | D13: Unit | E13: Basis / note
A21: Pricing Summary (direct-cost estimate)
A22: Section | B22: Amount
A23: 1 Preliminaries & General | B23: ='Tender Build-Up'!B10 -> 0
A24: 2 Erosion & Sediment Control | B24: ='Tender Build-Up'!B11 -> 0
A25: 3 Earthworks | B25: ='Tender Build-Up'!B12 -> 0
A26: 4 Stormwater & Detention | B26: ='Tender Build-Up'!B13 -> 0
A27: 5 Wastewater & Water | B27: ='Tender Build-Up'!B14 -> 0
A28: 6 Pavements & Concrete | B28: ='Tender Build-Up'!B15 -> 0
A29: 7 Kerbs, Channels & External Sitework | B29: ='Tender Build-Up'!B16 -> 0
A30: 8 Retaining Walls | B30: ='Tender Build-Up'!B17 -> 0
A31: 9 Testing, As-Builts & Compliance | B31: ='Tender Build-Up'!B18 -> 0
A32: 10 Reinstatement & Handover | B32: ='Tender Build-Up'!B19 -> 0
A33: Total priced amount excl. GST | B33: ='Tender Build-Up'!B20 -> 0
A34: Pricing basis | B34: Resource-linked direct cost; specialist quote/PC rows are visible in Resource Build-Up.
A35: GST | B35: Resource-linked direct cost; current project PC/provisional/quoted items must be visible in Resource Build-Up and QS Takeoff.
A36: Scope | B36: Rates exclude GST unless the optional tax display is activated in Commercial Inputs.
A37: Accuracy | B37: Measured, provided, calculated, allowance/PC and quoted items must retain current source references and verification status.
A38: Programme basis | B38: Programme basis must reconcile working days, productive crew days, elapsed calendar duration, time-related costs and applicable Weather Risk outputs.
A39: Tender Completion Build-Up (client-adjustable commercial provisions)
A40: Purpose | B40: This block reflects Tender Build-Up and current Commercial Inputs selections.
A41: Input sheet | B41: Use Commercial Inputs to adjust allowances, overhead and profit method, bonds, retention finance and GST.
A43: Line
A44: Base direct estimate excl. GST | B44: ='Tender Build-Up'!B20 -> 0 | E44: QS direct-cost estimate
A45: Pre-margin additions | B45: ='Tender Build-Up'!B39 -> 0 | E45: Commercial Inputs CA01-CA16
A46: Commercial adjustments | B46: ='Tender Build-Up'!B46 -> 0
A47: Tender total excl. GST | B47: ='Tender Build-Up'!B47 -> 0
A48: GST if selected | B48: ='Tender Build-Up'!B48 -> 0 | E48: Optional display
...

Sheet Tender Build-Up
A1: MASTER ESTIMATE WORKBOOK - TENDER BUILD-UP - REV2 RISK TRUTH
A3: Project
A4: Pricing status | B4: MASTER TEMPLATE - project-specific scope, quantities, rates, programme and commercial inputs not yet populated.
A5: GST | B5: Optional GST display via Commercial Inputs CA21.
A6: Retention | B6: Cashflow only by default.
A7: No direct-cost values are entered on this sheet. Base costs flow from QS Takeoff; commercial provisions flow from Commercial Inputs.
A9: Base direct estimate | B9: Amount excl. GST | C9: Source | D9: Treatment | E9: Notes
A10: Preliminaries & General | B10: =SUM('QS Takeoff'!G3:G12) -> 0 | C10: QS Takeoff | D10: Priced / provisional | E10: Linked QS section total; confirm current project scope, classification, source and firm-up action.
A11: Erosion & Sediment Control | B11: =SUM('QS Takeoff'!G13:G20) -> 0 | C11: QS Takeoff | D11: Priced / provisional | E11: Linked QS section total; confirm current project ESC scope and requirements.
A12: Earthworks | B12: =SUM('QS Takeoff'!G21:G30) -> 0 | C12: QS Takeoff | D12: Priced / provisional | E12: Linked QS section total; confirm current project quantities, ground basis, haul and disposal assumptions.
A13: Stormwater & Detention | B13: =SUM('QS Takeoff'!G31:G39) -> 0 | C13: QS Takeoff | D13: Priced / provisional | E13: Linked QS section total; confirm current project stormwater / detention design and supplier requirements.
A14: Wastewater & Water | B14: =SUM('QS Takeoff'!G40:G46) -> 0 | C14: QS Takeoff | D14: Priced / provisional | E14: Linked QS section total; confirm current project wastewater / water scope and authority interfaces.
A15: Pavements & Concrete | B15: =SUM('QS Takeoff'!G47:G52) -> 0 | C15: QS Takeoff | D15: Priced / provisional | E15: Linked QS section total; confirm current project pavement / concrete scope and specification.
A16: Kerbs, Channels & External Sitework | B16: =SUM('QS Takeoff'!G53:G61) -> 0 | C16: QS Takeoff | D16: Priced / provisional | E16: Linked QS section total; confirm current project kerb / external sitework scope.
A17: Retaining Walls | B17: =SUM('QS Takeoff'!G62:G67) -> 0 | C17: QS Takeoff | D17: Priced / provisional | E17: Linked QS section total; confirm current project retaining-wall design, quantities and temporary works.
A18: Testing, As-Builts & Compliance | B18: =SUM('QS Takeoff'!G68:G69) -> 0 | C18: QS Takeoff | D18: Priced / provisional | E18: Linked QS section total; confirm current testing, survey, as-built and compliance obligations.
A19: Reinstatement & Handover | B19: =SUM('QS Takeoff'!G70:G73) -> 0 | C19: QS Takeoff | D19: Priced / provisional | E19: Linked QS section total; confirm current reinstatement, defects and handover obligations.
A20: Base direct estimate excl. GST | B20: =SUM(B10:B19) -> 0 | D20: Subtotal | E20: Direct cost sourced from Resource Build-Up through QS Takeoff; includes measured, provisional, allowance and PC items.
A22: Pre-margin additions | B22: Calculated amount excl. GST | C22: Input source | D22: Include? | E22: Basis / Notes
A23: CA01 - Design / scope residual risk - Risk Truth | B23: =IF('Commercial Inputs'!$F$5<>"Yes",0,IF(OR('Commercial Inputs'!$C$5="Risk Engine",'Commercial Inputs'!$C$5="Weather Engine"),N('Commercial Inputs'!$L$5),IF('Commercial Inputs'!$C$5="PC Sum",N('Commercial Inputs'!$E$5),IF('Commercial Inputs'!$C$5="%",$B$20*N('Commercial Inputs'!$D$5),0)))) -> 0 | C23: ='Commercial Inputs'!C5 -> Risk Engine | D23: ='Commercial Inputs'!F5 -> Yes | E23: CA01 defaults to Risk Truth. PC Sum or % may be selected as a stated adjudication override; Include? controls whether the selected treatment enters the tender.
A24: CA02 - Construction / execution residual risk - Risk Truth | B24: =IF('Commercial Inputs'!$F$6<>"Yes",0,IF(OR('Commercial Inputs'!$C$6="Risk Engine",'Commercial Inputs'!$C$6="Weather Engine"),N('Commercial Inputs'!$L$6),IF('Commercial Inputs'!$C$6="PC Sum",N('Commercial Inputs'!$E$6),IF('Commercial Inputs'!$C$6="%",$B$20*N('Commercial Inputs'!$D$6),0)))) -> 0 | C24: ='Commercial Inputs'!C6 -> Risk Engine | D24: ='Commercial Inputs'!F6 -> Yes | E24: CA02 defaults to Risk Truth. PC Sum or % may be selected as a stated adjudication override; Include? controls whether the selected treatment enters the tender.
A25: ='Commercial Inputs'!A7&" - "&'Commercial Inputs'!B7 -> CA03 - Escalation / tender validity allowance | B25: =IF('Commercial Inputs'!$F$7<>"Yes",0,IF(OR('Commercial Inputs'!$C$7="Risk Engine",'Commercial Inputs'!$C$7="Weather Engine"),N('Commercial Inputs'!$L$7),IF('Commercial Inputs'!$C$7="PC Sum",N('Commercial Inputs'!$E$7),IF('Commercial Inputs'!$C$7="%",$B$20*N('Commercial Inputs'!$D$7),0)))) -> 0 | C25: ='Commercial Inputs'!C7 -> % | D25: ='Commercial Inputs'!F7 -> No | E25: ='Commercial Inputs'!I7 -> Enter only where escalation is evidence-based; do not default to a generic percentage.
A26: ='Commercial Inputs'!A8&" - "&'Commercial Inputs'!B8 -> CA04 - Final subcontractor quote gap / market adjustment | B26: =IF('Commercial Inputs'!$F$8<>"Yes",0,IF(OR('Commercial Inputs'!$C$8="Risk Engine",'Commercial Inputs'!$C$8="Weather Engine"),N('Commercial Inputs'!$L$8),IF('Commercial Inputs'!$C$8="PC Sum",N('Commercial Inputs'!$E$8),IF('Commercial Inputs'!$C$8="%",$B$20*N('Commercial Inputs'!$D$8),0)))) -> 0 | C26: ='Commercial Inputs'!C8 -> PC Sum | D26: ='Commercial Inputs'!F8 -> No | E26: ='Commercial Inputs'!I8 -> Use only for a distinct reconciled live-quote gap not already included in QS/PC items or Risk Truth.
A27: ='Commercial Inputs'!A9&" - "&'Commercial Inputs'!B9 -> CA05 - Council / authority consent and inspection fees | B27: =IF('Commercial Inputs'!$F$9<>"Yes",0,IF(OR('Commercial Inputs'!$C$9="Risk Engine",'Commercial Inputs'!$C$9="Weather Engine"),N('Commercial Inputs'!$L$9),IF('Commercial Inputs'!$C$9="PC Sum",N('Commercial Inputs'!$E$9),IF('Commercial Inputs'!$C$9="%",$B$20*N('Commercial Inputs'!$D$9),0)))) -> 0 | C27: ='Commercial Inputs'!C9 -> PC Sum | D27: ='Commercial Inputs'!F9 -> No | E27: ='Commercial Inputs'!I9 -> Confirm contractual responsibility before inclusion.
A28: ='Commercial Inputs'!A10&" - "&'Commercial Inputs'!B10 -> CA06 - Utility authority fees / relocations | B28: =IF('Commercial Inputs'!$F$10<>"Yes",0,IF(OR('Commercial Inputs'!$C$10="Risk Engine",'Commercial Inputs'!$C$10="Weather Engine"),N('Commercial Inputs'!$L$10),IF('Commercial Inputs'!$C$10="PC Sum",N('Commercial Inputs'!$E$10),IF('Commercial Inputs'!$C$10="%",$B$20*N('Commercial Inputs'!$D$10),0)))) -> 0 | C28: ='Commercial Inputs'!C10 -> PC Sum | D28: ='Commercial Inputs'!F10 -> No | E28: ='Commercial Inputs'!I10 -> Confirm contractual responsibility; physical construction scope should normally sit in QS.
A29: ='Commercial Inputs'!A11&" - "&'Commercial Inputs'!B11 -> CA07 - Temporary works engineering / PS documentation | B29: =IF('Commercial Inputs'!$F$11<>"Yes",0,IF(OR('Commercial Inputs'!$C$11="Risk Engine",'Commercial Inputs'!$C$11="Weather Engine"),N('Commercial Inputs'!$L$11),IF('Commercial Inputs'!$C$11="PC Sum",N('Commercial Inputs'!$E$11),IF('Commercial Inputs'!$C$11="%",$B$20*N('Commercial Inputs'!$D$11),0)))) -> 0 | C29: ='Commercial Inputs'!C11 -> PC Sum | D29: ='Commercial Inputs'!F11 -> No | E29: ='Commercial Inputs'!I11 -> Use only for temporary-works engineering / documentation not already in direct scope.
A30: CA08 - Abnormal ground / contamination / rock allowance | B30: =IF('Commercial Inputs'!$F$12<>"Yes",0,IF(OR('Commercial Inputs'!$C$12="Risk Engine",'Commercial Inputs'!$C$12="Weather Engine"),N('Commercial Inputs'!$L$12),IF('Commercial Inputs'!$C$12="PC Sum",N('Commercial Inputs'!$E$12),IF('Commercial Inputs'!$C$12="%",$B$20*N('Commercial Inputs'!$D$12),0)))) -> 0 | C30: ='Commercial Inputs'!C12 -> PC Sum | D30: ='Commercial Inputs'!F12 -> No | E30: No generic ground percentage. Use only an explicit evidence-based provision not more truthfully placed in QS or a specialist engine.
A31: ='Commercial Inputs'!A13&" - "&'Commercial Inputs'!B13 -> CA09 - Construction dewatering / groundwater control | B31: =IF('Commercial Inputs'!$F$13<>"Yes",0,IF(OR('Commercial Inputs'!$C$13="Risk Engine",'Commercial Inputs'!$C$13="Weather Engine"),N('Commercial Inputs'!$L$13),IF('Commercial Inputs'!$C$13="PC Sum",N('Commercial Inputs'!$E$13),IF('Commercial Inputs'!$C$13="%",$B$20*N('Commercial Inputs'!$D$13),0)))) -> 0 | C31: ='Commercial Inputs'!C13 -> PC Sum | D31: ='Commercial Inputs'!F13 -> No | E31: Project-specific construction water-control provision only; check overlap with Weather / Ground risk treatment.
A32: ='Commercial Inputs'!A14&" - "&'Commercial Inputs'!B14 -> CA10 - Weather risk allowance - linked approved engine | B32: =IF('Commercial Inputs'!$F$14<>"Yes",0,IF(OR('Commercial Inputs'!$C$14="Risk Engine",'Commercial Inputs'!$C$14="Weather Engine"),N('Commercial Inputs'!$L$14),IF('Commercial Inputs'!$C$14="PC Sum",N('Commercial Inputs'!$E$14),IF('Commercial Inputs'!$C$14="%",$B$20*N('Commercial Inputs'!$D$14),0)))) -> 0 | C32: ='Commercial Inputs'!C14 -> Weather Engine | D32: ='Commercial Inputs'!F14 -> Yes | E32: CA10 defaults to Weather Engine. PC Sum or % may be selected explicitly; Include? can turn the weather allowance off while the engine output remains retained for audit.
A33: ='Commercial Inputs'!A15&" - "&'Commercial Inputs'!B15 -> CA11 - Extended preliminaries beyond weather-adjusted tender baseline | B33: =IF('Commercial Inputs'!$F$15<>"Yes",0,IF(OR('Commercial Inputs'!$C$15="Risk Engine",'Commercial Inputs'!$C$15="Weather Engine"),N('Commercial Inputs'!$L$15),IF('Commercial Inputs'!$C$15="PC Sum",N('Commercial Inputs'!$E$15),IF('Commercial Inputs'!$C$15="%",$B$20*N('Commercial Inputs'!$D$15),0)))) -> 0 | C33: ='Commercial Inputs'!C15 -> PC Sum | D33: ='Commercial Inputs'!F15 -> No | E33: ='Commercial Inputs'!I15 -> Do not use for weather delay already included through CA10. Base QS preliminaries remain reconciled to 99 working days.
A34: ='Commercial Inputs'!A16&" - "&'Commercial Inputs'!B16 -> CA12 - Defects liability / maintenance beyond base | B34: =IF('Commercial Inputs'!$F$16<>"Yes",0,IF(OR('Commercial Inputs'!$C$16="Risk Engine",'Commercial Inputs'!$C$16="Weather Engine"),N('Commercial Inputs'!$L$16),IF('Commercial Inputs'!$C$16="PC Sum",N('Commercial Inputs'!$E$16),IF('Commercial Inputs'!$C$16="%",$B$20*N('Commercial Inputs'!$D$16),0)))) -> 0 | C34: ='Commercial Inputs'!C16 -> PC Sum | D34: ='Commercial Inputs'!F16 -> No | E34: ='Commercial Inputs'!I16 -> Reasonable defects attendance included under RH02.
A35: ='Commercial Inputs'!A17&" - "&'Commercial Inputs'!B17 -> CA13 - Stakeholder liaison / access marshals beyond base | B35: =IF('Commercial Inputs'!$F$17<>"Yes",0,IF(OR('Commercial Inputs'!$C$17="Risk Engine",'Commercial Inputs'!$C$17="Weather Engine"),N('Commercial Inputs'!$L$17),IF('Commercial Inputs'!$C$17="PC Sum",N('Commercial Inputs'!$E$17),IF('Commercial Inputs'!$C$17="%",$B$20*N('Commercial Inputs'!$D$17),0)))) -> 0 | C35: ='Commercial Inputs'!C17 -> PC Sum | D35: ='Commercial Inputs'!F17 -> No | E35: ='Commercial Inputs'!I17 -> Basic traffic/pedestrian management included in PG07.
A36: ='Commercial Inputs'!A18&" - "&'Commercial Inputs'!B18 -> CA14 - Out-of-hours / restricted access premium | B36: =IF('Commercial Inputs'!$F$18<>"Yes",0,IF(OR('Commercial Inputs'!$C$18="Risk Engine",'Commercial Inputs'!$C$18="Weather Engine"),N('Commercial Inputs'!$L$18),IF('Commercial Inputs'!$C$18="PC Sum",N('Commercial Inputs'!$E$18),IF('Commercial Inputs'!$C$18="%",$B$20*N('Commercial Inputs'!$D$18),0)))) -> 0 | C36: ='Commercial Inputs'!C18 -> PC Sum | D36: ='Commercial Inputs'!F18 -> No | E36: ='Commercial Inputs'!I18 -> Normal weekday access assumed.
A37: ='Commercial Inputs'!A19&" - "&'Commercial Inputs'!B19 -> CA15 - Unforeseen post-tender client scope additions | B37: =IF('Commercial Inputs'!$F$19<>"Yes",0,IF(OR('Commercial Inputs'!$C$19="Risk Engine",'Commercial Inputs'!$C$19="Weather Engine"),N('Commercial Inputs'!$L$19),IF('Commercial Inputs'!$C$19="PC Sum",N('Commercial Inputs'!$E$19),IF('Commercial Inputs'!$C$19="%",$B$20*N('Commercial Inputs'!$D$19),0)))) -> 0 | C37: ='Commercial Inputs'!C19 -> PC Sum | D37: ='Commercial Inputs'!F19 -> No | E37: ='Commercial Inputs'!I19 -> No allowance for later scope changes.
A38: ='Commercial Inputs'!A20&" - "&'Commercial Inputs'!B20 -> CA16 - Final tender rounding / adjudication adjustment | B38: =IF('Commercial Inputs'!$F$20<>"Yes",0,IF(OR('Commercial Inputs'!$C$20="Risk Engine",'Commercial Inputs'!$C$20="Weather Engine"),N('Commercial Inputs'!$L$20),IF('Commercial Inputs'!$C$20="PC Sum",N('Commercial Inputs'!$E$20),IF('Commercial Inputs'!$C$20="%",$B$20*N('Commercial Inputs'!$D$20),0)))) -> 0 | C38: ='Commercial Inputs'!C20 -> PC Sum | D38: ='Commercial Inputs'!F20 -> No | E38: ='Commercial Inputs'!I20 -> No balancing adjustment applied.
A39: Pre-margin additions subtotal | B39: =SUM(B23:B38) -> 0
A40: Subtotal before commercial adjustments | B40: =B20+B39 -> 0
A41: Overhead, profit and other commercial adjustments | B41: Calculated amount excl. GST | C41: Input source | D41: Include? | E41: Basis / Notes
A42: ='Commercial Inputs'!A21&" - "&'Commercial Inputs'!B21 -> CA17 - Company overhead recovery | B42: =IF('Commercial Inputs'!$F$21<>"Yes",0,IF('Commercial Inputs'!$C$21="Markup %",$B$40*N('Commercial Inputs'!$D$21),IF('Commercial Inputs'!$C$21="Fixed Amount",N('Commercial Inputs'!$E$21),0))) -> 0 | C42: ='Commercial Inputs'!C21 -> Markup % | D42: ='Commercial Inputs'!F21 -> No | E42: ='Commercial Inputs'!I21 -> Enter verified company overhead recovery separately from contractor profit.
A43: ='Commercial Inputs'!A22&" - "&'Commercial Inputs'!B22 -> CA18 - Contractor profit | B43: =IF('Commercial Inputs'!$F$22<>"Yes",0,IF('Commercial Inputs'!$C$22="Margin %",($B$40+$B$42+$B$44+$B$45)/(1-N('Commercial Inputs'!$D$22))-($B$40+$B$42+$B$44+$B$45),IF('Commercial Inputs'!$C$22="Markup %",($B$40+$B$42+$B$44+$B$45)*N('Commercial Inputs'!$D$22),IF('Commercial Inputs'!$C$22="Fixed Amount",N('Commercial Inputs'!$E$22),0)))) -> 0 | C43: ='Commercial Inputs'!C22 -> Margin % | D43: ='Commercial Inputs'!F22 -> No | E43: ='Commercial Inputs'!I22 -> Enter approved contractor profit; choose Margin or Markup in the profit-method selector.
...

Sheet Commercial Inputs
A1: COMMERCIAL INPUTS - BELOW-THE-LINE SOURCE OF TRUTH | H1: Profit method | I1: =C22 -> Margin %
H2: CA18 method (linked) | I2: =IF(C22="Margin %","Margin",IF(C22="Markup %","Markup",IF(C22="Fixed Amount","Fixed Amount",C22))) -> Margin | J2: The calculation method is selected in column C. There is no second profit-method selector.
A3: CA01/CA02: Risk Engine, PC Sum or %. CA10: Weather Engine, PC Sum or %. Other pre-margin allowances: PC Sum or %. Column F Include? is the on/off switch. Engine outputs remain live in column L even when another method is selected, preserving the audit trail.
A4: Ref | B4: Allowance / adjustment | C4: Input method | D4: Input % | E4: PC Sum excl. GST | F4: Include? | G4: Pricing stage | H4: Calculation / treatment | I4: Notes / basis | J4: Firm-up action | K4: Pricing method / flag shown in QS | L4: Engine Amount excl. GST | M4: Engine Source / Status
A5: CA01 | B5: Design / scope residual risk - Risk Truth linked | C5: Risk Engine | F5: Yes | G5: Pre-margin addition | H5: =IF(C5="Risk Engine","Uses linked Risk Truth engine amount in L5",IF(C5="Weather Engine","Uses linked Weather Risk amount in L5",IF(C5="PC Sum","Uses manual PC Sum in E5",IF(C5="%","Uses Input % in D5 against base direct cost","CHECK METHOD")))) -> Uses linked Risk Truth engine amount in L5 | I5: Residual design/scope risk only where the consequence cannot be more truthfully placed in Resource Build-Up/QS or a specialist engine. | J5: Close Risk Truth RED items and confirm residual is distinct / integration complete. | K5: =IF(F5<>"Yes",C5&" - OFF",C5) -> Risk Engine | L5: ='Risk Truth'!$B$12 -> 0 | M5: Risk Truth CA01 design/scope residual
A6: CA02 | B6: Construction / execution residual risk - Risk Truth linked | C6: Risk Engine | F6: Yes | G6: Pre-margin addition | H6: =IF(C6="Risk Engine","Uses linked Risk Truth engine amount in L6",IF(C6="Weather Engine","Uses linked Weather Risk amount in L6",IF(C6="PC Sum","Uses manual PC Sum in E6",IF(C6="%","Uses Input % in D6 against base direct cost","CHECK METHOD")))) -> Uses linked Risk Truth engine amount in L6 | I6: Residual construction/execution risk only where the consequence cannot be more truthfully placed in Resource Build-Up/QS or a specialist engine. | J6: Close Risk Truth RED items and confirm residual is distinct / integration complete. | K6: =IF(F6<>"Yes",C6&" - OFF",C6) -> Risk Engine | L6: ='Risk Truth'!$B$13 -> 0 | M6: Risk Truth CA02 construction/execution residual
A7: CA03 | B7: Escalation / tender validity allowance | C7: % | D7: 0 | F7: No | G7: Pre-margin addition | H7: =IF(C7="Risk Engine","Uses linked Risk Truth engine amount in L7",IF(C7="Weather Engine","Uses linked Weather Risk amount in L7",IF(C7="PC Sum","Uses manual PC Sum in E7",IF(C7="%","Uses Input % in D7 against base direct cost","CHECK METHOD")))) -> Uses Input % in D7 against base direct cost | I7: Enter only where escalation is evidence-based; do not default to a generic percentage. | J7: Confirm construction start and validity. | K7: =IF(F7<>"Yes",C7&" - OFF",C7) -> % - OFF | L7: 0 | M7: No specialist engine linked - select PC Sum or %
A8: CA04 | B8: Final subcontractor quote gap / market adjustment | C8: PC Sum | F8: No | G8: Pre-margin addition | H8: =IF(C8="Risk Engine","Uses linked Risk Truth engine amount in L8",IF(C8="Weather Engine","Uses linked Weather Risk amount in L8",IF(C8="PC Sum","Uses manual PC Sum in E8",IF(C8="%","Uses Input % in D8 against base direct cost","CHECK METHOD")))) -> Uses manual PC Sum in E8 | I8: Use only for a distinct reconciled live-quote gap not already included in QS/PC items or Risk Truth. | J8: Reconcile tank, walls and connections. | K8: =IF(F8<>"Yes",C8&" - OFF",C8) -> PC Sum - OFF | L8: 0 | M8: No specialist engine linked - select PC Sum or %
A9: CA05 | B9: Council / authority consent and inspection fees | C9: PC Sum | F9: No | G9: Pre-margin addition | H9: =IF(C9="Risk Engine","Uses linked Risk Truth engine amount in L9",IF(C9="Weather Engine","Uses linked Weather Risk amount in L9",IF(C9="PC Sum","Uses manual PC Sum in E9",IF(C9="%","Uses Input % in D9 against base direct cost","CHECK METHOD")))) -> Uses manual PC Sum in E9 | I9: Confirm contractual responsibility before inclusion. | J9: Confirm fee responsibility. | K9: =IF(F9<>"Yes",C9&" - OFF",C9) -> PC Sum - OFF | L9: 0 | M9: No specialist engine linked - select PC Sum or %
A10: CA06 | B10: Utility authority fees / relocations | C10: PC Sum | F10: No | G10: Pre-margin addition | H10: =IF(C10="Risk Engine","Uses linked Risk Truth engine amount in L10",IF(C10="Weather Engine","Uses linked Weather Risk amount in L10",IF(C10="PC Sum","Uses manual PC Sum in E10",IF(C10="%","Uses Input % in D10 against base direct cost","CHECK METHOD")))) -> Uses manual PC Sum in E10 | I10: Confirm contractual responsibility; physical construction scope should normally sit in QS. | J10: Confirm utilities. | K10: =IF(F10<>"Yes",C10&" - OFF",C10) -> PC Sum - OFF | L10: 0 | M10: No specialist engine linked - select PC Sum or %
A11: CA07 | B11: Temporary works engineering / PS documentation | C11: PC Sum | F11: No | G11: Pre-margin addition | H11: =IF(C11="Risk Engine","Uses linked Risk Truth engine amount in L11",IF(C11="Weather Engine","Uses linked Weather Risk amount in L11",IF(C11="PC Sum","Uses manual PC Sum in E11",IF(C11="%","Uses Input % in D11 against base direct cost","CHECK METHOD")))) -> Uses manual PC Sum in E11 | I11: Use only for temporary-works engineering / documentation not already in direct scope. | J11: Avoid duplication. | K11: =IF(F11<>"Yes",C11&" - OFF",C11) -> PC Sum - OFF | L11: 0 | M11: No specialist engine linked - select PC Sum or %
A12: CA08 | B12: Abnormal ground / contamination / rock allowance | C12: PC Sum | D12: 0 | F12: No | G12: Pre-margin addition | H12: =IF(C12="Risk Engine","Uses linked Risk Truth engine amount in L12",IF(C12="Weather Engine","Uses linked Weather Risk amount in L12",IF(C12="PC Sum","Uses manual PC Sum in E12",IF(C12="%","Uses Input % in D12 against base direct cost","CHECK METHOD")))) -> Uses manual PC Sum in E12 | I12: Do not use as a generic ground-risk percentage. Quantifiable ground consequences belong in QS or an approved specialist risk treatment. | J12: Review geotech/contamination data. | K12: =IF(F12<>"Yes",C12&" - OFF",C12) -> PC Sum - OFF | L12: 0 | M12: No specialist engine linked - select PC Sum or %
A13: CA09 | B13: Construction dewatering / groundwater control | C13: PC Sum | F13: No | G13: Pre-margin addition | H13: =IF(C13="Risk Engine","Uses linked Risk Truth engine amount in L13",IF(C13="Weather Engine","Uses linked Weather Risk amount in L13",IF(C13="PC Sum","Uses manual PC Sum in E13",IF(C13="%","Uses Input % in D13 against base direct cost","CHECK METHOD")))) -> Uses manual PC Sum in E13 | I13: Project-specific construction water-control allowance only; check Weather / Ground overlap before inclusion. | J13: Confirm methodology/groundwater. | K13: =IF(F13<>"Yes",C13&" - OFF",C13) -> PC Sum - OFF | L13: 0 | M13: No specialist engine linked - select PC Sum or %
A14: CA10 | B14: Weather risk allowance - linked approved engine | C14: Weather Engine | F14: Yes | G14: Pre-margin addition | H14: =IF(C14="Risk Engine","Uses linked Risk Truth engine amount in L14",IF(C14="Weather Engine","Uses linked Weather Risk amount in L14",IF(C14="PC Sum","Uses manual PC Sum in E14",IF(C14="%","Uses Input % in D14 against base direct cost","CHECK METHOD")))) -> Uses linked Weather Risk amount in L14 | I14: Formula-linked approved Weather Risk output. Do not duplicate normal weather in CA02 or direct productivity. | J14: Rerun Weather Tool if start date, baseline duration, exposed resource cost/mix, work calendar or critical path changes. | K14: =IF(F14<>"Yes",C14&" - OFF",C14) -> Weather Engine | L14: ='Weather Risk'!$B$40 -> 0 | M14: Weather Risk specialist engine -> CA10
A15: CA11 | B15: Extended preliminaries beyond weather-adjusted tender baseline | C15: PC Sum | F15: No | G15: Pre-margin addition | H15: =IF(C15="Risk Engine","Uses linked Risk Truth engine amount in L15",IF(C15="Weather Engine","Uses linked Weather Risk amount in L15",IF(C15="PC Sum","Uses manual PC Sum in E15",IF(C15="%","Uses Input % in D15 against base direct cost","CHECK METHOD")))) -> Uses manual PC Sum in E15 | I15: Do not use for weather delay already included through CA10. Base QS preliminaries remain reconciled to 99 working days. | J15: Add only for non-weather instructed extension or revised contract programme after checking CA10 overlap. | K15: =IF(F15<>"Yes",C15&" - OFF",C15) -> PC Sum - OFF | L15: 0 | M15: No specialist engine linked - select PC Sum or %
A16: CA12 | B16: Defects liability / maintenance beyond base | C16: PC Sum | F16: No | G16: Pre-margin addition | H16: =IF(C16="Risk Engine","Uses linked Risk Truth engine amount in L16",IF(C16="Weather Engine","Uses linked Weather Risk amount in L16",IF(C16="PC Sum","Uses manual PC Sum in E16",IF(C16="%","Uses Input % in D16 against base direct cost","CHECK METHOD")))) -> Uses manual PC Sum in E16 | I16: Reasonable defects attendance included under RH02. | J16: Confirm special maintenance obligations. | K16: =IF(F16<>"Yes",C16&" - OFF",C16) -> PC Sum - OFF | L16: 0 | M16: No specialist engine linked - select PC Sum or %
A17: CA13 | B17: Stakeholder liaison / access marshals beyond base | C17: PC Sum | F17: No | G17: Pre-margin addition | H17: =IF(C17="Risk Engine","Uses linked Risk Truth engine amount in L17",IF(C17="Weather Engine","Uses linked Weather Risk amount in L17",IF(C17="PC Sum","Uses manual PC Sum in E17",IF(C17="%","Uses Input % in D17 against base direct cost","CHECK METHOD")))) -> Uses manual PC Sum in E17 | I17: Basic traffic/pedestrian management included in PG07. | J17: Confirm restricted operations. | K17: =IF(F17<>"Yes",C17&" - OFF",C17) -> PC Sum - OFF | L17: 0 | M17: No specialist engine linked - select PC Sum or %
A18: CA14 | B18: Out-of-hours / restricted access premium | C18: PC Sum | F18: No | G18: Pre-margin addition | H18: =IF(C18="Risk Engine","Uses linked Risk Truth engine amount in L18",IF(C18="Weather Engine","Uses linked Weather Risk amount in L18",IF(C18="PC Sum","Uses manual PC Sum in E18",IF(C18="%","Uses Input % in D18 against base direct cost","CHECK METHOD")))) -> Uses manual PC Sum in E18 | I18: Normal weekday access assumed. | J18: Confirm work windows. | K18: =IF(F18<>"Yes",C18&" - OFF",C18) -> PC Sum - OFF | L18: 0 | M18: No specialist engine linked - select PC Sum or %
A19: CA15 | B19: Unforeseen post-tender client scope additions | C19: PC Sum | F19: No | G19: Pre-margin addition | H19: =IF(C19="Risk Engine","Uses linked Risk Truth engine amount in L19",IF(C19="Weather Engine","Uses linked Weather Risk amount in L19",IF(C19="PC Sum","Uses manual PC Sum in E19",IF(C19="%","Uses Input % in D19 against base direct cost","CHECK METHOD")))) -> Uses manual PC Sum in E19 | I19: No allowance for later scope changes. | J19: Include only if instructed. | K19: =IF(F19<>"Yes",C19&" - OFF",C19) -> PC Sum - OFF | L19: 0 | M19: No specialist engine linked - select PC Sum or %
A20: CA16 | B20: Final tender rounding / adjudication adjustment | C20: PC Sum | F20: No | G20: Pre-margin addition | H20: =IF(C20="Risk Engine","Uses linked Risk Truth engine amount in L20",IF(C20="Weather Engine","Uses linked Weather Risk amount in L20",IF(C20="PC Sum","Uses manual PC Sum in E20",IF(C20="%","Uses Input % in D20 against base direct cost","CHECK METHOD")))) -> Uses manual PC Sum in E20 | I20: No balancing adjustment applied. | J20: Use only at approved adjudication. | K20: =IF(F20<>"Yes",C20&" - OFF",C20) -> PC Sum - OFF | L20: 0 | M20: No specialist engine linked - select PC Sum or %
A21: CA17 | B21: Company overhead recovery | C21: Markup % | D21: 0 | F21: No | G21: Commercial adjustment | H21: Markup applied to cost subtotal before profit | I21: Enter verified company overhead recovery separately from contractor profit. | J21: Jason to enter the verified company overhead recovery rate. | K21: % user input provision
A22: CA18 | B22: Contractor profit | C22: Margin % | D22: 0 | F22: No | G22: Commercial adjustment | H22: Selectable true margin or markup after overhead and other commercial costs | I22: Enter approved contractor profit; choose Margin or Markup in the profit-method selector. | J22: Confirm the target profit and calculation method at adjudication. | K22: % user input provision
A23: CA19 | B23: Bonds / contract securities allowance | C23: % | D23: 0 | F23: No | G23: Commercial adjustment | H23: Applied if selected | I23: Include only where contract securities create a genuine contractor cost. | J23: Confirm security terms. | K23: % user input provision
A24: CA20 | B24: Retention finance / cashflow cost allowance | C24: % | D24: 0 | F24: No | G24: Commercial adjustment | H24: Applied if selected | I24: Finance cost only; retention withholding itself is a cashflow item. | J24: Confirm retention terms. | K24: % user input provision
A25: CA21 | B25: GST | C25: % | D25: 0.15 | F25: No | G25: Tax | H25: Applied to tender total if selected | I25: Optional tax display. Set 15% for NZ GST or 10% for Australian GST when applicable; estimate control total remains ex tax. | J25: Confirm submission format. | K25: % user input provision
A26: CA22 | B26: Contract retention withholding | C26: % | D26: 0 | F26: No | G26: Cashflow only | H26: Visibility only | I26: Not added to tender price. | J26: Confirm retention cap/terms. | K26: User input
A27: CA23 | B27: Retention holding period | C27: Months | D27: 0 | F27: No | G27: Cashflow only | H27: Times retention release | I27: Assumed 12 months. | J27: Confirm contract. | K27: % user input provision
A28: CA24 | B28: Deposit / advance payment | C28: % | D28: 0 | F28: No | G28: Cashflow only | H28: Part of tender value | I28: Used as first cashflow stage. | J28: Confirm whether permitted. | K28: User selection
A29: CA25 | B29: Retention applies to deposit | C29: Selection | F29: No | G29: Cashflow only | H29: Yes/No selection | I29: Normally No. | J29: Confirm contract.
A30: Notes
A31: 1 | B31: Leave Include? as No for any provision that is not to be included. Enter Input % or PC Sum depending on the intended basis; PC Sum overrides % where populated.
A32: 2 | B32: Retentions are included as cashflow/security visibility only. They do not increase the tender price unless CA20 retention finance/cashflow cost is included.
A33: 3 | B33: The deposit and stage cashflow are portions of the tender total, not additional revenue. Stage percentages must total 100%.

Sheet QS Takeoff
A1: QS TAKEOFF - MASTER ESTIMATE WORKBOOK REV2 - RESOURCE-LINKED | L1: Rate and Amount are linked from Resource Build-Up. Change scope/quantity here; change cost resources in Resource Build-Up.
A2: Civil Scope / WBS | B2: Code | C2: Description | D2: Unit | E2: Quantity | F2: Rate excl. GST | G2: Amount excl. GST | H2: Quantity Basis | I2: Source drawing / scope | J2: Status | K2: Notes / Assumptions | L2: Pricing Method | M2: Pricing Basis / Build-up | N2: Source Type | O2: Source URL(s) | P2: Pricing Flag | Q2: Confidence / Firm-up Action | R2: Owner | S2: Verification Status | T2: Quote / Reference
F3: =IF(OR(B3="",E3=0),0,G3/E3) -> 0 | G3: =IF(B3="",0,SUMIF('Resource Build-Up'!$B$7:$B$306,B3,'Resource Build-Up'!$Z$7:$Z$306)) -> 0 | L3: =IF(B3="","",IF(J3="Excluded","Excluded","Resource-linked")) | M3: =IF(B3="","",IF(G3=0,"No resource cost / review","Resource Build-Up -> "&B3)) | N3: =IF(B3="","","Resource Build-Up") | O3: =IF(B3="","","See Resource Build-Up / Resource Rate Library") | P3: =IF(B3="","",IF(COUNTIF('Resource Build-Up'!$B$7:$B$306,B3)=0,IF(G3=0,"ZERO / REVIEW","NO RESOURCE"),"RESOURCE LINKED")) | R3: =IF(OR(ISNUMBER(SEARCH("PC",P3)),ISNUMBER(SEARCH("quote",Q3))),"Jason","Rick") -> Rick | S3: =IF(B3="","",IF(COUNTIF('Resource Build-Up'!$B$7:$B$306,B3)=0,"NO RESOURCE",IF(COUNTIFS('Resource Build-Up'!$B$7:$B$306,B3,'Resource Build-Up'!$AI$7:$AI$306,"<>OK")>0,"RESOURCE QA","LINKED")))
F4: =IF(OR(B4="",E4=0),0,G4/E4) -> 0 | G4: =IF(B4="",0,SUMIF('Resource Build-Up'!$B$7:$B$306,B4,'Resource Build-Up'!$Z$7:$Z$306)) -> 0 | L4: =IF(B4="","",IF(J4="Excluded","Excluded","Resource-linked")) | M4: =IF(B4="","",IF(G4=0,"No resource cost / review","Resource Build-Up -> "&B4)) | N4: =IF(B4="","","Resource Build-Up") | O4: =IF(B4="","","See Resource Build-Up / Resource Rate Library") | P4: =IF(B4="","",IF(COUNTIF('Resource Build-Up'!$B$7:$B$306,B4)=0,IF(G4=0,"ZERO / REVIEW","NO RESOURCE"),"RESOURCE LINKED")) | R4: =IF(OR(ISNUMBER(SEARCH("PC",P4)),ISNUMBER(SEARCH("quote",Q4))),"Jason","Rick") -> Rick | S4: =IF(B4="","",IF(COUNTIF('Resource Build-Up'!$B$7:$B$306,B4)=0,"NO RESOURCE",IF(COUNTIFS('Resource Build-Up'!$B$7:$B$306,B4,'Resource Build-Up'!$AI$7:$AI$306,"<>OK")>0,"RESOURCE QA","LINKED")))
F5: =IF(OR(B5="",E5=0),0,G5/E5) -> 0 | G5: =IF(B5="",0,SUMIF('Resource Build-Up'!$B$7:$B$306,B5,'Resource Build-Up'!$Z$7:$Z$306)) -> 0 | L5: =IF(B5="","",IF(J5="Excluded","Excluded","Resource-linked")) | M5: =IF(B5="","",IF(G5=0,"No resource cost / review","Resource Build-Up -> "&B5)) | N5: =IF(B5="","","Resource Build-Up") | O5: =IF(B5="","","See Resource Build-Up / Resource Rate Library") | P5: =IF(B5="","",IF(COUNTIF('Resource Build-Up'!$B$7:$B$306,B5)=0,IF(G5=0,"ZERO / REVIEW","NO RESOURCE"),"RESOURCE LINKED")) | R5: =IF(OR(ISNUMBER(SEARCH("PC",P5)),ISNUMBER(SEARCH("quote",Q5))),"Jason","Rick") -> Rick | S5: =IF(B5="","",IF(COUNTIF('Resource Build-Up'!$B$7:$B$306,B5)=0,"NO RESOURCE",IF(COUNTIFS('Resource Build-Up'!$B$7:$B$306,B5,'Resource Build-Up'!$AI$7:$AI$306,"<>OK")>0,"RESOURCE QA","LINKED")))
F6: =IF(OR(B6="",E6=0),0,G6/E6) -> 0 | G6: =IF(B6="",0,SUMIF('Resource Build-Up'!$B$7:$B$306,B6,'Resource Build-Up'!$Z$7:$Z$306)) -> 0 | L6: =IF(B6="","",IF(J6="Excluded","Excluded","Resource-linked")) | M6: =IF(B6="","",IF(G6=0,"No resource cost / review","Resource Build-Up -> "&B6)) | N6: =IF(B6="","","Resource Build-Up") | O6: =IF(B6="","","See Resource Build-Up / Resource Rate Library") | P6: =IF(B6="","",IF(COUNTIF('Resource Build-Up'!$B$7:$B$306,B6)=0,IF(G6=0,"ZERO / REVIEW","NO RESOURCE"),"RESOURCE LINKED")) | R6: =IF(OR(ISNUMBER(SEARCH("PC",P6)),ISNUMBER(SEARCH("quote",Q6))),"Jason","Rick") -> Rick | S6: =IF(B6="","",IF(COUNTIF('Resource Build-Up'!$B$7:$B$306,B6)=0,"NO RESOURCE",IF(COUNTIFS('Resource Build-Up'!$B$7:$B$306,B6,'Resource Build-Up'!$AI$7:$AI$306,"<>OK")>0,"RESOURCE QA","LINKED")))
F7: =IF(OR(B7="",E7=0),0,G7/E7) -> 0 | G7: =IF(B7="",0,SUMIF('Resource Build-Up'!$B$7:$B$306,B7,'Resource Build-Up'!$Z$7:$Z$306)) -> 0 | L7: =IF(B7="","",IF(J7="Excluded","Excluded","Resource-linked")) | M7: =IF(B7="","",IF(G7=0,"No resource cost / review","Resource Build-Up -> "&B7)) | N7: =IF(B7="","","Resource Build-Up") | O7: =IF(B7="","","See Resource Build-Up / Resource Rate Library") | P7: =IF(B7="","",IF(COUNTIF('Resource Build-Up'!$B$7:$B$306,B7)=0,IF(G7=0,"ZERO / REVIEW","NO RESOURCE"),"RESOURCE LINKED")) | R7: =IF(OR(ISNUMBER(SEARCH("PC",P7)),ISNUMBER(SEARCH("quote",Q7))),"Jason","Rick") -> Rick | S7: =IF(B7="","",IF(COUNTIF('Resource Build-Up'!$B$7:$B$306,B7)=0,"NO RESOURCE",IF(COUNTIFS('Resource Build-Up'!$B$7:$B$306,B7,'Resource Build-Up'!$AI$7:$AI$306,"<>OK")>0,"RESOURCE QA","LINKED")))
F8: =IF(OR(B8="",E8=0),0,G8/E8) -> 0 | G8: =IF(B8="",0,SUMIF('Resource Build-Up'!$B$7:$B$306,B8,'Resource Build-Up'!$Z$7:$Z$306)) -> 0 | L8: =IF(B8="","",IF(J8="Excluded","Excluded","Resource-linked")) | M8: =IF(B8="","",IF(G8=0,"No resource cost / review","Resource Build-Up -> "&B8)) | N8: =IF(B8="","","Resource Build-Up") | O8: =IF(B8="","","See Resource Build-Up / Resource Rate Library") | P8: =IF(B8="","",IF(COUNTIF('Resource Build-Up'!$B$7:$B$306,B8)=0,IF(G8=0,"ZERO / REVIEW","NO RESOURCE"),"RESOURCE LINKED")) | R8: =IF(OR(ISNUMBER(SEARCH("PC",P8)),ISNUMBER(SEARCH("quote",Q8))),"Jason","Rick") -> Rick | S8: =IF(B8="","",IF(COUNTIF('Resource Build-Up'!$B$7:$B$306,B8)=0,"NO RESOURCE",IF(COUNTIFS('Resource Build-Up'!$B$7:$B$306,B8,'Resource Build-Up'!$AI$7:$AI$306,"<>OK")>0,"RESOURCE QA","LINKED")))
F9: =IF(OR(B9="",E9=0),0,G9/E9) -> 0 | G9: =IF(B9="",0,SUMIF('Resource Build-Up'!$B$7:$B$306,B9,'Resource Build-Up'!$Z$7:$Z$306)) -> 0 | L9: =IF(B9="","",IF(J9="Excluded","Excluded","Resource-linked")) | M9: =IF(B9="","",IF(G9=0,"No resource cost / review","Resource Build-Up -> "&B9)) | N9: =IF(B9="","","Resource Build-Up") | O9: =IF(B9="","","See Resource Build-Up / Resource Rate Library") | P9: =IF(B9="","",IF(COUNTIF('Resource Build-Up'!$B$7:$B$306,B9)=0,IF(G9=0,"ZERO / REVIEW","NO RESOURCE"),"RESOURCE LINKED")) | R9: =IF(OR(ISNUMBER(SEARCH("PC",P9)),ISNUMBER(SEARCH("quote",Q9))),"Jason","Rick") -> Rick | S9: =IF(B9="","",IF(COUNTIF('Resource Build-Up'!$B$7:$B$306,B9)=0,"NO RESOURCE",IF(COUNTIFS('Resource Build-Up'!$B$7:$B$306,B9,'Resource Build-Up'!$AI$7:$AI$306,"<>OK")>0,"RESOURCE QA","LINKED")))
F10: =IF(OR(B10="",E10=0),0,G10/E10) -> 0 | G10: =IF(B10="",0,SUMIF('Resource Build-Up'!$B$7:$B$306,B10,'Resource Build-Up'!$Z$7:$Z$306)) -> 0 | L10: =IF(B10="","",IF(J10="Excluded","Excluded","Resource-linked")) | M10: =IF(B10="","",IF(G10=0,"No resource cost / review","Resource Build-Up -> "&B10)) | N10: =IF(B10="","","Resource Build-Up") | O10: =IF(B10="","","See Resource Build-Up / Resource Rate Library") | P10: =IF(B10="","",IF(COUNTIF('Resource Build-Up'!$B$7:$B$306,B10)=0,IF(G10=0,"ZERO / REVIEW","NO RESOURCE"),"RESOURCE LINKED")) | R10: =IF(OR(ISNUMBER(SEARCH("PC",P10)),ISNUMBER(SEARCH("quote",Q10))),"Jason","Rick") -> Rick | S10: =IF(B10="","",IF(COUNTIF('Resource Build-Up'!$B$7:$B$306,B10)=0,"NO RESOURCE",IF(COUNTIFS('Resource Build-Up'!$B$7:$B$306,B10,'Resource Build-Up'!$AI$7:$AI$306,"<>OK")>0,"RESOURCE QA","LINKED")))
F11: =IF(OR(B11="",E11=0),0,G11/E11) -> 0 | G11: =IF(B11="",0,SUMIF('Resource Build-Up'!$B$7:$B$306,B11,'Resource Build-Up'!$Z$7:$Z$306)) -> 0 | L11: =IF(B11="","",IF(J11="Excluded","Excluded","Resource-linked")) | M11: =IF(B11="","",IF(G11=0,"No resource cost / review","Resource Build-Up -> "&B11)) | N11: =IF(B11="","","Resource Build-Up") | O11: =IF(B11="","","See Resource Build-Up / Resource Rate Library") | P11: =IF(B11="","",IF(COUNTIF('Resource Build-Up'!$B$7:$B$306,B11)=0,IF(G11=0,"ZERO / REVIEW","NO RESOURCE"),"RESOURCE LINKED")) | R11: =IF(OR(ISNUMBER(SEARCH("PC",P11)),ISNUMBER(SEARCH("quote",Q11))),"Jason","Rick") -> Rick | S11: =IF(B11="","",IF(COUNTIF('Resource Build-Up'!$B$7:$B$306,B11)=0,"NO RESOURCE",IF(COUNTIFS('Resource Build-Up'!$B$7:$B$306,B11,'Resource Build-Up'!$AI$7:$AI$306,"<>OK")>0,"RESOURCE QA","LINKED")))
F12: =IF(OR(B12="",E12=0),0,G12/E12) -> 0 | G12: =IF(B12="",0,SUMIF('Resource Build-Up'!$B$7:$B$306,B12,'Resource Build-Up'!$Z$7:$Z$306)) -> 0 | L12: =IF(B12="","",IF(J12="Excluded","Excluded","Resource-linked")) | M12: =IF(B12="","",IF(G12=0,"No resource cost / review","Resource Build-Up -> "&B12)) | N12: =IF(B12="","","Resource Build-Up") | O12: =IF(B12="","","See Resource Build-Up / Resource Rate Library") | P12: =IF(B12="","",IF(COUNTIF('Resource Build-Up'!$B$7:$B$306,B12)=0,IF(G12=0,"ZERO / REVIEW","NO RESOURCE"),"RESOURCE LINKED")) | R12: =IF(OR(ISNUMBER(SEARCH("PC",P12)),ISNUMBER(SEARCH("quote",Q12))),"Jason","Rick") -> Rick | S12: =IF(B12="","",IF(COUNTIF('Resource Build-Up'!$B$7:$B$306,B12)=0,"NO RESOURCE",IF(COUNTIFS('Resource Build-Up'!$B$7:$B$306,B12,'Resource Build-Up'!$AI$7:$AI$306,"<>OK")>0,"RESOURCE QA","LINKED")))
F13: =IF(OR(B13="",E13=0),0,G13/E13) -> 0 | G13: =IF(B13="",0,SUMIF('Resource Build-Up'!$B$7:$B$306,B13,'Resource Build-Up'!$Z$7:$Z$306)) -> 0 | L13: =IF(B13="","",IF(J13="Excluded","Excluded","Resource-linked")) | M13: =IF(B13="","",IF(G13=0,"No resource cost / review","Resource Build-Up -> "&B13)) | N13: =IF(B13="","","Resource Build-Up") | O13: =IF(B13="","","See Resource Build-Up / Resource Rate Library") | P13: =IF(B13="","",IF(COUNTIF('Resource Build-Up'!$B$7:$B$306,B13)=0,IF(G13=0,"ZERO / REVIEW","NO RESOURCE"),"RESOURCE LINKED")) | R13: =IF(OR(ISNUMBER(SEARCH("PC",P13)),ISNUMBER(SEARCH("quote",Q13))),"Jason","Rick") -> Rick | S13: =IF(B13="","",IF(COUNTIF('Resource Build-Up'!$B$7:$B$306,B13)=0,"NO RESOURCE",IF(COUNTIFS('Resource Build-Up'!$B$7:$B$306,B13,'Resource Build-Up'!$AI$7:$AI$306,"<>OK")>0,"RESOURCE QA","LINKED")))
F14: =IF(OR(B14="",E14=0),0,G14/E14) -> 0 | G14: =IF(B14="",0,SUMIF('Resource Build-Up'!$B$7:$B$306,B14,'Resource Build-Up'!$Z$7:$Z$306)) -> 0 | L14: =IF(B14="","",IF(J14="Excluded","Excluded","Resource-linked")) | M14: =IF(B14="","",IF(G14=0,"No resource cost / review","Resource Build-Up -> "&B14)) | N14: =IF(B14="","","Resource Build-Up") | O14: =IF(B14="","","See Resource Build-Up / Resource Rate Library") | P14: =IF(B14="","",IF(COUNTIF('Resource Build-Up'!$B$7:$B$306,B14)=0,IF(G14=0,"ZERO / REVIEW","NO RESOURCE"),"RESOURCE LINKED")) | R14: =IF(OR(ISNUMBER(SEARCH("PC",P14)),ISNUMBER(SEARCH("quote",Q14))),"Jason","Rick") -> Rick | S14: =IF(B14="","",IF(COUNTIF('Resource Build-Up'!$B$7:$B$306,B14)=0,"NO RESOURCE",IF(COUNTIFS('Resource Build-Up'!$B$7:$B$306,B14,'Resource Build-Up'!$AI$7:$AI$306,"<>OK")>0,"RESOURCE QA","LINKED")))
... F73: =IF(OR(B73="",E73=0),0,G73/E73) -> 0 | G73: =IF(B73="",0,SUMIF('Resource Build-Up'!$B$7:$B$306,B73,'Resource Build-Up'!$Z$7:$Z$306)) -> 0 | L73: =IF(B73="","",IF(J73="Excluded","Excluded","Resource-linked")) | M73: =IF(B73="","",IF(G73=0,"No resource cost / review","Resource Build-Up -> "&B73)) | N73: =IF(B73="","","Resource Build-Up") | O73: =IF(B73="","","See Resource Build-Up / Resource Rate Library") | P73: =IF(B73="","",IF(COUNTIF('Resource Build-Up'!$B$7:$B$306,B73)=0,IF(G73=0,"ZERO / REVIEW","NO RESOURCE"),"RESOURCE LINKED")) | R73: =IF(OR(ISNUMBER(SEARCH("PC",P73)),ISNUMBER(SEARCH("quote",Q73))),"Jason","Rick") -> Rick | S73: =IF(B73="","",IF(COUNTIF('Resource Build-Up'!$B$7:$B$306,B73)=0,"NO RESOURCE",IF(COUNTIFS('Resource Build-Up'!$B$7:$B$306,B73,'Resource Build-Up'!$AI$7:$AI$306,"<>OK")>0,"RESOURCE QA","LINKED")))
A74: TOTAL MEASURED DIRECT COST | G74: =SUM(G3:G73) -> 0

Sheet Stage Cashflow
A1: STAGE PAYMENT & CASHFLOW - MASTER ESTIMATE WORKBOOK REV2
A2: Only stage timing, stage percentages and retention applicability are inputs. Revenue and direct-cost allocations remain formula linked.
A3: Cash on hand = cumulative net pre-GST receipts less base direct stage costs and included pre-margin provisions. Commercial adjustments (overhead/profit/bonds/finance) remain visible as commercial return/cost after those provisions.
A4: Stage | B4: Timing / milestone | C4: Stage % | D4: Retention applies? | E4: Opening cash | F4: Gross stage revenue excl. GST | G4: Retention withheld | H4: Net stage revenue excl. GST | I4: Stage cost / provision | J4: Net cash movement | K4: Closing cash on hand | L4: Cumulative net revenue | M4: Cumulative retention held | N4: GST if selected | O4: Net stage receipt incl. GST | P4: Notes
A5: Deposit / advance | B5: On contract award | C5: =IF('Commercial Inputs'!$F$28="Yes",'Commercial Inputs'!$D$28,0) -> 0 | D5: =IF('Commercial Inputs'!$F$29="Yes","Yes","No") -> No | E5: =0 -> 0 | F5: ='Tender Build-Up'!$B$47*C5 -> 0 | G5: =IF(AND(D5="Yes",'Commercial Inputs'!$F$26="Yes"),F5*'Commercial Inputs'!$D$26,0) -> 0 | H5: =F5-G5 -> 0 | I5: =0 -> 0 | J5: =H5-I5 -> 0 | K5: =E5+J5 -> 0 | L5: =H5 -> 0 | M5: =G5 -> 0 | N5: =IF('Commercial Inputs'!$F$25="Yes",H5*'Commercial Inputs'!$D$25,0) -> 0 | O5: =H5+N5 -> 0
A6: Mobilisation, preliminaries and ESC | E6: =K5 -> 0 | F6: ='Tender Build-Up'!$B$47*C6 -> 0 | G6: =IF(AND(D6="Yes",'Commercial Inputs'!$F$26="Yes"),F6*'Commercial Inputs'!$D$26,0) -> 0 | H6: =F6-G6 -> 0 | I6: =SUM(Summary!$B$23:$B$24) -> 0 | J6: =H6-I6 -> 0 | K6: =E6+J6 -> 0 | L6: =L5+H6 -> 0 | M6: =M5+G6 -> 0 | N6: =IF('Commercial Inputs'!$F$25="Yes",H6*'Commercial Inputs'!$D$25,0) -> 0 | O6: =H6+N6 -> 0
A7: Earthworks and imported fill | E7: =K6 -> 0 | F7: ='Tender Build-Up'!$B$47*C7 -> 0 | G7: =IF(AND(D7="Yes",'Commercial Inputs'!$F$26="Yes"),F7*'Commercial Inputs'!$D$26,0) -> 0 | H7: =F7-G7 -> 0 | I7: =Summary!$B$25 -> 0 | J7: =H7-I7 -> 0 | K7: =E7+J7 -> 0 | L7: =L6+H7 -> 0 | M7: =M6+G7 -> 0 | N7: =IF('Commercial Inputs'!$F$25="Yes",H7*'Commercial Inputs'!$D$25,0) -> 0 | O7: =H7+N7 -> 0
A8: Stormwater, detention, sewer and water | E8: =K7 -> 0 | F8: ='Tender Build-Up'!$B$47*C8 -> 0 | G8: =IF(AND(D8="Yes",'Commercial Inputs'!$F$26="Yes"),F8*'Commercial Inputs'!$D$26,0) -> 0 | H8: =F8-G8 -> 0 | I8: =SUM(Summary!$B$26:$B$27) -> 0 | J8: =H8-I8 -> 0 | K8: =E8+J8 -> 0 | L8: =L7+H8 -> 0 | M8: =M7+G8 -> 0 | N8: =IF('Commercial Inputs'!$F$25="Yes",H8*'Commercial Inputs'!$D$25,0) -> 0 | O8: =H8+N8 -> 0
A9: Pavements, kerbs and sitework | E9: =K8 -> 0 | F9: ='Tender Build-Up'!$B$47*C9 -> 0 | G9: =IF(AND(D9="Yes",'Commercial Inputs'!$F$26="Yes"),F9*'Commercial Inputs'!$D$26,0) -> 0 | H9: =F9-G9 -> 0 | I9: =SUM(Summary!$B$28:$B$29) -> 0 | J9: =H9-I9 -> 0 | K9: =E9+J9 -> 0 | L9: =L8+H9 -> 0 | M9: =M8+G9 -> 0 | N9: =IF('Commercial Inputs'!$F$25="Yes",H9*'Commercial Inputs'!$D$25,0) -> 0 | O9: =H9+N9 -> 0
A10: Retaining walls and interfaces | E10: =K9 -> 0 | F10: ='Tender Build-Up'!$B$47*C10 -> 0 | G10: =IF(AND(D10="Yes",'Commercial Inputs'!$F$26="Yes"),F10*'Commercial Inputs'!$D$26,0) -> 0 | H10: =F10-G10 -> 0 | I10: =Summary!$B$30 -> 0 | J10: =H10-I10 -> 0 | K10: =E10+J10 -> 0 | L10: =L9+H10 -> 0 | M10: =M9+G10 -> 0 | N10: =IF('Commercial Inputs'!$F$25="Yes",H10*'Commercial Inputs'!$D$25,0) -> 0 | O10: =H10+N10 -> 0
A11: Testing, completion and handover | E11: =K10 -> 0 | F11: ='Tender Build-Up'!$B$47*C11 -> 0 | G11: =IF(AND(D11="Yes",'Commercial Inputs'!$F$26="Yes"),F11*'Commercial Inputs'!$D$26,0) -> 0 | H11: =F11-G11 -> 0 | I11: =SUM(Summary!$B$31:$B$32) -> 0 | J11: =H11-I11 -> 0 | K11: =E11+J11 -> 0 | L11: =L10+H11 -> 0 | M11: =M10+G11 -> 0 | N11: =IF('Commercial Inputs'!$F$25="Yes",H11*'Commercial Inputs'!$D$25,0) -> 0 | O11: =H11+N11 -> 0
A12: Included pre-margin cost / risk provisions | B12: Timing to allocate / refine | C12: 0 | D12: No | E12: =K11 -> 0 | F12: 0 | G12: 0 | H12: 0 | I12: ='Tender Build-Up'!$B$39 -> 0 | J12: =H12-I12 -> 0 | K12: =E12+J12 -> 0 | L12: =L11+H12 -> 0 | M12: =M11+G12 -> 0 | N12: =0 -> 0 | O12: =H12+N12 -> 0
A13: Retention release | B13: ="After "&TEXT('Commercial Inputs'!$D$27,"0")&" months" -> After 0 months | D13: No | E13: =K12 -> 0 | F13: =SUM(G5:G11) -> 0 | G13: =0 -> 0 | H13: =F13 -> 0 | I13: =0 -> 0 | J13: =H13 -> 0 | K13: =E13+J13 -> 0 | L13: =L12+H13 -> 0 | M13: =0 -> 0 | N13: =IF('Commercial Inputs'!$F$25="Yes",H13*'Commercial Inputs'!$D$25,0) -> 0 | O13: =H13+N13 -> 0
A15: Cashflow checks
A16: Stage percentages total | C16: =SUM(C5:C11) -> 0 | P16: =IF(ABS(C16-1)<0.000001,"OK","CHECK") -> CHECK
A17: Gross stage revenue equals tender excl. GST | F17: =SUM(F5:F11) -> 0 | P17: =IF(ABS(F17-'Tender Build-Up'!$B$47)<0.01,"OK","CHECK") -> OK
A18: Base direct costs + pre-margin provisions allocated | I18: =SUM(I5:I12) -> 0 | P18: =IF(ABS(I18-(Summary!$B$33+'Tender Build-Up'!$B$39))<0.01,"OK","CHECK") -> OK
A19: Net receipts plus retention release equal tender | L19: =L13 -> 0 | P19: =IF(ABS(L19-'Tender Build-Up'!$B$47)<0.01,"OK","CHECK") -> OK
A20: Final cash equals commercial adjustments after cost provisions | K20: =K13 -> 0 | P20: =IF(ABS(K20-'Tender Build-Up'!$B$46)<0.01,"OK","CHECK") -> OK
A21: Lowest closing cash before retention release | K21: =MIN(K5:K12) -> 0 | P21: =IF(K21>=0,"POSITIVE","FUNDING REQUIRED") -> POSITIVE

Sheet Resource Rate Library
A1: COMPANY RESOURCE RATE LIBRARY - MASTER ESTIMATE WORKBOOK REV2
A2: Reusable company / benchmark resource library. Retain useful history; update verified rates with source, effective date, region, GST basis, inclusions/exclusions and supersession reason.
A3: Jason: enter verified actual company/supplier rates with source, date, region, GST basis, inclusions and exclusions. Mark replaced rates superseded/inactive rather than deleting them.
A4: Resource Code | B4: Resource Category | C4: Resource Description | D4: Default Cost Type | E4: Unit | F4: Procurement Mode | G4: Operator Included? | H4: Fuel Included? | I4: Base Rate excl. GST | J4: Region / Market | K4: Effective Date | L4: Source Type | M4: Supplier / Source | N4: Source URL / Quote Ref | O4: Minimum / Mobilisation | P4: Rate Inclusions | Q4: Rate Exclusions | R4: Confidence | S4: Verification Status | T4: Notes
A5: LAB-FOREMAN | B5: Labour | C5: Civil foreman / working foreman | D5: Labour | E5: hr | F5: Internal / agency | G5: N/A | H5: N/A | I5: 64 | J5: Auckland / NZ | K5: 13-Aug-2026 | L5: Template market benchmark | M5: SEEK / statutory on-cost basis | N5: https://nz.seek.com/civil-drainage-jobs/in-All-Auckland | https://nz.seek.com/drainage-foreman-jobs/in-All-Auckland/full-time | P5: Direct employment allowance | Q5: Margin, vehicle, overtime | R5: Medium | S5: AMBER - market/on-cost benchmark; company payroll required | T5: Firm to company payroll before award
A6: LAB-SUPERVISOR | B6: Labour | C6: Site supervisor / project manager | D6: Labour | E6: hr | F6: Internal / agency | G6: N/A | H6: N/A | I6: 73 | J6: Auckland / NZ | K6: 13-Aug-2026 | L6: Template market benchmark | M6: SEEK / statutory on-cost basis | N6: https://nz.seek.com/civil-drainage-jobs/in-All-Auckland | https://nz.seek.com/drainage-foreman-jobs/in-All-Auckland/full-time | P6: Direct employment allowance | Q6: Margin, vehicle, overtime | R6: Medium | S6: AMBER - market/on-cost benchmark; company payroll required | T6: Firm to company payroll before award
A7: LAB-OPERATOR | B7: Labour | C7: Plant operator | D7: Labour | E7: hr | F7: Internal / agency | G7: N/A | H7: N/A | I7: 45 | J7: Auckland / NZ | K7: 13-Aug-2026 | L7: Template market benchmark | M7: Auckland civil market | N7: https://nz.seek.com/civil-drainage-jobs/in-All-Auckland | https://nz.seek.com/drainage-foreman-jobs/in-All-Auckland/full-time | P7: Direct employment allowance | Q7: Plant and overtime | R7: Medium | S7: AMBER - market/on-cost benchmark; company payroll required
A8: LAB-DRAINLAYER | B8: Labour | C8: Registered drainlayer / pipe layer | D8: Labour | E8: hr | F8: Internal / agency | G8: N/A | H8: N/A | I8: 51 | J8: Auckland / NZ | K8: 13-Aug-2026 | L8: Template market benchmark | M8: Auckland civil market | N8: https://nz.seek.com/civil-drainage-jobs/in-All-Auckland | https://nz.seek.com/drainage-foreman-jobs/in-All-Auckland/full-time | P8: Direct employment allowance | Q8: Vehicle and overtime | R8: Medium | S8: AMBER - market/on-cost benchmark; company payroll required
A9: LAB-LABOURER | B9: Labour | C9: Civil labourer | D9: Labour | E9: hr | F9: Internal / agency | G9: N/A | H9: N/A | I9: 38 | J9: Auckland / NZ | K9: 13-Aug-2026 | L9: Template market benchmark | M9: Auckland civil market | N9: https://nz.seek.com/civil-drainage-jobs/in-All-Auckland | https://nz.seek.com/drainage-foreman-jobs/in-All-Auckland/full-time | P9: Direct employment allowance | Q9: Overtime | R9: Medium | S9: AMBER - market/on-cost benchmark; company payroll required
A10: LAB-CONCRETE | B10: Labour | C10: Concrete placer / finisher | D10: Labour | E10: hr | F10: Internal / agency | G10: N/A | H10: N/A | I10: 44 | J10: Auckland / NZ | K10: 13-Aug-2026 | L10: Template market benchmark | M10: Auckland civil market | N10: https://nz.seek.com/civil-drainage-jobs/in-All-Auckland | https://nz.seek.com/drainage-foreman-jobs/in-All-Auckland/full-time | P10: Direct employment allowance | Q10: Specialist pump | R10: Medium | S10: AMBER - market/on-cost benchmark; company payroll required
A11: PL-EXC-1.7 | B11: Plant | C11: 1.7 t excavator wet hire | D11: Plant | E11: hr | F11: Wet hire | G11: Yes | H11: Yes | I11: 85 | J11: Auckland | K11: 13-Aug-2026 | L11: Published supplier wet-hire rate | M11: ASAP Machine Hire; NZ Machine Hire cross-check | N11: https://www.asapmachinehire.co.nz/price-list | https://www.nzmachinehire.co.nz/_files/ugd/d7f8c7_1379402df1a242f88fef70fc3ce1475c.pdf | O11: Delivery by quote | P11: Machine, operator, fuel and normal buckets | Q11: Delivery, overtime and specialist attachments | R11: High | S11: GREEN - 3-point checked | T11: Wet rate. Do not add a separate operator or fuel line.
A12: PL-EXC-5 | B12: Plant | C12: 5.5 t excavator wet hire | D12: Plant | E12: hr | F12: Wet hire | G12: Yes | H12: Yes | I12: 110 | J12: Auckland | K12: 13-Aug-2026 | L12: Published supplier wet-hire rate | M12: ASAP Machine Hire; NZ Machine Hire cross-check | N12: https://www.asapmachinehire.co.nz/price-list | https://www.nzmachinehire.co.nz/_files/ugd/d7f8c7_1379402df1a242f88fef70fc3ce1475c.pdf | O12: Delivery by quote | P12: Machine, operator, fuel and normal buckets | Q12: Delivery, overtime and specialist attachments | R12: High | S12: GREEN - 3-point checked | T12: Wet rate. Separate excavator-operator lines set to zero.
A13: PL-EXC-13 | B13: Plant | C13: 14 t excavator wet hire | D13: Plant | E13: hr | F13: Wet hire | G13: Yes | H13: Yes | I13: 150 | J13: Auckland | K13: 13-Aug-2026 | L13: Published supplier wet-hire rate | M13: ASAP Machine Hire; NZ Machine Hire cross-check | N13: https://www.asapmachinehire.co.nz/price-list | https://www.nzmachinehire.co.nz/_files/ugd/d7f8c7_1379402df1a242f88fef70fc3ce1475c.pdf | O13: Delivery by quote | P13: Machine, operator, fuel and normal buckets | Q13: Delivery, overtime and specialist attachments | R13: High | S13: GREEN - 3-point checked | T13: Published current wet rate. Separate excavator-operator lines set to zero.
