Workbook

Sheet Estimator
A1: Weather Risk Estimator - Evidence-Based Allowance | B1: Weather Risk Estimator - Evidence-Based Allowance | C1: Weather Risk Estimator - Evidence-Based Allowance | D1: Weather Risk Estimator - Evidence-Based Allowance | E1: Weather Risk Estimator - Evidence-Based Allowance | F1: Weather Risk Estimator - Evidence-Based Allowance | G1: Weather Risk Estimator - Evidence-Based Allowance | H1: Weather Risk Estimator - Evidence-Based Allowance | I1: Weather Risk Estimator - Evidence-Based Allowance | J1: Weather Risk Estimator - Evidence-Based Allowance | K1: Weather Risk Estimator - Evidence-Based Allowance | L1: Weather Risk Estimator - Evidence-Based Allowance | M1: Weather Risk Estimator - Evidence-Based Allowance | N1: Weather Risk Estimator - Evidence-Based Allowance | O1: Weather Risk Estimator - Evidence-Based Allowance | P1: Weather Risk Estimator - Evidence-Based Allowance | Q1: Weather Risk Estimator - Evidence-Based Allowance
A3: Project and Cost Inputs | B3: Project and Cost Inputs | D3: Task Factors | E3: Task Factors | G3: Weather and Cost Outputs | H3: Weather and Cost Outputs
A4: Nearest NIWA location | B4: Christchurch | D4: Default rain exposure | E4: =IF($B$9="","",INDEX('Task Library'!$C$7:$C$45,MATCH($B$9,'Task Library'!$A$7:$A$45,0))) -> 1.00 | G4: Date-engine coverage | H4: 01/01/2025 to 31/12/2040
A5: Start date | B5: 46266 | D5: Override rain exposure | G5: Standard workdays | H5: =IF(OR(B5="",B6="",B6<B5),"",SUMPRODUCT((('Date Engine'!$A$7:$A$5850>=$B$5)*('Date Engine'!$A$7:$A$5850<=$B$6)*'Date Engine'!$G$7:$G$5850))) -> 153
A6: End date | B6: 46478 | D6: Effective rain exposure | E6: =IF(E4="","",IF(E5="",E4,E5)) -> 1.00 | G6: Effective workdays | H6: =IF(H5="","",IF(B8="",H5,B8)) -> 153
A7: Working days per week | B7: 5 | G7: Average NIWA wet-day probability | H7: =IFERROR(SUMPRODUCT((('Date Engine'!$A$7:$A$5850>=$B$5)*('Date Engine'!$A$7:$A$5850<=$B$6)*'Date Engine'!$G$7:$G$5850)*'Date Engine'!$H$7:$H$5850)/SUMPRODUCT((('Date Engine'!$A$7:$A$5850>=$B$5)*('Date Engine'!$A$7:$A$5850<=$B$6)*'Date Engine'!$G$7:$G$5850)),"") -> 0.21009558
A8: Working days override (optional) | D8: Default rain productivity loss | E8: =IF($B$9="","",INDEX('Task Library'!$D$7:$D$45,MATCH($B$9,'Task Library'!$A$7:$A$45,0))) -> 0.70 | G8: Local-adjusted wet-day probability | H8: =IF(H7="","",MIN(1,H7*B16)) -> 0.21009558
A9: Representative task | B9: Bulk earthworks | D9: Override rain productivity loss | G9: Mean rain per wet day (context only) | H9: =IFERROR(SUMPRODUCT((('Date Engine'!$A$7:$A$5850>=$B$5)*('Date Engine'!$A$7:$A$5850<=$B$6)*'Date Engine'!$G$7:$G$5850)*'Date Engine'!$H$7:$H$5850*'Date Engine'!$I$7:$I$5850)/SUMPRODUCT((('Date Engine'!$A$7:$A$5850>=$B$5)*('Date Engine'!$A$7:$A$5850<=$B$6)*'Date Engine'!$G$7:$G$5850)*'Date Engine'!$H$7:$H$5850),"") -> 7.0023297
A10: Weather-exposed labour cost $ | D10: Effective rain productivity loss | E10: =IF(E8="","",IF(E9="",E8,E9)) -> 0.70 | G10: Effective wind-event probability | H10: =IF(B15<>"",B15,IFERROR(SUMPRODUCT((('Date Engine'!$A$7:$A$5850>=$B$5)*('Date Engine'!$A$7:$A$5850<=$B$6)*'Date Engine'!$G$7:$G$5850)*'Date Engine'!$J$7:$J$5850)/SUMPRODUCT((('Date Engine'!$A$7:$A$5850>=$B$5)*('Date Engine'!$A$7:$A$5850<=$B$6)*'Date Engine'!$G$7:$G$5850)),0)) -> 0
A11: Weather-exposed plant cost $ | G11: Wind evidence status | H11: =IF(B4="Auckland","AMBER - legacy Auckland wind proxy",IF(B15<>"","AMBER - project override requires source","RED - no wind frequency loaded")) -> RED - no wind frequency loaded
A12: Daily time-related preliminaries $ | D12: Default wet-ground carryover eq. days | E12: =IF($B$9="","",INDEX('Task Library'!$E$7:$E$45,MATCH($B$9,'Task Library'!$A$7:$A$45,0))) -> 0.2
A13: Weekly hire / facilities $ | D13: Override carryover eq. days | G13: On-day rain impact % | H13: =IF(OR(H8="",E6="",E10="",E26=""),"",H8*E6*E10*E26) -> 0.12500687
A14: Project-specific recovery allowance $ | B14: 0 | D14: Effective carryover eq. days | E14: =IF(E12="","",IF(E13="",E12,E13)) -> 0.2 | G14: Wet-ground carryover impact % | H14: =IF(OR(H8="",E14="",E26=""),"",H8*E14*E26) -> 0.035716249
A15: Wind probability override (optional) | G15: Wind impact % | H15: =IF(OR(E18="",E22="",E26=""),"",H10*E18*E22*E26) -> 0
A16: Local wet-day factor | B16: 1 | D16: Default wind sensitivity | E16: =IF($B$9="","",INDEX('Task Library'!$F$7:$F$45,MATCH($B$9,'Task Library'!$A$7:$A$45,0))) -> 0.15 | G16: Combined direct impact % | H16: =IF(B9="","",MIN(1,H13+H14+H15)) -> 0.16072312
A17: Local factor basis / reference | D17: Override wind sensitivity | G17: Expected equivalent lost working days | H17: =IF(OR(H6="",B9=""),"",H6*H16) -> 24.590638
A18: Task is on critical path? | B18: Yes | D18: Effective wind sensitivity | E18: =IF(E16="","",IF(E17="",E16,E17)) -> 0.15 | G18: Suggested critical-path delay working days | H18: =IF(B9="","",IF(B18="Yes",H17,0)) -> 24.590638
D20: Default wind productivity loss | E20: =IF($B$9="","",INDEX('Task Library'!$G$7:$G$45,MATCH($B$9,'Task Library'!$A$7:$A$45,0))) -> 0.70 | G20: Direct productivity allowance $ | H20: =IF(B9="","",(B10+B11)*H16) -> 0 | J20: Month | K20: Wet-Day Probability | L20: Rain per Wet Day (mm)
D21: Override wind productivity loss | G21: Time-related preliminaries allowance $ | H21: =IF(B9="","",H18*B12) -> 0 | J21: Jan | K21: =SUMIFS('Climate Data'!$G$7:$G$366,'Climate Data'!$A$7:$A$366,$B$4,'Climate Data'!$B$7:$B$366,1) -> 0.19462366 | L21: =SUMIFS('Climate Data'!$H$7:$H$366,'Climate Data'!$A$7:$A$366,$B$4,'Climate Data'!$B$7:$B$366,1) -> 7.0276243
D22: Effective wind productivity loss | E22: =IF(E20="","",IF(E21="",E20,E21)) -> 0.70 | G22: Additional billed hire weeks | H22: =IF(OR(H18="",H18=0),0,ROUNDUP(H18/B7,0)) -> 5 | J22: Feb | K22: =SUMIFS('Climate Data'!$G$7:$G$366,'Climate Data'!$A$7:$A$366,$B$4,'Climate Data'!$B$7:$B$366,2) -> 0.18867925 | L22: =SUMIFS('Climate Data'!$H$7:$H$366,'Climate Data'!$A$7:$A$366,$B$4,'Climate Data'!$B$7:$B$366,2) -> 7.4625
G23: Hire / facilities allowance $ | H23: =IF(B9="","",H22*B13) -> 0 | J23: Mar | K23: =SUMIFS('Climate Data'!$G$7:$G$366,'Climate Data'!$A$7:$A$366,$B$4,'Climate Data'!$B$7:$B$366,3) -> 0.18494624 | L23: =SUMIFS('Climate Data'!$H$7:$H$366,'Climate Data'!$A$7:$A$366,$B$4,'Climate Data'!$B$7:$B$366,3) -> 7.8662791
D24: Default nonrecoverable share | E24: =IF($B$9="","",INDEX('Task Library'!$H$7:$H$45,MATCH($B$9,'Task Library'!$A$7:$A$45,0))) -> 0.85 | G24: Project-specific recovery allowance $ | H24: =B14 -> 0 | J24: Apr | K24: =SUMIFS('Climate Data'!$G$7:$G$366,'Climate Data'!$A$7:$A$366,$B$4,'Climate Data'!$B$7:$B$366,4) -> 0.25555556 | L24: =SUMIFS('Climate Data'!$H$7:$H$366,'Climate Data'!$A$7:$A$366,$B$4,'Climate Data'!$B$7:$B$366,4) -> 7.5
D25: Override nonrecoverable share | G25: Total weather allowance $ | H25: =IF(B9="","",SUM(H20:H21,H23:H24)) -> 0 | J25: May | K25: =SUMIFS('Climate Data'!$G$7:$G$366,'Climate Data'!$A$7:$A$366,$B$4,'Climate Data'!$B$7:$B$366,5) -> 0.23010753 | L25: =SUMIFS('Climate Data'!$H$7:$H$366,'Climate Data'!$A$7:$A$366,$B$4,'Climate Data'!$B$7:$B$366,5) -> 8.1448598
D26: Effective nonrecoverable share | E26: =IF(E24="","",IF(E25="",E24,E25)) -> 0.85 | G26: Total as % of exposed direct cost | H26: =IFERROR(H25/(B10+B11),0) -> 0 | J26: Jun | K26: =SUMIFS('Climate Data'!$G$7:$G$366,'Climate Data'!$A$7:$A$366,$B$4,'Climate Data'!$B$7:$B$366,6) -> 0.28666667 | L26: =SUMIFS('Climate Data'!$H$7:$H$366,'Climate Data'!$A$7:$A$366,$B$4,'Climate Data'!$B$7:$B$366,6) -> 7.9418605
J27: Jul | K27: =SUMIFS('Climate Data'!$G$7:$G$366,'Climate Data'!$A$7:$A$366,$B$4,'Climate Data'!$B$7:$B$366,7) -> 0.24731183 | L27: =SUMIFS('Climate Data'!$H$7:$H$366,'Climate Data'!$A$7:$A$366,$B$4,'Climate Data'!$B$7:$B$366,7) -> 8.373913
G28: Chance of at least one wet workday | H28: =IF(OR(H8="",H6=""),"",1-(1-H8)^H6) -> 1 | J28: Aug | K28: =SUMIFS('Climate Data'!$G$7:$G$366,'Climate Data'!$A$7:$A$366,$B$4,'Climate Data'!$B$7:$B$366,8) -> 0.23548387 | L28: =SUMIFS('Climate Data'!$H$7:$H$366,'Climate Data'!$A$7:$A$366,$B$4,'Climate Data'!$B$7:$B$366,8) -> 7.9589041
G29: Output confidence | H29: =IF(OR(B5="",B6="",B9=""),"INCOMPLETE - enter dates and task",IF(OR(B5<DATE(2025,1,1),B6>DATE(2040,12,31)),"RED - dates outside engine",IF(AND(E18>=20%,H10=0),"RED - wind input missing for wind-sensitive task",IF(AND(B16<>1,B17=""),"RED - local factor has no basis","AMBER - NIWA data GREEN; task factors uncalibrated")))) -> RED - wind input missing for wind-sensitive task | J29: Sep | K29: =SUMIFS('Climate Data'!$G$7:$G$366,'Climate Data'!$A$7:$A$366,$B$4,'Climate Data'!$B$7:$B$366,9) -> 0.20666667 | L29: =SUMIFS('Climate Data'!$H$7:$H$366,'Climate Data'!$A$7:$A$366,$B$4,'Climate Data'!$B$7:$B$366,9) -> 6.8064516
G30: Release action | H30: =IF(LEFT(H29,10)="INCOMPLETE","Complete inputs before use",IF(LEFT(H29,3)="RED","Resolve RED input before issue","Disclose AMBER task factors and firm up with actual records / project evidence")) -> Resolve RED input before issue | J30: Oct | K30: =SUMIFS('Climate Data'!$G$7:$G$366,'Climate Data'!$A$7:$A$366,$B$4,'Climate Data'!$B$7:$B$366,10) -> 0.23225806 | L30: =SUMIFS('Climate Data'!$H$7:$H$366,'Climate Data'!$A$7:$A$366,$B$4,'Climate Data'!$B$7:$B$366,10) -> 6.8194444
J31: Nov | K31: =SUMIFS('Climate Data'!$G$7:$G$366,'Climate Data'!$A$7:$A$366,$B$4,'Climate Data'!$B$7:$B$366,11) -> 0.23333333 | L31: =SUMIFS('Climate Data'!$H$7:$H$366,'Climate Data'!$A$7:$A$366,$B$4,'Climate Data'!$B$7:$B$366,11) -> 6.4428571
J32: Dec | K32: =SUMIFS('Climate Data'!$G$7:$G$366,'Climate Data'!$A$7:$A$366,$B$4,'Climate Data'!$B$7:$B$366,12) -> 0.22688172 | L32: =SUMIFS('Climate Data'!$H$7:$H$366,'Climate Data'!$A$7:$A$366,$B$4,'Climate Data'!$B$7:$B$366,12) -> 6.7962085
A34: Estimator Statement and Controls | B34: Estimator Statement and Controls | C34: Estimator Statement and Controls | D34: Estimator Statement and Controls | E34: Estimator Statement and Controls | F34: Estimator Statement and Controls | G34: Estimator Statement and Controls | H34: Estimator Statement and Controls | I34: Estimator Statement and Controls | J34: Estimator Statement and Controls | K34: Estimator Statement and Controls | L34: Estimator Statement and Controls | M34: Estimator Statement and Controls | N34: Estimator Statement and Controls | O34: Estimator Statement and Controls | P34: Estimator Statement and Controls | Q34: Estimator Statement and Controls
A35: =IF(OR(B5="",B6="",B9=""),"Enter a location, dates and task to calculate an evidence-based allowance.","Using NIWA 1991-2020 climate normals for "&B4&", the selected working period has an average "&TEXT(H8,"0.0%")&" chance of a 1 mm wet day. For "&B9&", the model estimates "&TEXT(H17,"0.00")&" equivalent lost working days and a total weather allowance of "&TEXT(H25,"$#,##0")&". NIWA data is sourced evidence; task sensitivity and carryover remain AMBER company assumptions until calibrated.") -> Using NIWA 1991-2020 climate normals for Christchurch, the selected working period has an average 21.0% chance of a 1 mm wet day. For Bulk earthworks, the model estimates 24.59 equivalent lost working days and a total weather allowance of $0. NIWA data is sourced evidence; task sensitivity and carryover remain AMBER company assumptions until calibrated.
A39: Controls: - A 1 mm wet day is not automatically a lost day. Task factors convert climate exposure into estimated productivity loss. - Rain, wet-ground carryover and wind are calculated separately. Rainfall intensity is shown as context only. - Wind uses an AMBER Auckland proxy only; other locations require a sourced override when wind matters. - Suggested delay days apply only when the representative task is genuinely on the critical path. - Public holidays and shutdowns are not included in the date engine. - Do not add task lost days across concurrent activities; use the Activity Allowances critical-path flags and the live programme.

Sheet Activity Allowances
A1: Activity Weather Allowances - Programme and Cost Link | B1: Activity Weather Allowances - Programme and Cost Link | C1: Activity Weather Allowances - Programme and Cost Link | D1: Activity Weather Allowances - Programme and Cost Link | E1: Activity Weather Allowances - Programme and Cost Link | F1: Activity Weather Allowances - Programme and Cost Link | G1: Activity Weather Allowances - Programme and Cost Link | H1: Activity Weather Allowances - Programme and Cost Link | I1: Activity Weather Allowances - Programme and Cost Link | J1: Activity Weather Allowances - Programme and Cost Link | K1: Activity Weather Allowances - Programme and Cost Link | L1: Activity Weather Allowances - Programme and Cost Link | M1: Activity Weather Allowances - Programme and Cost Link | N1: Activity Weather Allowances - Programme and Cost Link | O1: Activity Weather Allowances - Programme and Cost Link | P1: Activity Weather Allowances - Programme and Cost Link | Q1: Activity Weather Allowances - Programme and Cost Link | R1: Activity Weather Allowances - Programme and Cost Link | S1: Activity Weather Allowances - Programme and Cost Link | T1: Activity Weather Allowances - Programme and Cost Link | U1: Activity Weather Allowances - Programme and Cost Link | V1: Activity Weather Allowances - Programme and Cost Link | W1: Activity Weather Allowances - Programme and Cost Link | X1: Activity Weather Allowances - Programme and Cost Link | Y1: Activity Weather Allowances - Programme and Cost Link | Z1: Activity Weather Allowances - Programme and Cost Link | AA1: Activity Weather Allowances - Programme and Cost Link | AB1: Activity Weather Allowances - Programme and Cost Link | AC1: Activity Weather Allowances - Programme and Cost Link | AD1: Activity Weather Allowances - Programme and Cost Link | AE1: Activity Weather Allowances - Programme and Cost Link | AF1: Activity Weather Allowances - Programme and Cost Link | AG1: Activity Weather Allowances - Programme and Cost Link | AH1: Activity Weather Allowances - Programme and Cost Link | AI1: Activity Weather Allowances - Programme and Cost Link | AJ1: Activity Weather Allowances - Programme and Cost Link | AK1: Activity Weather Allowances - Programme and Cost Link | AL1: Activity Weather Allowances - Programme and Cost Link
A3: Local wet-day factor | B3: 1 | C3: Wind probability override | E3: Daily time-related preliminaries $ | G3: Weekly hire / facilities $ | I3: Project recovery / remediation allowance $ | J3: 0 | L3: Use Critical Path = Yes only for sequential activities on the actual critical path. Concurrent task losses must not be added as programme delay. Direct productivity costs may still be assessed by activity.
A6: Task | B6: Category | C6: Start | D6: Finish | E6: Critical Path? | F6: Exposed Labour $ | G6: Exposed Plant $ | H6: Rain Exposure Default | I6: Rain Exposure Override | J6: Effective Rain Exposure | K6: Rain Loss Default | L6: Rain Loss Override | M6: Effective Rain Loss | N6: Carryover Default | O6: Carryover Override | P6: Effective Carryover | Q6: Wind Sensitivity Default | R6: Wind Sensitivity Override | S6: Effective Wind Sensitivity | T6: Wind Loss Default | U6: Wind Loss Override | V6: Effective Wind Loss | W6: Nonrecoverable Default | X6: Nonrecoverable Override | Y6: Effective Nonrecoverable | Z6: Workdays | AA6: Avg Wet Probability | AB6: Adjusted Wet Probability | AC6: Wind Probability | AD6: Rain Impact % | AE6: Carryover Impact % | AF6: Wind Impact % | AG6: Combined Impact % | AH6: Direct Allowance $ | AI6: Equivalent Lost WD | AJ6: CP Delay WD | AK6: Status | AL6: Basis / Note
B7: =IF(A7="","",INDEX('Task Library'!$B$7:$B$45,MATCH(A7,'Task Library'!$A$7:$A$45,0))) | E7: No | H7: =IF(A7="","",INDEX('Task Library'!$C$7:$C$45,MATCH(A7,'Task Library'!$A$7:$A$45,0))) | J7: =IF(H7="","",IF(I7="",H7,I7)) | K7: =IF(A7="","",INDEX('Task Library'!$D$7:$D$45,MATCH(A7,'Task Library'!$A$7:$A$45,0))) | M7: =IF(K7="","",IF(L7="",K7,L7)) | N7: =IF(A7="","",INDEX('Task Library'!$E$7:$E$45,MATCH(A7,'Task Library'!$A$7:$A$45,0))) | P7: =IF(N7="","",IF(O7="",N7,O7)) | Q7: =IF(A7="","",INDEX('Task Library'!$F$7:$F$45,MATCH(A7,'Task Library'!$A$7:$A$45,0))) | S7: =IF(Q7="","",IF(R7="",Q7,R7)) | T7: =IF(A7="","",INDEX('Task Library'!$G$7:$G$45,MATCH(A7,'Task Library'!$A$7:$A$45,0))) | V7: =IF(T7="","",IF(U7="",T7,U7)) | W7: =IF(A7="","",INDEX('Task Library'!$H$7:$H$45,MATCH(A7,'Task Library'!$A$7:$A$45,0))) | Y7: =IF(W7="","",IF(X7="",W7,X7)) | Z7: =IF(OR(C7="",D7="",D7<C7),"",SUMPRODUCT((('Date Engine'!$A$7:$A$5850>=C7)*('Date Engine'!$A$7:$A$5850<=D7)*'Date Engine'!$G$7:$G$5850))) | AA7: =IFERROR(SUMPRODUCT((('Date Engine'!$A$7:$A$5850>=C7)*('Date Engine'!$A$7:$A$5850<=D7)*'Date Engine'!$G$7:$G$5850)*'Date Engine'!$H$7:$H$5850)/SUMPRODUCT((('Date Engine'!$A$7:$A$5850>=C7)*('Date Engine'!$A$7:$A$5850<=D7)*'Date Engine'!$G$7:$G$5850)),"") | AB7: =IF(AA7="","",MIN(1,AA7*$B$3)) | AC7: =IF($D$3<>"",$D$3,IFERROR(SUMPRODUCT((('Date Engine'!$A$7:$A$5850>=C7)*('Date Engine'!$A$7:$A$5850<=D7)*'Date Engine'!$G$7:$G$5850)*'Date Engine'!$J$7:$J$5850)/SUMPRODUCT((('Date Engine'!$A$7:$A$5850>=C7)*('Date Engine'!$A$7:$A$5850<=D7)*'Date Engine'!$G$7:$G$5850)),0)) -> 0 | AD7: =IF(OR(AB7="",J7="",M7="",Y7=""),"",AB7*J7*M7*Y7) | AE7: =IF(OR(AB7="",P7="",Y7=""),"",AB7*P7*Y7) | AF7: =IF(OR(S7="",V7="",Y7=""),"",AC7*S7*V7*Y7) | AG7: =IF(A7="","",MIN(1,AD7+AE7+AF7)) | AH7: =IF(A7="","",(F7+G7)*AG7) | AI7: =IF(OR(A7="",Z7=""),"",Z7*AG7) | AJ7: =IF(A7="","",IF(E7="Yes",AI7,0)) | AK7: =IF(A7="","",IF(OR(C7<DATE(2025,1,1),D7>DATE(2040,12,31),D7<C7),"RED - date input",IF(AND(S7>=20%,AC7=0),"RED - wind input",IF($B$3<>1,"AMBER - local factor requires basis","AMBER - task factors uncalibrated"))))
B8: =IF(A8="","",INDEX('Task Library'!$B$7:$B$45,MATCH(A8,'Task Library'!$A$7:$A$45,0))) | E8: No | H8: =IF(A8="","",INDEX('Task Library'!$C$7:$C$45,MATCH(A8,'Task Library'!$A$7:$A$45,0))) | J8: =IF(H8="","",IF(I8="",H8,I8)) | K8: =IF(A8="","",INDEX('Task Library'!$D$7:$D$45,MATCH(A8,'Task Library'!$A$7:$A$45,0))) | M8: =IF(K8="","",IF(L8="",K8,L8)) | N8: =IF(A8="","",INDEX('Task Library'!$E$7:$E$45,MATCH(A8,'Task Library'!$A$7:$A$45,0))) | P8: =IF(N8="","",IF(O8="",N8,O8)) | Q8: =IF(A8="","",INDEX('Task Library'!$F$7:$F$45,MATCH(A8,'Task Library'!$A$7:$A$45,0))) | S8: =IF(Q8="","",IF(R8="",Q8,R8)) | T8: =IF(A8="","",INDEX('Task Library'!$G$7:$G$45,MATCH(A8,'Task Library'!$A$7:$A$45,0))) | V8: =IF(T8="","",IF(U8="",T8,U8)) | W8: =IF(A8="","",INDEX('Task Library'!$H$7:$H$45,MATCH(A8,'Task Library'!$A$7:$A$45,0))) | Y8: =IF(W8="","",IF(X8="",W8,X8)) | Z8: =IF(OR(C8="",D8="",D8<C8),"",SUMPRODUCT((('Date Engine'!$A$7:$A$5850>=C8)*('Date Engine'!$A$7:$A$5850<=D8)*'Date Engine'!$G$7:$G$5850))) | AA8: =IFERROR(SUMPRODUCT((('Date Engine'!$A$7:$A$5850>=C8)*('Date Engine'!$A$7:$A$5850<=D8)*'Date Engine'!$G$7:$G$5850)*'Date Engine'!$H$7:$H$5850)/SUMPRODUCT((('Date Engine'!$A$7:$A$5850>=C8)*('Date Engine'!$A$7:$A$5850<=D8)*'Date Engine'!$G$7:$G$5850)),"") | AB8: =IF(AA8="","",MIN(1,AA8*$B$3)) | AC8: =IF($D$3<>"",$D$3,IFERROR(SUMPRODUCT((('Date Engine'!$A$7:$A$5850>=C8)*('Date Engine'!$A$7:$A$5850<=D8)*'Date Engine'!$G$7:$G$5850)*'Date Engine'!$J$7:$J$5850)/SUMPRODUCT((('Date Engine'!$A$7:$A$5850>=C8)*('Date Engine'!$A$7:$A$5850<=D8)*'Date Engine'!$G$7:$G$5850)),0)) -> 0 | AD8: =IF(OR(AB8="",J8="",M8="",Y8=""),"",AB8*J8*M8*Y8) | AE8: =IF(OR(AB8="",P8="",Y8=""),"",AB8*P8*Y8) | AF8: =IF(OR(S8="",V8="",Y8=""),"",AC8*S8*V8*Y8) | AG8: =IF(A8="","",MIN(1,AD8+AE8+AF8)) | AH8: =IF(A8="","",(F8+G8)*AG8) | AI8: =IF(OR(A8="",Z8=""),"",Z8*AG8) | AJ8: =IF(A8="","",IF(E8="Yes",AI8,0)) | AK8: =IF(A8="","",IF(OR(C8<DATE(2025,1,1),D8>DATE(2040,12,31),D8<C8),"RED - date input",IF(AND(S8>=20%,AC8=0),"RED - wind input",IF($B$3<>1,"AMBER - local factor requires basis","AMBER - task factors uncalibrated"))))
B9: =IF(A9="","",INDEX('Task Library'!$B$7:$B$45,MATCH(A9,'Task Library'!$A$7:$A$45,0))) | E9: No | H9: =IF(A9="","",INDEX('Task Library'!$C$7:$C$45,MATCH(A9,'Task Library'!$A$7:$A$45,0))) | J9: =IF(H9="","",IF(I9="",H9,I9)) | K9: =IF(A9="","",INDEX('Task Library'!$D$7:$D$45,MATCH(A9,'Task Library'!$A$7:$A$45,0))) | M9: =IF(K9="","",IF(L9="",K9,L9)) | N9: =IF(A9="","",INDEX('Task Library'!$E$7:$E$45,MATCH(A9,'Task Library'!$A$7:$A$45,0))) | P9: =IF(N9="","",IF(O9="",N9,O9)) | Q9: =IF(A9="","",INDEX('Task Library'!$F$7:$F$45,MATCH(A9,'Task Library'!$A$7:$A$45,0))) | S9: =IF(Q9="","",IF(R9="",Q9,R9)) | T9: =IF(A9="","",INDEX('Task Library'!$G$7:$G$45,MATCH(A9,'Task Library'!$A$7:$A$45,0))) | V9: =IF(T9="","",IF(U9="",T9,U9)) | W9: =IF(A9="","",INDEX('Task Library'!$H$7:$H$45,MATCH(A9,'Task Library'!$A$7:$A$45,0))) | Y9: =IF(W9="","",IF(X9="",W9,X9)) | Z9: =IF(OR(C9="",D9="",D9<C9),"",SUMPRODUCT((('Date Engine'!$A$7:$A$5850>=C9)*('Date Engine'!$A$7:$A$5850<=D9)*'Date Engine'!$G$7:$G$5850))) | AA9: =IFERROR(SUMPRODUCT((('Date Engine'!$A$7:$A$5850>=C9)*('Date Engine'!$A$7:$A$5850<=D9)*'Date Engine'!$G$7:$G$5850)*'Date Engine'!$H$7:$H$5850)/SUMPRODUCT((('Date Engine'!$A$7:$A$5850>=C9)*('Date Engine'!$A$7:$A$5850<=D9)*'Date Engine'!$G$7:$G$5850)),"") | AB9: =IF(AA9="","",MIN(1,AA9*$B$3)) | AC9: =IF($D$3<>"",$D$3,IFERROR(SUMPRODUCT((('Date Engine'!$A$7:$A$5850>=C9)*('Date Engine'!$A$7:$A$5850<=D9)*'Date Engine'!$G$7:$G$5850)*'Date Engine'!$J$7:$J$5850)/SUMPRODUCT((('Date Engine'!$A$7:$A$5850>=C9)*('Date Engine'!$A$7:$A$5850<=D9)*'Date Engine'!$G$7:$G$5850)),0)) -> 0 | AD9: =IF(OR(AB9="",J9="",M9="",Y9=""),"",AB9*J9*M9*Y9) | AE9: =IF(OR(AB9="",P9="",Y9=""),"",AB9*P9*Y9) | AF9: =IF(OR(S9="",V9="",Y9=""),"",AC9*S9*V9*Y9) | AG9: =IF(A9="","",MIN(1,AD9+AE9+AF9)) | AH9: =IF(A9="","",(F9+G9)*AG9) | AI9: =IF(OR(A9="",Z9=""),"",Z9*AG9) | AJ9: =IF(A9="","",IF(E9="Yes",AI9,0)) | AK9: =IF(A9="","",IF(OR(C9<DATE(2025,1,1),D9>DATE(2040,12,31),D9<C9),"RED - date input",IF(AND(S9>=20%,AC9=0),"RED - wind input",IF($B$3<>1,"AMBER - local factor requires basis","AMBER - task factors uncalibrated"))))
B10: =IF(A10="","",INDEX('Task Library'!$B$7:$B$45,MATCH(A10,'Task Library'!$A$7:$A$45,0))) | E10: No | H10: =IF(A10="","",INDEX('Task Library'!$C$7:$C$45,MATCH(A10,'Task Library'!$A$7:$A$45,0))) | J10: =IF(H10="","",IF(I10="",H10,I10)) | K10: =IF(A10="","",INDEX('Task Library'!$D$7:$D$45,MATCH(A10,'Task Library'!$A$7:$A$45,0))) | M10: =IF(K10="","",IF(L10="",K10,L10)) | N10: =IF(A10="","",INDEX('Task Library'!$E$7:$E$45,MATCH(A10,'Task Library'!$A$7:$A$45,0))) | P10: =IF(N10="","",IF(O10="",N10,O10)) | Q10: =IF(A10="","",INDEX('Task Library'!$F$7:$F$45,MATCH(A10,'Task Library'!$A$7:$A$45,0))) | S10: =IF(Q10="","",IF(R10="",Q10,R10)) | T10: =IF(A10="","",INDEX('Task Library'!$G$7:$G$45,MATCH(A10,'Task Library'!$A$7:$A$45,0))) | V10: =IF(T10="","",IF(U10="",T10,U10)) | W10: =IF(A10="","",INDEX('Task Library'!$H$7:$H$45,MATCH(A10,'Task Library'!$A$7:$A$45,0))) | Y10: =IF(W10="","",IF(X10="",W10,X10)) | Z10: =IF(OR(C10="",D10="",D10<C10),"",SUMPRODUCT((('Date Engine'!$A$7:$A$5850>=C10)*('Date Engine'!$A$7:$A$5850<=D10)*'Date Engine'!$G$7:$G$5850))) | AA10: =IFERROR(SUMPRODUCT((('Date Engine'!$A$7:$A$5850>=C10)*('Date Engine'!$A$7:$A$5850<=D10)*'Date Engine'!$G$7:$G$5850)*'Date Engine'!$H$7:$H$5850)/SUMPRODUCT((('Date Engine'!$A$7:$A$5850>=C10)*('Date Engine'!$A$7:$A$5850<=D10)*'Date Engine'!$G$7:$G$5850)),"") | AB10: =IF(AA10="","",MIN(1,AA10*$B$3)) | AC10: =IF($D$3<>"",$D$3,IFERROR(SUMPRODUCT((('Date Engine'!$A$7:$A$5850>=C10)*('Date Engine'!$A$7:$A$5850<=D10)*'Date Engine'!$G$7:$G$5850)*'Date Engine'!$J$7:$J$5850)/SUMPRODUCT((('Date Engine'!$A$7:$A$5850>=C10)*('Date Engine'!$A$7:$A$5850<=D10)*'Date Engine'!$G$7:$G$5850)),0)) -> 0 | AD10: =IF(OR(AB10="",J10="",M10="",Y10=""),"",AB10*J10*M10*Y10) | AE10: =IF(OR(AB10="",P10="",Y10=""),"",AB10*P10*Y10) | AF10: =IF(OR(S10="",V10="",Y10=""),"",AC10*S10*V10*Y10) | AG10: =IF(A10="","",MIN(1,AD10+AE10+AF10)) | AH10: =IF(A10="","",(F10+G10)*AG10) | AI10: =IF(OR(A10="",Z10=""),"",Z10*AG10) | AJ10: =IF(A10="","",IF(E10="Yes",AI10,0)) | AK10: =IF(A10="","",IF(OR(C10<DATE(2025,1,1),D10>DATE(2040,12,31),D10<C10),"RED - date input",IF(AND(S10>=20%,AC10=0),"RED - wind input",IF($B$3<>1,"AMBER - local factor requires basis","AMBER - task factors uncalibrated"))))
B11: =IF(A11="","",INDEX('Task Library'!$B$7:$B$45,MATCH(A11,'Task Library'!$A$7:$A$45,0))) | E11: No | H11: =IF(A11="","",INDEX('Task Library'!$C$7:$C$45,MATCH(A11,'Task Library'!$A$7:$A$45,0))) | J11: =IF(H11="","",IF(I11="",H11,I11)) | K11: =IF(A11="","",INDEX('Task Library'!$D$7:$D$45,MATCH(A11,'Task Library'!$A$7:$A$45,0))) | M11: =IF(K11="","",IF(L11="",K11,L11)) | N11: =IF(A11="","",INDEX('Task Library'!$E$7:$E$45,MATCH(A11,'Task Library'!$A$7:$A$45,0))) | P11: =IF(N11="","",IF(O11="",N11,O11)) | Q11: =IF(A11="","",INDEX('Task Library'!$F$7:$F$45,MATCH(A11,'Task Library'!$A$7:$A$45,0))) | S11: =IF(Q11="","",IF(R11="",Q11,R11)) | T11: =IF(A11="","",INDEX('Task Library'!$G$7:$G$45,MATCH(A11,'Task Library'!$A$7:$A$45,0))) | V11: =IF(T11="","",IF(U11="",T11,U11)) | W11: =IF(A11="","",INDEX('Task Library'!$H$7:$H$45,MATCH(A11,'Task Library'!$A$7:$A$45,0))) | Y11: =IF(W11="","",IF(X11="",W11,X11)) | Z11: =IF(OR(C11="",D11="",D11<C11),"",SUMPRODUCT((('Date Engine'!$A$7:$A$5850>=C11)*('Date Engine'!$A$7:$A$5850<=D11)*'Date Engine'!$G$7:$G$5850))) | AA11: =IFERROR(SUMPRODUCT((('Date Engine'!$A$7:$A$5850>=C11)*('Date Engine'!$A$7:$A$5850<=D11)*'Date Engine'!$G$7:$G$5850)*'Date Engine'!$H$7:$H$5850)/SUMPRODUCT((('Date Engine'!$A$7:$A$5850>=C11)*('Date Engine'!$A$7:$A$5850<=D11)*'Date Engine'!$G$7:$G$5850)),"") | AB11: =IF(AA11="","",MIN(1,AA11*$B$3)) | AC11: =IF($D$3<>"",$D$3,IFERROR(SUMPRODUCT((('Date Engine'!$A$7:$A$5850>=C11)*('Date Engine'!$A$7:$A$5850<=D11)*'Date Engine'!$G$7:$G$5850)*'Date Engine'!$J$7:$J$5850)/SUMPRODUCT((('Date Engine'!$A$7:$A$5850>=C11)*('Date Engine'!$A$7:$A$5850<=D11)*'Date Engine'!$G$7:$G$5850)),0)) -> 0 | AD11: =IF(OR(AB11="",J11="",M11="",Y11=""),"",AB11*J11*M11*Y11) | AE11: =IF(OR(AB11="",P11="",Y11=""),"",AB11*P11*Y11) | AF11: =IF(OR(S11="",V11="",Y11=""),"",AC11*S11*V11*Y11) | AG11: =IF(A11="","",MIN(1,AD11+AE11+AF11)) | AH11: =IF(A11="","",(F11+G11)*AG11) | AI11: =IF(OR(A11="",Z11=""),"",Z11*AG11) | AJ11: =IF(A11="","",IF(E11="Yes",AI11,0)) | AK11: =IF(A11="","",IF(OR(C11<DATE(2025,1,1),D11>DATE(2040,12,31),D11<C11),"RED - date input",IF(AND(S11>=20%,AC11=0),"RED - wind input",IF($B$3<>1,"AMBER - local factor requires basis","AMBER - task factors uncalibrated"))))
B12: =IF(A12="","",INDEX('Task Library'!$B$7:$B$45,MATCH(A12,'Task Library'!$A$7:$A$45,0))) | E12: No | H12: =IF(A12="","",INDEX('Task Library'!$C$7:$C$45,MATCH(A12,'Task Library'!$A$7:$A$45,0))) | J12: =IF(H12="","",IF(I12="",H12,I12)) | K12: =IF(A12="","",INDEX('Task Library'!$D$7:$D$45,MATCH(A12,'Task Library'!$A$7:$A$45,0))) | M12: =IF(K12="","",IF(L12="",K12,L12)) | N12: =IF(A12="","",INDEX('Task Library'!$E$7:$E$45,MATCH(A12,'Task Library'!$A$7:$A$45,0))) | P12: =IF(N12="","",IF(O12="",N12,O12)) | Q12: =IF(A12="","",INDEX('Task Library'!$F$7:$F$45,MATCH(A12,'Task Library'!$A$7:$A$45,0))) | S12: =IF(Q12="","",IF(R12="",Q12,R12)) | T12: =IF(A12="","",INDEX('Task Library'!$G$7:$G$45,MATCH(A12,'Task Library'!$A$7:$A$45,0))) | V12: =IF(T12="","",IF(U12="",T12,U12)) | W12: =IF(A12="","",INDEX('Task Library'!$H$7:$H$45,MATCH(A12,'Task Library'!$A$7:$A$45,0))) | Y12: =IF(W12="","",IF(X12="",W12,X12)) | Z12: =IF(OR(C12="",D12="",D12<C12),"",SUMPRODUCT((('Date Engine'!$A$7:$A$5850>=C12)*('Date Engine'!$A$7:$A$5850<=D12)*'Date Engine'!$G$7:$G$5850))) | AA12: =IFERROR(SUMPRODUCT((('Date Engine'!$A$7:$A$5850>=C12)*('Date Engine'!$A$7:$A$5850<=D12)*'Date Engine'!$G$7:$G$5850)*'Date Engine'!$H$7:$H$5850)/SUMPRODUCT((('Date Engine'!$A$7:$A$5850>=C12)*('Date Engine'!$A$7:$A$5850<=D12)*'Date Engine'!$G$7:$G$5850)),"") | AB12: =IF(AA12="","",MIN(1,AA12*$B$3)) | AC12: =IF($D$3<>"",$D$3,IFERROR(SUMPRODUCT((('Date Engine'!$A$7:$A$5850>=C12)*('Date Engine'!$A$7:$A$5850<=D12)*'Date Engine'!$G$7:$G$5850)*'Date Engine'!$J$7:$J$5850)/SUMPRODUCT((('Date Engine'!$A$7:$A$5850>=C12)*('Date Engine'!$A$7:$A$5850<=D12)*'Date Engine'!$G$7:$G$5850)),0)) -> 0 | AD12: =IF(OR(AB12="",J12="",M12="",Y12=""),"",AB12*J12*M12*Y12) | AE12: =IF(OR(AB12="",P12="",Y12=""),"",AB12*P12*Y12) | AF12: =IF(OR(S12="",V12="",Y12=""),"",AC12*S12*V12*Y12) | AG12: =IF(A12="","",MIN(1,AD12+AE12+AF12)) | AH12: =IF(A12="","",(F12+G12)*AG12) | AI12: =IF(OR(A12="",Z12=""),"",Z12*AG12) | AJ12: =IF(A12="","",IF(E12="Yes",AI12,0)) | AK12: =IF(A12="","",IF(OR(C12<DATE(2025,1,1),D12>DATE(2040,12,31),D12<C12),"RED - date input",IF(AND(S12>=20%,AC12=0),"RED - wind input",IF($B$3<>1,"AMBER - local factor requires basis","AMBER - task factors uncalibrated"))))
B13: =IF(A13="","",INDEX('Task Library'!$B$7:$B$45,MATCH(A13,'Task Library'!$A$7:$A$45,0))) | E13: No | H13: =IF(A13="","",INDEX('Task Library'!$C$7:$C$45,MATCH(A13,'Task Library'!$A$7:$A$45,0))) | J13: =IF(H13="","",IF(I13="",H13,I13)) | K13: =IF(A13="","",INDEX('Task Library'!$D$7:$D$45,MATCH(A13,'Task Library'!$A$7:$A$45,0))) | M13: =IF(K13="","",IF(L13="",K13,L13)) | N13: =IF(A13="","",INDEX('Task Library'!$E$7:$E$45,MATCH(A13,'Task Library'!$A$7:$A$45,0))) | P13: =IF(N13="","",IF(O13="",N13,O13)) | Q13: =IF(A13="","",INDEX('Task Library'!$F$7:$F$45,MATCH(A13,'Task Library'!$A$7:$A$45,0))) | S13: =IF(Q13="","",IF(R13="",Q13,R13)) | T13: =IF(A13="","",INDEX('Task Library'!$G$7:$G$45,MATCH(A13,'Task Library'!$A$7:$A$45,0))) | V13: =IF(T13="","",IF(U13="",T13,U13)) | W13: =IF(A13="","",INDEX('Task Library'!$H$7:$H$45,MATCH(A13,'Task Library'!$A$7:$A$45,0))) | Y13: =IF(W13="","",IF(X13="",W13,X13)) | Z13: =IF(OR(C13="",D13="",D13<C13),"",SUMPRODUCT((('Date Engine'!$A$7:$A$5850>=C13)*('Date Engine'!$A$7:$A$5850<=D13)*'Date Engine'!$G$7:$G$5850))) | AA13: =IFERROR(SUMPRODUCT((('Date Engine'!$A$7:$A$5850>=C13)*('Date Engine'!$A$7:$A$5850<=D13)*'Date Engine'!$G$7:$G$5850)*'Date Engine'!$H$7:$H$5850)/SUMPRODUCT((('Date Engine'!$A$7:$A$5850>=C13)*('Date Engine'!$A$7:$A$5850<=D13)*'Date Engine'!$G$7:$G$5850)),"") | AB13: =IF(AA13="","",MIN(1,AA13*$B$3)) | AC13: =IF($D$3<>"",$D$3,IFERROR(SUMPRODUCT((('Date Engine'!$A$7:$A$5850>=C13)*('Date Engine'!$A$7:$A$5850<=D13)*'Date Engine'!$G$7:$G$5850)*'Date Engine'!$J$7:$J$5850)/SUMPRODUCT((('Date Engine'!$A$7:$A$5850>=C13)*('Date Engine'!$A$7:$A$5850<=D13)*'Date Engine'!$G$7:$G$5850)),0)) -> 0 | AD13: =IF(OR(AB13="",J13="",M13="",Y13=""),"",AB13*J13*M13*Y13) | AE13: =IF(OR(AB13="",P13="",Y13=""),"",AB13*P13*Y13) | AF13: =IF(OR(S13="",V13="",Y13=""),"",AC13*S13*V13*Y13) | AG13: =IF(A13="","",MIN(1,AD13+AE13+AF13)) | AH13: =IF(A13="","",(F13+G13)*AG13) | AI13: =IF(OR(A13="",Z13=""),"",Z13*AG13) | AJ13: =IF(A13="","",IF(E13="Yes",AI13,0)) | AK13: =IF(A13="","",IF(OR(C13<DATE(2025,1,1),D13>DATE(2040,12,31),D13<C13),"RED - date input",IF(AND(S13>=20%,AC13=0),"RED - wind input",IF($B$3<>1,"AMBER - local factor requires basis","AMBER - task factors uncalibrated"))))
B14: =IF(A14="","",INDEX('Task Library'!$B$7:$B$45,MATCH(A14,'Task Library'!$A$7:$A$45,0))) | E14: No | H14: =IF(A14="","",INDEX('Task Library'!$C$7:$C$45,MATCH(A14,'Task Library'!$A$7:$A$45,0))) | J14: =IF(H14="","",IF(I14="",H14,I14)) | K14: =IF(A14="","",INDEX('Task Library'!$D$7:$D$45,MATCH(A14,'Task Library'!$A$7:$A$45,0))) | M14: =IF(K14="","",IF(L14="",K14,L14)) | N14: =IF(A14="","",INDEX('Task Library'!$E$7:$E$45,MATCH(A14,'Task Library'!$A$7:$A$45,0))) | P14: =IF(N14="","",IF(O14="",N14,O14)) | Q14: =IF(A14="","",INDEX('Task Library'!$F$7:$F$45,MATCH(A14,'Task Library'!$A$7:$A$45,0))) | S14: =IF(Q14="","",IF(R14="",Q14,R14)) | T14: =IF(A14="","",INDEX('Task Library'!$G$7:$G$45,MATCH(A14,'Task Library'!$A$7:$A$45,0))) | V14: =IF(T14="","",IF(U14="",T14,U14)) | W14: =IF(A14="","",INDEX('Task Library'!$H$7:$H$45,MATCH(A14,'Task Library'!$A$7:$A$45,0))) | Y14: =IF(W14="","",IF(X14="",W14,X14)) | Z14: =IF(OR(C14="",D14="",D14<C14),"",SUMPRODUCT((('Date Engine'!$A$7:$A$5850>=C14)*('Date Engine'!$A$7:$A$5850<=D14)*'Date Engine'!$G$7:$G$5850))) | AA14: =IFERROR(SUMPRODUCT((('Date Engine'!$A$7:$A$5850>=C14)*('Date Engine'!$A$7:$A$5850<=D14)*'Date Engine'!$G$7:$G$5850)*'Date Engine'!$H$7:$H$5850)/SUMPRODUCT((('Date Engine'!$A$7:$A$5850>=C14)*('Date Engine'!$A$7:$A$5850<=D14)*'Date Engine'!$G$7:$G$5850)),"") | AB14: =IF(AA14="","",MIN(1,AA14*$B$3)) | AC14: =IF($D$3<>"",$D$3,IFERROR(SUMPRODUCT((('Date Engine'!$A$7:$A$5850>=C14)*('Date Engine'!$A$7:$A$5850<=D14)*'Date Engine'!$G$7:$G$5850)*'Date Engine'!$J$7:$J$5850)/SUMPRODUCT((('Date Engine'!$A$7:$A$5850>=C14)*('Date Engine'!$A$7:$A$5850<=D14)*'Date Engine'!$G$7:$G$5850)),0)) -> 0 | AD14: =IF(OR(AB14="",J14="",M14="",Y14=""),"",AB14*J14*M14*Y14) | AE14: =IF(OR(AB14="",P14="",Y14=""),"",AB14*P14*Y14) | AF14: =IF(OR(S14="",V14="",Y14=""),"",AC14*S14*V14*Y14) | AG14: =IF(A14="","",MIN(1,AD14+AE14+AF14)) | AH14: =IF(A14="","",(F14+G14)*AG14) | AI14: =IF(OR(A14="",Z14=""),"",Z14*AG14) | AJ14: =IF(A14="","",IF(E14="Yes",AI14,0)) | AK14: =IF(A14="","",IF(OR(C14<DATE(2025,1,1),D14>DATE(2040,12,31),D14<C14),"RED - date input",IF(AND(S14>=20%,AC14=0),"RED - wind input",IF($B$3<>1,"AMBER - local factor requires basis","AMBER - task factors uncalibrated"))))
B15: =IF(A15="","",INDEX('Task Library'!$B$7:$B$45,MATCH(A15,'Task Library'!$A$7:$A$45,0))) | E15: No | H15: =IF(A15="","",INDEX('Task Library'!$C$7:$C$45,MATCH(A15,'Task Library'!$A$7:$A$45,0))) | J15: =IF(H15="","",IF(I15="",H15,I15)) | K15: =IF(A15="","",INDEX('Task Library'!$D$7:$D$45,MATCH(A15,'Task Library'!$A$7:$A$45,0))) | M15: =IF(K15="","",IF(L15="",K15,L15)) | N15: =IF(A15="","",INDEX('Task Library'!$E$7:$E$45,MATCH(A15,'Task Library'!$A$7:$A$45,0))) | P15: =IF(N15="","",IF(O15="",N15,O15)) | Q15: =IF(A15="","",INDEX('Task Library'!$F$7:$F$45,MATCH(A15,'Task Library'!$A$7:$A$45,0))) | S15: =IF(Q15="","",IF(R15="",Q15,R15)) | T15: =IF(A15="","",INDEX('Task Library'!$G$7:$G$45,MATCH(A15,'Task Library'!$A$7:$A$45,0))) | V15: =IF(T15="","",IF(U15="",T15,U15)) | W15: =IF(A15="","",INDEX('Task Library'!$H$7:$H$45,MATCH(A15,'Task Library'!$A$7:$A$45,0))) | Y15: =IF(W15="","",IF(X15="",W15,X15)) | Z15: =IF(OR(C15="",D15="",D15<C15),"",SUMPRODUCT((('Date Engine'!$A$7:$A$5850>=C15)*('Date Engine'!$A$7:$A$5850<=D15)*'Date Engine'!$G$7:$G$5850))) | AA15: =IFERROR(SUMPRODUCT((('Date Engine'!$A$7:$A$5850>=C15)*('Date Engine'!$A$7:$A$5850<=D15)*'Date Engine'!$G$7:$G$5850)*'Date Engine'!$H$7:$H$5850)/SUMPRODUCT((('Date Engine'!$A$7:$A$5850>=C15)*('Date Engine'!$A$7:$A$5850<=D15)*'Date Engine'!$G$7:$G$5850)),"") | AB15: =IF(AA15="","",MIN(1,AA15*$B$3)) | AC15: =IF($D$3<>"",$D$3,IFERROR(SUMPRODUCT((('Date Engine'!$A$7:$A$5850>=C15)*('Date Engine'!$A$7:$A$5850<=D15)*'Date Engine'!$G$7:$G$5850)*'Date Engine'!$J$7:$J$5850)/SUMPRODUCT((('Date Engine'!$A$7:$A$5850>=C15)*('Date Engine'!$A$7:$A$5850<=D15)*'Date Engine'!$G$7:$G$5850)),0)) -> 0 | AD15: =IF(OR(AB15="",J15="",M15="",Y15=""),"",AB15*J15*M15*Y15) | AE15: =IF(OR(AB15="",P15="",Y15=""),"",AB15*P15*Y15) | AF15: =IF(OR(S15="",V15="",Y15=""),"",AC15*S15*V15*Y15) | AG15: =IF(A15="","",MIN(1,AD15+AE15+AF15)) | AH15: =IF(A15="","",(F15+G15)*AG15) | AI15: =IF(OR(A15="",Z15=""),"",Z15*AG15) | AJ15: =IF(A15="","",IF(E15="Yes",AI15,0)) | AK15: =IF(A15="","",IF(OR(C15<DATE(2025,1,1),D15>DATE(2040,12,31),D15<C15),"RED - date input",IF(AND(S15>=20%,AC15=0),"RED - wind input",IF($B$3<>1,"AMBER - local factor requires basis","AMBER - task factors uncalibrated"))))
B16: =IF(A16="","",INDEX('Task Library'!$B$7:$B$45,MATCH(A16,'Task Library'!$A$7:$A$45,0))) | E16: No | H16: =IF(A16="","",INDEX('Task Library'!$C$7:$C$45,MATCH(A16,'Task Library'!$A$7:$A$45,0))) | J16: =IF(H16="","",IF(I16="",H16,I16)) | K16: =IF(A16="","",INDEX('Task Library'!$D$7:$D$45,MATCH(A16,'Task Library'!$A$7:$A$45,0))) | M16: =IF(K16="","",IF(L16="",K16,L16)) | N16: =IF(A16="","",INDEX('Task Library'!$E$7:$E$45,MATCH(A16,'Task Library'!$A$7:$A$45,0))) | P16: =IF(N16="","",IF(O16="",N16,O16)) | Q16: =IF(A16="","",INDEX('Task Library'!$F$7:$F$45,MATCH(A16,'Task Library'!$A$7:$A$45,0))) | S16: =IF(Q16="","",IF(R16="",Q16,R16)) | T16: =IF(A16="","",INDEX('Task Library'!$G$7:$G$45,MATCH(A16,'Task Library'!$A$7:$A$45,0))) | V16: =IF(T16="","",IF(U16="",T16,U16)) | W16: =IF(A16="","",INDEX('Task Library'!$H$7:$H$45,MATCH(A16,'Task Library'!$A$7:$A$45,0))) | Y16: =IF(W16="","",IF(X16="",W16,X16)) | Z16: =IF(OR(C16="",D16="",D16<C16),"",SUMPRODUCT((('Date Engine'!$A$7:$A$5850>=C16)*('Date Engine'!$A$7:$A$5850<=D16)*'Date Engine'!$G$7:$G$5850))) | AA16: =IFERROR(SUMPRODUCT((('Date Engine'!$A$7:$A$5850>=C16)*('Date Engine'!$A$7:$A$5850<=D16)*'Date Engine'!$G$7:$G$5850)*'Date Engine'!$H$7:$H$5850)/SUMPRODUCT((('Date Engine'!$A$7:$A$5850>=C16)*('Date Engine'!$A$7:$A$5850<=D16)*'Date Engine'!$G$7:$G$5850)),"") | AB16: =IF(AA16="","",MIN(1,AA16*$B$3)) | AC16: =IF($D$3<>"",$D$3,IFERROR(SUMPRODUCT((('Date Engine'!$A$7:$A$5850>=C16)*('Date Engine'!$A$7:$A$5850<=D16)*'Date Engine'!$G$7:$G$5850)*'Date Engine'!$J$7:$J$5850)/SUMPRODUCT((('Date Engine'!$A$7:$A$5850>=C16)*('Date Engine'!$A$7:$A$5850<=D16)*'Date Engine'!$G$7:$G$5850)),0)) -> 0 | AD16: =IF(OR(AB16="",J16="",M16="",Y16=""),"",AB16*J16*M16*Y16) | AE16: =IF(OR(AB16="",P16="",Y16=""),"",AB16*P16*Y16) | AF16: =IF(OR(S16="",V16="",Y16=""),"",AC16*S16*V16*Y16) | AG16: =IF(A16="","",MIN(1,AD16+AE16+AF16)) | AH16: =IF(A16="","",(F16+G16)*AG16) | AI16: =IF(OR(A16="",Z16=""),"",Z16*AG16) | AJ16: =IF(A16="","",IF(E16="Yes",AI16,0)) | AK16: =IF(A16="","",IF(OR(C16<DATE(2025,1,1),D16>DATE(2040,12,31),D16<C16),"RED - date input",IF(AND(S16>=20%,AC16=0),"RED - wind input",IF($B$3<>1,"AMBER - local factor requires basis","AMBER - task factors uncalibrated"))))
B17: =IF(A17="","",INDEX('Task Library'!$B$7:$B$45,MATCH(A17,'Task Library'!$A$7:$A$45,0))) | E17: No | H17: =IF(A17="","",INDEX('Task Library'!$C$7:$C$45,MATCH(A17,'Task Library'!$A$7:$A$45,0))) | J17: =IF(H17="","",IF(I17="",H17,I17)) | K17: =IF(A17="","",INDEX('Task Library'!$D$7:$D$45,MATCH(A17,'Task Library'!$A$7:$A$45,0))) | M17: =IF(K17="","",IF(L17="",K17,L17)) | N17: =IF(A17="","",INDEX('Task Library'!$E$7:$E$45,MATCH(A17,'Task Library'!$A$7:$A$45,0))) | P17: =IF(N17="","",IF(O17="",N17,O17)) | Q17: =IF(A17="","",INDEX('Task Library'!$F$7:$F$45,MATCH(A17,'Task Library'!$A$7:$A$45,0))) | S17: =IF(Q17="","",IF(R17="",Q17,R17)) | T17: =IF(A17="","",INDEX('Task Library'!$G$7:$G$45,MATCH(A17,'Task Library'!$A$7:$A$45,0))) | V17: =IF(T17="","",IF(U17="",T17,U17)) | W17: =IF(A17="","",INDEX('Task Library'!$H$7:$H$45,MATCH(A17,'Task Library'!$A$7:$A$45,0))) | Y17: =IF(W17="","",IF(X17="",W17,X17)) | Z17: =IF(OR(C17="",D17="",D17<C17),"",SUMPRODUCT((('Date Engine'!$A$7:$A$5850>=C17)*('Date Engine'!$A$7:$A$5850<=D17)*'Date Engine'!$G$7:$G$5850))) | AA17: =IFERROR(SUMPRODUCT((('Date Engine'!$A$7:$A$5850>=C17)*('Date Engine'!$A$7:$A$5850<=D17)*'Date Engine'!$G$7:$G$5850)*'Date Engine'!$H$7:$H$5850)/SUMPRODUCT((('Date Engine'!$A$7:$A$5850>=C17)*('Date Engine'!$A$7:$A$5850<=D17)*'Date Engine'!$G$7:$G$5850)),"") | AB17: =IF(AA17="","",MIN(1,AA17*$B$3)) | AC17: =IF($D$3<>"",$D$3,IFERROR(SUMPRODUCT((('Date Engine'!$A$7:$A$5850>=C17)*('Date Engine'!$A$7:$A$5850<=D17)*'Date Engine'!$G$7:$G$5850)*'Date Engine'!$J$7:$J$5850)/SUMPRODUCT((('Date Engine'!$A$7:$A$5850>=C17)*('Date Engine'!$A$7:$A$5850<=D17)*'Date Engine'!$G$7:$G$5850)),0)) -> 0 | AD17: =IF(OR(AB17="",J17="",M17="",Y17=""),"",AB17*J17*M17*Y17) | AE17: =IF(OR(AB17="",P17="",Y17=""),"",AB17*P17*Y17) | AF17: =IF(OR(S17="",V17="",Y17=""),"",AC17*S17*V17*Y17) | AG17: =IF(A17="","",MIN(1,AD17+AE17+AF17)) | AH17: =IF(A17="","",(F17+G17)*AG17) | AI17: =IF(OR(A17="",Z17=""),"",Z17*AG17) | AJ17: =IF(A17="","",IF(E17="Yes",AI17,0)) | AK17: =IF(A17="","",IF(OR(C17<DATE(2025,1,1),D17>DATE(2040,12,31),D17<C17),"RED - date input",IF(AND(S17>=20%,AC17=0),"RED - wind input",IF($B$3<>1,"AMBER - local factor requires basis","AMBER - task factors uncalibrated"))))
B18: =IF(A18="","",INDEX('Task Library'!$B$7:$B$45,MATCH(A18,'Task Library'!$A$7:$A$45,0))) | E18: No | H18: =IF(A18="","",INDEX('Task Library'!$C$7:$C$45,MATCH(A18,'Task Library'!$A$7:$A$45,0))) | J18: =IF(H18="","",IF(I18="",H18,I18)) | K18: =IF(A18="","",INDEX('Task Library'!$D$7:$D$45,MATCH(A18,'Task Library'!$A$7:$A$45,0))) | M18: =IF(K18="","",IF(L18="",K18,L18)) | N18: =IF(A18="","",INDEX('Task Library'!$E$7:$E$45,MATCH(A18,'Task Library'!$A$7:$A$45,0))) | P18: =IF(N18="","",IF(O18="",N18,O18)) | Q18: =IF(A18="","",INDEX('Task Library'!$F$7:$F$45,MATCH(A18,'Task Library'!$A$7:$A$45,0))) | S18: =IF(Q18="","",IF(R18="",Q18,R18)) | T18: =IF(A18="","",INDEX('Task Library'!$G$7:$G$45,MATCH(A18,'Task Library'!$A$7:$A$45,0))) | V18: =IF(T18="","",IF(U18="",T18,U18)) | W18: =IF(A18="","",INDEX('Task Library'!$H$7:$H$45,MATCH(A18,'Task Library'!$A$7:$A$45,0))) | Y18: =IF(W18="","",IF(X18="",W18,X18)) | Z18: =IF(OR(C18="",D18="",D18<C18),"",SUMPRODUCT((('Date Engine'!$A$7:$A$5850>=C18)*('Date Engine'!$A$7:$A$5850<=D18)*'Date Engine'!$G$7:$G$5850))) | AA18: =IFERROR(SUMPRODUCT((('Date Engine'!$A$7:$A$5850>=C18)*('Date Engine'!$A$7:$A$5850<=D18)*'Date Engine'!$G$7:$G$5850)*'Date Engine'!$H$7:$H$5850)/SUMPRODUCT((('Date Engine'!$A$7:$A$5850>=C18)*('Date Engine'!$A$7:$A$5850<=D18)*'Date Engine'!$G$7:$G$5850)),"") | AB18: =IF(AA18="","",MIN(1,AA18*$B$3)) | AC18: =IF($D$3<>"",$D$3,IFERROR(SUMPRODUCT((('Date Engine'!$A$7:$A$5850>=C18)*('Date Engine'!$A$7:$A$5850<=D18)*'Date Engine'!$G$7:$G$5850)*'Date Engine'!$J$7:$J$5850)/SUMPRODUCT((('Date Engine'!$A$7:$A$5850>=C18)*('Date Engine'!$A$7:$A$5850<=D18)*'Date Engine'!$G$7:$G$5850)),0)) -> 0 | AD18: =IF(OR(AB18="",J18="",M18="",Y18=""),"",AB18*J18*M18*Y18) | AE18: =IF(OR(AB18="",P18="",Y18=""),"",AB18*P18*Y18) | AF18: =IF(OR(S18="",V18="",Y18=""),"",AC18*S18*V18*Y18) | AG18: =IF(A18="","",MIN(1,AD18+AE18+AF18)) | AH18: =IF(A18="","",(F18+G18)*AG18) | AI18: =IF(OR(A18="",Z18=""),"",Z18*AG18) | AJ18: =IF(A18="","",IF(E18="Yes",AI18,0)) | AK18: =IF(A18="","",IF(OR(C18<DATE(2025,1,1),D18>DATE(2040,12,31),D18<C18),"RED - date input",IF(AND(S18>=20%,AC18=0),"RED - wind input",IF($B$3<>1,"AMBER - local factor requires basis","AMBER - task factors uncalibrated"))))
... B36: =IF(A36="","",INDEX('Task Library'!$B$7:$B$45,MATCH(A36,'Task Library'!$A$7:$A$45,0))) | E36: No | H36: =IF(A36="","",INDEX('Task Library'!$C$7:$C$45,MATCH(A36,'Task Library'!$A$7:$A$45,0))) | J36: =IF(H36="","",IF(I36="",H36,I36)) | K36: =IF(A36="","",INDEX('Task Library'!$D$7:$D$45,MATCH(A36,'Task Library'!$A$7:$A$45,0))) | M36: =IF(K36="","",IF(L36="",K36,L36)) | N36: =IF(A36="","",INDEX('Task Library'!$E$7:$E$45,MATCH(A36,'Task Library'!$A$7:$A$45,0))) | P36: =IF(N36="","",IF(O36="",N36,O36)) | Q36: =IF(A36="","",INDEX('Task Library'!$F$7:$F$45,MATCH(A36,'Task Library'!$A$7:$A$45,0))) | S36: =IF(Q36="","",IF(R36="",Q36,R36)) | T36: =IF(A36="","",INDEX('Task Library'!$G$7:$G$45,MATCH(A36,'Task Library'!$A$7:$A$45,0))) | V36: =IF(T36="","",IF(U36="",T36,U36)) | W36: =IF(A36="","",INDEX('Task Library'!$H$7:$H$45,MATCH(A36,'Task Library'!$A$7:$A$45,0))) | Y36: =IF(W36="","",IF(X36="",W36,X36)) | Z36: =IF(OR(C36="",D36="",D36<C36),"",SUMPRODUCT((('Date Engine'!$A$7:$A$5850>=C36)*('Date Engine'!$A$7:$A$5850<=D36)*'Date Engine'!$G$7:$G$5850))) | AA36: =IFERROR(SUMPRODUCT((('Date Engine'!$A$7:$A$5850>=C36)*('Date Engine'!$A$7:$A$5850<=D36)*'Date Engine'!$G$7:$G$5850)*'Date Engine'!$H$7:$H$5850)/SUMPRODUCT((('Date Engine'!$A$7:$A$5850>=C36)*('Date Engine'!$A$7:$A$5850<=D36)*'Date Engine'!$G$7:$G$5850)),"") | AB36: =IF(AA36="","",MIN(1,AA36*$B$3)) | AC36: =IF($D$3<>"",$D$3,IFERROR(SUMPRODUCT((('Date Engine'!$A$7:$A$5850>=C36)*('Date Engine'!$A$7:$A$5850<=D36)*'Date Engine'!$G$7:$G$5850)*'Date Engine'!$J$7:$J$5850)/SUMPRODUCT((('Date Engine'!$A$7:$A$5850>=C36)*('Date Engine'!$A$7:$A$5850<=D36)*'Date Engine'!$G$7:$G$5850)),0)) -> 0 | AD36: =IF(OR(AB36="",J36="",M36="",Y36=""),"",AB36*J36*M36*Y36) | AE36: =IF(OR(AB36="",P36="",Y36=""),"",AB36*P36*Y36) | AF36: =IF(OR(S36="",V36="",Y36=""),"",AC36*S36*V36*Y36) | AG36: =IF(A36="","",MIN(1,AD36+AE36+AF36)) | AH36: =IF(A36="","",(F36+G36)*AG36) | AI36: =IF(OR(A36="",Z36=""),"",Z36*AG36) | AJ36: =IF(A36="","",IF(E36="Yes",AI36,0)) | AK36: =IF(A36="","",IF(OR(C36<DATE(2025,1,1),D36>DATE(2040,12,31),D36<C36),"RED - date input",IF(AND(S36>=20%,AC36=0),"RED - wind input",IF($B$3<>1,"AMBER - local factor requires basis","AMBER - task factors uncalibrated"))))
A38: Project Weather Summary | B38: Project Weather Summary | C38: Project Weather Summary | D38: Project Weather Summary | E38: Project Weather Summary | F38: Project Weather Summary | G38: Project Weather Summary | H38: Project Weather Summary
A39: Exposed labour + plant $ | B39: =SUM(F7:G36) -> 0 | D39: Use this summary in the estimate only after: 1. Activities and dates align with the live programme. 2. Critical Path = Yes reflects the real critical path, not every weather-sensitive task. 3. Labour and plant values include only weather-exposed cost pools. 4. RED inputs are resolved or expressly excluded. 5. AMBER task factors are disclosed and assigned a firm-up action.
A40: Direct productivity allowance $ | B40: =SUM(AH7:AH36) -> 0
A41: Suggested critical-path delay working days | B41: =SUM(AJ7:AJ36) -> 0
A42: Time-related preliminaries allowance $ | B42: =B41*$F$3 -> 0
A43: Additional billed hire weeks | B43: =IF(B41=0,0,ROUNDUP(B41/Estimator!$B$7,0)) -> 0
A44: Hire / facilities allowance $ | B44: =B43*$H$3 -> 0
A45: Project recovery / remediation allowance $ | B45: =$J$3 -> 0
A46: Total weather allowance $ | B46: =SUM(B40,B42,B44:B45) -> 0

Sheet Task Library
A1: Task Weather Sensitivity Library - Company Defaults | B1: Task Weather Sensitivity Library - Company Defaults | C1: Task Weather Sensitivity Library - Company Defaults | D1: Task Weather Sensitivity Library - Company Defaults | E1: Task Weather Sensitivity Library - Company Defaults | F1: Task Weather Sensitivity Library - Company Defaults | G1: Task Weather Sensitivity Library - Company Defaults | H1: Task Weather Sensitivity Library - Company Defaults | I1: Task Weather Sensitivity Library - Company Defaults | J1: Task Weather Sensitivity Library - Company Defaults | K1: Task Weather Sensitivity Library - Company Defaults | L1: Task Weather Sensitivity Library - Company Defaults | M1: Task Weather Sensitivity Library - Company Defaults | N1: Task Weather Sensitivity Library - Company Defaults | O1: Task Weather Sensitivity Library - Company Defaults
A3: These defaults are transparent company judgement, not NIWA facts. They remain AMBER until calibrated against actual project records and independently reviewed. Override only with a recorded job-specific basis. Wet-ground carryover is an equivalent lost-day fraction following each wet day, not a guaranteed shutdown.
A6: Task | B6: Category | C6: Rain Exposure | D6: Rain Productivity Loss | E6: Wet-Ground Carryover Eq. Days / Wet Day | F6: Wind Sensitivity | G6: Wind Productivity Loss | H6: Nonrecoverable Share | I6: Default Status | J6: Actual Records | K6: Calibration Status | L6: Original Basis Note | M6: Required Review Action | N6: Approved By | O6: Approved Date
A7: Site establishment / temp fencing | B7: Civil | C7: 0.35 | D7: 0.20 | E7: 0.02 | F7: 0.10 | G7: 0.20 | H7: 0.40 | I7: AMBER - company judgement | J7: =COUNTIF('Weather Log'!$D$7:$D$206,A7) -> 0 | K7: =IF(J7=0,"UNCALIBRATED",IF(J7<5,"PARTIAL - fewer than 5 records",IF(J7<10,"AMBER - 5 to 9 records","REVIEW FOR GREEN - 10+ records"))) -> UNCALIBRATED | L7: General outdoor set-up, usually partly workable. | M7: Calibrate from Weather Log and obtain estimator/PM approval before GREEN.
A8: Erosion & sediment controls | B8: Civil | C8: 0.85 | D8: 0.50 | E8: 0.08 | F8: 0.20 | G8: 0.50 | H8: 0.70 | I8: AMBER - company judgement | J8: =COUNTIF('Weather Log'!$D$7:$D$206,A8) -> 0 | K8: =IF(J8=0,"UNCALIBRATED",IF(J8<5,"PARTIAL - fewer than 5 records",IF(J8<10,"AMBER - 5 to 9 records","REVIEW FOR GREEN - 10+ records"))) -> UNCALIBRATED | L8: Often still required in wet weather, but slower and messier. | M8: Calibrate from Weather Log and obtain estimator/PM approval before GREEN.
A9: Bulk earthworks | B9: Civil | C9: 1.00 | D9: 0.70 | E9: 0.2 | F9: 0.15 | G9: 0.70 | H9: 0.85 | I9: AMBER - company judgement | J9: =COUNTIF('Weather Log'!$D$7:$D$206,A9) -> 0 | K9: =IF(J9=0,"UNCALIBRATED",IF(J9<5,"PARTIAL - fewer than 5 records",IF(J9<10,"AMBER - 5 to 9 records","REVIEW FOR GREEN - 10+ records"))) -> UNCALIBRATED | L9: Highly exposed to wet ground and access deterioration. | M9: Calibrate from Weather Log and obtain estimator/PM approval before GREEN.
A10: Detailed earthworks / trim subgrade | B10: Civil | C10: 1.00 | D10: 0.80 | E10: 0.25 | F10: 0.15 | G10: 0.80 | H10: 0.90 | I10: AMBER - company judgement | J10: =COUNTIF('Weather Log'!$D$7:$D$206,A10) -> 0 | K10: =IF(J10=0,"UNCALIBRATED",IF(J10<5,"PARTIAL - fewer than 5 records",IF(J10<10,"AMBER - 5 to 9 records","REVIEW FOR GREEN - 10+ records"))) -> UNCALIBRATED | L10: Fine tolerances make wet conditions painful. | M10: Calibrate from Weather Log and obtain estimator/PM approval before GREEN.
A11: Cut to fill / cartage | B11: Civil | C11: 0.95 | D11: 0.65 | E11: 0.15 | F11: 0.10 | G11: 0.65 | H11: 0.80 | I11: AMBER - company judgement | J11: =COUNTIF('Weather Log'!$D$7:$D$206,A11) -> 0 | K11: =IF(J11=0,"UNCALIBRATED",IF(J11<5,"PARTIAL - fewer than 5 records",IF(J11<10,"AMBER - 5 to 9 records","REVIEW FOR GREEN - 10+ records"))) -> UNCALIBRATED | L11: Wet haul roads and loaded traffic slow the whole chain. | M11: Calibrate from Weather Log and obtain estimator/PM approval before GREEN.
A12: Building platform / pad prep | B12: Civil | C12: 0.95 | D12: 0.75 | E12: 0.2 | F12: 0.10 | G12: 0.75 | H12: 0.85 | I12: AMBER - company judgement | J12: =COUNTIF('Weather Log'!$D$7:$D$206,A12) -> 0 | K12: =IF(J12=0,"UNCALIBRATED",IF(J12<5,"PARTIAL - fewer than 5 records",IF(J12<10,"AMBER - 5 to 9 records","REVIEW FOR GREEN - 10+ records"))) -> UNCALIBRATED | L12: Moisture condition and compaction control matter. | M12: Calibrate from Weather Log and obtain estimator/PM approval before GREEN.
A13: Drainage trenching | B13: Civil | C13: 0.95 | D13: 0.65 | E13: 0.15 | F13: 0.10 | G13: 0.65 | H13: 0.80 | I13: AMBER - company judgement | J13: =COUNTIF('Weather Log'!$D$7:$D$206,A13) -> 0 | K13: =IF(J13=0,"UNCALIBRATED",IF(J13<5,"PARTIAL - fewer than 5 records",IF(J13<10,"AMBER - 5 to 9 records","REVIEW FOR GREEN - 10+ records"))) -> UNCALIBRATED | L13: Water ingress, slumping, and access issues. | M13: Calibrate from Weather Log and obtain estimator/PM approval before GREEN.
A14: Manholes / chambers | B14: Civil | C14: 0.90 | D14: 0.60 | E14: 0.08 | F14: 0.05 | G14: 0.60 | H14: 0.75 | I14: AMBER - company judgement | J14: =COUNTIF('Weather Log'!$D$7:$D$206,A14) -> 0 | K14: =IF(J14=0,"UNCALIBRATED",IF(J14<5,"PARTIAL - fewer than 5 records",IF(J14<10,"AMBER - 5 to 9 records","REVIEW FOR GREEN - 10+ records"))) -> UNCALIBRATED | L14: Less affected than open trench runs, but still exposed. | M14: Calibrate from Weather Log and obtain estimator/PM approval before GREEN.
A15: Service trenches / ducting | B15: Civil | C15: 0.90 | D15: 0.60 | E15: 0.1 | F15: 0.10 | G15: 0.60 | H15: 0.75 | I15: AMBER - company judgement | J15: =COUNTIF('Weather Log'!$D$7:$D$206,A15) -> 0 | K15: =IF(J15=0,"UNCALIBRATED",IF(J15<5,"PARTIAL - fewer than 5 records",IF(J15<10,"AMBER - 5 to 9 records","REVIEW FOR GREEN - 10+ records"))) -> UNCALIBRATED | L15: Small but still sensitive to rain and reinstatement. | M15: Calibrate from Weather Log and obtain estimator/PM approval before GREEN.
A16: Bored piles / drilled holes | B16: Civil | C16: 1.00 | D16: 0.70 | E16: 0.15 | F16: 0.15 | G16: 0.70 | H16: 0.85 | I16: AMBER - company judgement | J16: =COUNTIF('Weather Log'!$D$7:$D$206,A16) -> 0 | K16: =IF(J16=0,"UNCALIBRATED",IF(J16<5,"PARTIAL - fewer than 5 records",IF(J16<10,"AMBER - 5 to 9 records","REVIEW FOR GREEN - 10+ records"))) -> UNCALIBRATED | L16: Wet ground and hole stability are key risks. | M16: Calibrate from Weather Log and obtain estimator/PM approval before GREEN.
A17: Driven poles / posts | B17: Civil | C17: 0.95 | D17: 0.60 | E17: 0.05 | F17: 0.20 | G17: 0.60 | H17: 0.80 | I17: AMBER - company judgement | J17: =COUNTIF('Weather Log'!$D$7:$D$206,A17) -> 0 | K17: =IF(J17=0,"UNCALIBRATED",IF(J17<5,"PARTIAL - fewer than 5 records",IF(J17<10,"AMBER - 5 to 9 records","REVIEW FOR GREEN - 10+ records"))) -> UNCALIBRATED | L17: Weather affects access and standing time. | M17: Calibrate from Weather Log and obtain estimator/PM approval before GREEN.
A18: Retaining wall excavation | B18: Civil | C18: 0.95 | D18: 0.70 | E18: 0.15 | F18: 0.10 | G18: 0.70 | H18: 0.85 | I18: AMBER - company judgement | J18: =COUNTIF('Weather Log'!$D$7:$D$206,A18) -> 0 | K18: =IF(J18=0,"UNCALIBRATED",IF(J18<5,"PARTIAL - fewer than 5 records",IF(J18<10,"AMBER - 5 to 9 records","REVIEW FOR GREEN - 10+ records"))) -> UNCALIBRATED | L18: Slope and spoil handling usually worsen in the wet. | M18: Calibrate from Weather Log and obtain estimator/PM approval before GREEN.
... A45: Workshop fabrication / sheltered prep | B45: Building | C45: 0.10 | D45: 0.08 | E45: 0 | F45: 0.02 | G45: 0.08 | H45: 0.20 | I45: AMBER - company judgement | J45: =COUNTIF('Weather Log'!$D$7:$D$206,A45) -> 0 | K45: =IF(J45=0,"UNCALIBRATED",IF(J45<5,"PARTIAL - fewer than 5 records",IF(J45<10,"AMBER - 5 to 9 records","REVIEW FOR GREEN - 10+ records"))) -> UNCALIBRATED | L45: Low but not zero. | M45: Calibrate from Weather Log and obtain estimator/PM approval before GREEN.

Sheet Climate Data
A1: NIWA Climate Data - 1991-2020 Normals | B1: NIWA Climate Data - 1991-2020 Normals | C1: NIWA Climate Data - 1991-2020 Normals | D1: NIWA Climate Data - 1991-2020 Normals | E1: NIWA Climate Data - 1991-2020 Normals | F1: NIWA Climate Data - 1991-2020 Normals | G1: NIWA Climate Data - 1991-2020 Normals | H1: NIWA Climate Data - 1991-2020 Normals | I1: NIWA Climate Data - 1991-2020 Normals | J1: NIWA Climate Data - 1991-2020 Normals
A3: Official NIWA mean monthly wet days and rainfall. Daily wet-day probability is calculated as mean wet days divided by normal calendar days. A wet day is 1 mm or more of rain; it is not automatically a lost construction day.
A6: Location | B6: Month # | C6: Month | D6: Mean Wet Days >=1 mm | E6: Mean Rainfall (mm) | F6: Normal Calendar Days | G6: Daily Wet-Day Probability | H6: Mean Rain per Wet Day (mm) | I6: Source Period | J6: Evidence Status
A7: Kaitaia | B7: 1 | C7: Jan | D7: 6.1363636 | E7: 75 | F7: 31 | G7: =IFERROR(D7/F7,0) -> 0.19794721 | H7: =IFERROR(E7/D7,0) -> 12.222222 | I7: 1991-2020 | J7: GREEN - official NIWA normal
A8: Kaitaia | B8: 2 | C8: Feb | D8: 6.5 | E8: 86 | F8: 28.266667 | G8: =IFERROR(D8/F8,0) -> 0.22995283 | H8: =IFERROR(E8/D8,0) -> 13.230769 | I8: 1991-2020 | J8: GREEN - official NIWA normal
A9: Kaitaia | B9: 3 | C9: Mar | D9: 7.5909091 | E9: 84.7 | F9: 31 | G9: =IFERROR(D9/F9,0) -> 0.24486804 | H9: =IFERROR(E9/D9,0) -> 11.158084 | I9: 1991-2020 | J9: GREEN - official NIWA normal
A10: Kaitaia | B10: 4 | C10: Apr | D10: 10.090909 | E10: 98.8 | F10: 30 | G10: =IFERROR(D10/F10,0) -> 0.33636364 | H10: =IFERROR(E10/D10,0) -> 9.790991 | I10: 1991-2020 | J10: GREEN - official NIWA normal
A11: Kaitaia | B11: 5 | C11: May | D11: 13.227273 | E11: 130.5 | F11: 31 | G11: =IFERROR(D11/F11,0) -> 0.42668622 | H11: =IFERROR(E11/D11,0) -> 9.8659794 | I11: 1991-2020 | J11: GREEN - official NIWA normal
A12: Kaitaia | B12: 6 | C12: Jun | D12: 14.681818 | E12: 149.9 | F12: 30 | G12: =IFERROR(D12/F12,0) -> 0.48939394 | H12: =IFERROR(E12/D12,0) -> 10.209907 | I12: 1991-2020 | J12: GREEN - official NIWA normal
A13: Kaitaia | B13: 7 | C13: Jul | D13: 15.863636 | E13: 168.1 | F13: 31 | G13: =IFERROR(D13/F13,0) -> 0.51173021 | H13: =IFERROR(E13/D13,0) -> 10.596562 | I13: 1991-2020 | J13: GREEN - official NIWA normal
A14: Kaitaia | B14: 8 | C14: Aug | D14: 15.5 | E14: 137 | F14: 31 | G14: =IFERROR(D14/F14,0) -> 0.5 | H14: =IFERROR(E14/D14,0) -> 8.8387097 | I14: 1991-2020 | J14: GREEN - official NIWA normal
A15: Kaitaia | B15: 9 | C15: Sep | D15: 12.772727 | E15: 121.7 | F15: 30 | G15: =IFERROR(D15/F15,0) -> 0.42575758 | H15: =IFERROR(E15/D15,0) -> 9.5281139 | I15: 1991-2020 | J15: GREEN - official NIWA normal
A16: Kaitaia | B16: 10 | C16: Oct | D16: 10.363636 | E16: 90.4 | F16: 31 | G16: =IFERROR(D16/F16,0) -> 0.33431085 | H16: =IFERROR(E16/D16,0) -> 8.722807 | I16: 1991-2020 | J16: GREEN - official NIWA normal
A17: Kaitaia | B17: 11 | C17: Nov | D17: 9.2272727 | E17: 76.3 | F17: 30 | G17: =IFERROR(D17/F17,0) -> 0.30757576 | H17: =IFERROR(E17/D17,0) -> 8.2689655 | I17: 1991-2020 | J17: GREEN - official NIWA normal
A18: Kaitaia | B18: 12 | C18: Dec | D18: 9.8636364 | E18: 101.6 | F18: 31 | G18: =IFERROR(D18/F18,0) -> 0.31818182 | H18: =IFERROR(E18/D18,0) -> 10.300461 | I18: 1991-2020 | J18: GREEN - official NIWA normal
... A366: Chatham Islands | B366: 12 | C366: Dec | D366: 10.125 | E366: 62.9 | F366: 31 | G366: =IFERROR(D366/F366,0) -> 0.3266129 | H366: =IFERROR(E366/D366,0) -> 6.2123457 | I366: 1991-2020 | J366: GREEN - official NIWA normal

Sheet Station Register
A1: NIWA Station Register - 1991-2020 Climate Normals | B1: NIWA Station Register - 1991-2020 Climate Normals | C1: NIWA Station Register - 1991-2020 Climate Normals | D1: NIWA Station Register - 1991-2020 Climate Normals | E1: NIWA Station Register - 1991-2020 Climate Normals | F1: NIWA Station Register - 1991-2020 Climate Normals | G1: NIWA Station Register - 1991-2020 Climate Normals | H1: NIWA Station Register - 1991-2020 Climate Normals
A3: Use the nearest representative station, then record any local site factor and its basis. Rainfall and wet-day station records are shown separately where NIWA used different stations.
A6: Location Selector | B6: Rain Station | C6: Rain Network | D6: Wet-Day Station | E6: Wet-Day Network | F6: Latitude | G6: Longitude | H6: Height (m)
A7: Kaitaia | B7: Kaitaia Ews | C7: A53127 | D7: Kaitaia Ews | E7: A53127 | F7: -35.13352 | G7: 173.26294 | H7: 85
A8: Whangarei | B8: Whangarei Aero Aws | C8: A54737 | D8: Whangarei Aero Aws | E8: A54737 | F8: -35.77062 | G8: 174.36285 | H8: 37
A9: Auckland | B9: Auckland Aero | C9: C74082 | D9: Auckland Aero | E9: C74082 | F9: -37.00813 | G9: 174.78873 | H9: 7
A10: Tauranga | B10: Tauranga Aero Aws | C10: B76624 | D10: Tauranga Aero Aws | E10: B76624 | F10: -37.675 | G10: 176.192 | H10: 2
A11: Hamilton | B11: Hamilton, Ruakura 2 Ews | C11: C75734 | D11: Hamilton, Ruakura 2 Ews | E11: C75734 | F11: -37.77389 | G11: 175.30517 | H11: 45
A12: Rotorua | B12: Rotorua Aero Aws | C12: B86133 | D12: Rotorua Aero Aws | E12: B86133 | F12: -38.10592 | G12: 176.31481 | H12: 286
A13: Gisborne | B13: Gisborne Ews | C13: D87697 | D13: Gisborne Aero Aws | E13: D87695 | F13: -38.6586 | G13: 177.98513 | H13: 5
A14: Taupo | B14: Taupo Aero Aws | C14: B86704 | D14: Taupo Aero Aws | E14: B86704 | F14: -38.74252 | G14: 176.08105 | H14: 402
A15: New Plymouth | B15: New Plymouth Aero Aws | C15: C94012 | D15: New Plymouth Aero Aws | E15: C94012 | F15: -39.00786 | G15: 174.18382 | H15: 28
A16: Napier | B16: Napier Aero Aws | C16: D96484 | D16: Napier Aero Aws | E16: D96484 | F16: -39.47033 | G16: 176.86463 | H16: 3
A17: Whanganui | B17: Whanganui, Spriggens Park Ews | C17: E95902 | D17: Whanganui, Spriggens Park Ews | E17: E95902 | F17: -39.93704 | G17: 175.04509 | H17: 15
A18: Palmerston North | B18: Palmerston North Ews | C18: E0536D | D18: Palmerston North Ews | E18: E0536D | F18: -40.38195 | G18: 175.60915 | H18: 21
... A36: Chatham Islands | B36: Chatham Island Aero Aws | C36: K98617 | D36: Chatham Island Aero Aws | E36: K98617 | F36: -43.81676 | G36: -176.47502 | H36: 12

Sheet Wind Proxy
