Workbook

Sheet Template Guide
A1: MASTER ESTIMATE WORKBOOK - TEMPLATE | B1: Blackline QSi Pro | template Rev1 (14 Oct 2026)
A2: Purpose | B2: Clean master for one job. An external AI (or the estimator) fills it from the tender documents; the Blackline QSi Pro app imports it and recalculates every figure itself.
A3: Instructions | B3: Read instructions/Workbook_Builder_Instructions.md before filling anything. The sheet names, header rows and column positions below are a contract with the app.
A5: CAPACITY
A6: QS Takeoff | B6: Rows 3-202 (one item per row; total on row 203). Formula columns F, G, L-O, R are pre-filled.
A7: Resource Build-Up | B7: Rows 7-306. All formula columns are pre-filled; type only the input columns (see instructions section 5.2).
A8: Resource Rate Library | B8: Rows 5-200. The existing company rates are kept; add rates only with source, date and verification status.
A9: Programme Export | B9: Rows 7-206 follow QS rows 3-202; rows 207-226 are for control tasks (cure, holds) that are not QS items.
A10: Rate Verification | B10: One row per Build-Up row (rows 8-307); fill the evidence columns K-P, T, U.
A11: Tender Build-Up | B11: Type the QS section names in A10:A19 (exactly as written on QS Takeoff). Row 21 must read OK.
A12: Cover & Instructions | B12: Assumptions A1-A15, exclusions EX-01 to EX-08, RFIs RFI-01 to RFI-30, 9 document categories. Copy a row inside a block to add more.
A13: Consolidated Package | B13: Rows 6-11 are subcontract package slots. Row 13 holds a confirmed overlap.
A14: Weather Risk | B14: B13 and B14 are set to =0 in the template. Point them at the Build-Up rows that carry daily time-related preliminaries and weekly hire, e.g. B13 ='Resource Build-Up'!Y22*8 and B14 ='Resource Build-Up'!Y48+'Resource Build-Up'!Y60.
A16: COMPANY DEFAULTS KEPT | B16: Overhead 10% (markup) and profit 15% (true margin) on Commercial Inputs CA17/CA18 are the company's current settings; confirm per job. All other allowances are OFF and zero.
A17: FULL MASTER | B17: All the supporting sheets are present (Summary, Stage Cashflow, Estimate Review Board, ERB Adjudication, Programme Adjudication, Programme Notes, Materials & Component Takeoff, MS Project Import). The app reads what it needs and ignores the rest; they stay for the old workflow and future import.
A18: MS Project Import | B18: Generated from Programme Export: compact rows, predecessors as task IDs (column F), predecessor codes (R) and a helper column (S). Save as CSV (or copy the filled rows) to load into MS Project; the platform reads the same table and builds its programme from it.
... A23: RECALCULATE | B23: After editing, recalculate and save so formulas hold values (LibreOffice: soffice --headless --convert-to xlsx --outdir out file.xlsx).

Sheet Cover & Instructions
A1: TENDER SNAPSHOT / START HERE
A2: ="Working all-in tender excl. GST: "&TEXT('Consolidated Package'!F56,"$#,##0.00")&" | overhead "&TEXT('Commercial Inputs'!D21,"0.0%")&" + profit "&TEXT('Commercial Inputs'!D22,"0.0%")
A4: THE FIRST QUESTION: WHAT WILL THIS COST? | E4: CURRENT COMMERCIAL BUILD-UP
A5: ='Consolidated Package'!F56 | E5: Own works pre-commercial | F5: ='Consolidated Package'!B5
E6: Subcontract packages (known) | F6: =SUM('Consolidated Package'!B6:B11)
E7: Current known cost before OH/profit | F7: ='Consolidated Package'!B56
E8: Company overhead | F8: ='Consolidated Package'!C56
A9: WORKING ALL-IN TENDER, EXCL. GST | E9: Profit | F9: ='Consolidated Package'!E56
E10: WORKING ALL-IN TENDER | F10: ='Consolidated Package'!F56
E11: Gross margin on sell | F11: =IFERROR(('Consolidated Package'!F56-'Consolidated Package'!B56)/'Consolidated Package'!F56,0)
E13: KEY CONTROLS
E14: Own works standalone tender | F14: ='Tender Build-Up'!B47
E15: Management Reserve, pre-margin | F15: ='Commercial Inputs'!E20
E16: Weather allowance | F16: ='Weather Risk'!B38
E17: Dry programme (working days) | F17: ='Weather Risk'!B8
E18: Weather-adjusted planning (days) | F18: ='Weather Risk'!B8+'Weather Risk'!B26
E19: Risk Truth release gate | F19: ='Risk Truth'!B15
A21: HOW TO READ THIS WORKBOOK - SIMPLE WORKFLOW
A22: 1 | B22: Cover & Instructions | C22: Job details, document register, assumptions, exclusions, RFIs, release QA
A23: 2 | B23: Consolidated Package | C23: Own works + subcontract packages + overhead + profit = all-in tender
A24: 3 | B24: QS Takeoff | C24: One row per priced item with quantity, source, status
A25: 4 | B25: Resource Build-Up | C25: How each QS item is built: labour, plant, materials, subcontract, preliminaries
A26: 5 | B26: Commercial Inputs | C26: Allowances, management reserve, overhead, profit, GST
A27: 6 | B27: Tender Build-Up | C27: The commercial stack, calculated
A28: 7 | B28: Risk Truth | C28: Risk register, exposures, duplication controls, release gate
A29: 8 | B29: Weather Risk / Programme Export | C29: Project weather inputs and task durations / logic
A30: 9 | B30: Supplier Quote Register + logs | C30: Quotes, emails, RFIs, documents, decisions, changes
A33: CURRENT RELEASE POSITION
A34: (Write where the estimate stands and what blocks release. List every RED item.)
A38: Project | B38: NOT PROVIDED | D38: Location | E38: NOT PROVIDED
A39: Current drawings | B39: NOT PROVIDED | D39: Issue date | E39: NOT PROVIDED
A40: Scope | B40: NOT PROVIDED | D40: GST | E40: All values shown exclude GST
A41: Programme | B41: NOT PROVIDED | D41: Weather | E41: NOT PROVIDED
A42: Price status | B42: NOT PROVIDED | D42: Commercial | E42: NOT PROVIDED
A44: Risk Truth | B44: Risk-control and reconciliation module. Tracks baseline vs residual exposure, provision routing, duplication and release gate.
A46: DRAWING / DOCUMENT REGISTER
A47: Document / Drawing | B47: Reference | C47: Estimate use
A48: Plans / drawings
A49: Specifications
A50: Geotechnical / ground information
...

Sheet Scope Coverage
A1: Scope ID | B1: Group | C1: Requirement | D1: Detail | E1: Source (document / sheet / page) | F1: Owner | G1: Treatment | H1: Cost refs (QS codes / CA lines) | I1: Register refs (A#, EX-#, RFI-#) | J1: Quote refs | K1: Basis (what was priced and why) | L1: Action
A2: SC-001
A3: SC-002
A4: SC-003
A5: SC-004
A6: SC-005
A7: SC-006
A8: SC-007
A9: SC-008
A10: SC-009
A11: SC-010
A12: SC-011
A13: SC-012
... A301: SC-300

Sheet Summary
A1: ESTIMATE SUMMARY - MASTER ESTIMATE WORKBOOK
A2: WORKING ALL-IN TENDER | B2: ='Consolidated Package'!F56
A4: Current known cost before OH/profit | B4: ='Consolidated Package'!B56 | D4: Project | E4: ='Cover & Instructions'!B38
A5: ="Company OH, "&TEXT('Commercial Inputs'!D21,"0.0%") | B5: ='Consolidated Package'!C56 | D5: Issue | E5: ='Cover & Instructions'!E39
A6: ="Profit, "&TEXT('Commercial Inputs'!D22,"0.0%")&" true margin" | B6: ='Consolidated Package'!E56 | D6: Programme | E6: ='Cover & Instructions'!B41
A7: Siteworks standalone tender | B7: ='Tender Build-Up'!B47 | D7: Weather allowance | E7: ='Weather Risk'!B38
A8: Subcontract packages (known) | B8: =SUM('Consolidated Package'!B6:B11) | D8: Management Reserve | E8: ='Commercial Inputs'!E20
D9: GST | E9: ='Cover & Instructions'!E40
A10: Release status | B10: ='Risk Truth'!B15 | D10: Ground basis
A11: Supplier/material costs within the own-works estimate are already included in the Resource Build-Up; subcontract packages are added once in the Consolidated Package.
A12: Key Quantities
A21: Pricing Summary (direct-cost estimate)
A22: Section | B22: Amount
A23: =IF('Tender Build-Up'!A10="","",1&" "&'Tender Build-Up'!A10) | B23: ='Tender Build-Up'!B10
A24: =IF('Tender Build-Up'!A11="","",2&" "&'Tender Build-Up'!A11) | B24: ='Tender Build-Up'!B11
A25: =IF('Tender Build-Up'!A12="","",3&" "&'Tender Build-Up'!A12) | B25: ='Tender Build-Up'!B12
A26: =IF('Tender Build-Up'!A13="","",4&" "&'Tender Build-Up'!A13) | B26: ='Tender Build-Up'!B13
A27: =IF('Tender Build-Up'!A14="","",5&" "&'Tender Build-Up'!A14) | B27: ='Tender Build-Up'!B14
A28: =IF('Tender Build-Up'!A15="","",6&" "&'Tender Build-Up'!A15) | B28: ='Tender Build-Up'!B15
A29: =IF('Tender Build-Up'!A16="","",7&" "&'Tender Build-Up'!A16) | B29: ='Tender Build-Up'!B16
A30: =IF('Tender Build-Up'!A17="","",8&" "&'Tender Build-Up'!A17) | B30: ='Tender Build-Up'!B17
A31: =IF('Tender Build-Up'!A18="","",9&" "&'Tender Build-Up'!A18) | B31: ='Tender Build-Up'!B18
A32: =IF('Tender Build-Up'!A19="","",10&" "&'Tender Build-Up'!A19) | B32: ='Tender Build-Up'!B19
A33: Total priced amount excl. GST | B33: ='Tender Build-Up'!B20
A34: Pricing basis
A35: GST
A36: Scope
A37: Accuracy
A38: Programme basis
A39: Tender Completion Build-Up (client-adjustable commercial provisions)
A40: Purpose | B40: This block reflects Tender Build-Up and current Commercial Inputs selections.
A41: Input sheet | B41: Use Commercial Inputs to adjust allowances, overhead and profit method, bonds, retention finance and GST.
A43: Line
A44: Base direct estimate excl. GST | B44: ='Tender Build-Up'!B20 | E44: QS direct-cost estimate
A45: Pre-margin additions | B45: ='Tender Build-Up'!B39 | E45: Commercial Inputs CA01-CA16 incl. CA16 Management Reserve
A46: Commercial adjustments | B46: ='Tender Build-Up'!B46 | E46: Commercial Inputs CA17-CA20 commercial adjustments
A47: Tender total excl. GST | B47: ='Tender Build-Up'!B47 | E47: Working tender incl. Management Reserve; excl GST
A48: GST if selected | B48: ='Tender Build-Up'!B48 | E48: Optional display
A49: Tender total incl. GST if selected | B49: ='Tender Build-Up'!B49 | E49: Optional tax-inclusive check
A50: Net pre-GST payment after retention | B50: ='Tender Build-Up'!B53 | E50: Tender total less retention withholding after CA25 deposit treatment.
...

Sheet Consolidated Package
A1: CONSOLIDATED ALL-IN PACKAGE - OWN WORKS + SUBCONTRACT PACKAGES
A2: WORKING ALL-IN TENDER EXCL GST | B2: =F56
A4: Package / Control | B4: Amount excl GST | C4: Classification | D4: Included in Siteworks direct? | E4: Status | F4: Release
A5: Own works current pre-commercial package | B5: ='Tender Build-Up'!B40 | C5: LINKED / CURRENT | D5: Yes | E5: Own works | F5: AMBER / WORKING
C6: QUOTED | D6: No | F6: AMBER
C7: QUOTED | D7: No | F7: AMBER
C8: QUOTED | D8: No | F8: AMBER
C9: QUOTED | D9: No | F9: AMBER
C10: QUOTED | D10: No | F10: AMBER
C11: QUOTED | D11: No | F11: AMBER
A12: GROSS CURRENT KNOWN PACKAGE | B12: =B5+SUM(B6:B11) | C12: CALCULATED | D12: Review total only | E12: Not final tender | F12: HOLD
A13: Confirmed overlap between own works and a package | B13: 0 | C13: CLOSED | D13: None | E13: Interface closed | F13: AMBER / CLOSED
A14: Current known package after overlap | B14: =B12-B13 | C14: CALCULATED | D14: Review only | E14: Not final tender | F14: HOLD
A15: Unpriced packages (see Quote Log) | C15: UNPRICED | D15: No
A16: WORKING ALL-IN TENDER EXCL GST | B16: =F56 | C16: CALCULATED / WORKING | D16: N/A
A20: Rules: one row per subcontract package (rows 6-11; insert more by copying a row). Amount as a number, 'Included in Siteworks direct?' = No, classification QUOTED / QUOTED BASE / CONFIRMED ADDITIONAL / ALLOCATED (never CALCULATED). A package with no price yet stays as a row with no amount and is recorded on the Quote Log.
A54: CURRENT WORKING COMMERCIAL SCENARIO - OVERHEAD AND PROFIT FROM COMMERCIAL INPUTS CA17 / CA18
A55: Scenario | B55: Precommercial cost | C55: Overhead | D55: Subtotal after OH | E55: Profit | F55: Tender excl GST | G55: Commercial uplift
A56: Current known package after overlap | B56: =B14 | C56: =IF('Commercial Inputs'!$F$21<>"Yes",0,IF('Commercial Inputs'!$C$21="Markup %",B56*N('Commercial Inputs'!$D$21),N('Commercial Inputs'!$E$21))) | D56: =B56+C56 | E56: =IF('Commercial Inputs'!$F$22<>"Yes",0,IF('Commercial Inputs'!$C$22="Margin %",D56/(1-N('Commercial Inputs'!$D$22))-D56,IF('Commercial Inputs'!$C$22="Markup %",D56*N('Commercial Inputs'!$D$22),N('Commercial Inputs'!$E$22)))) | F56: =D56+E56 | G56: =F56-B56

Sheet Tender Build-Up
A1: MASTER ESTIMATE WORKBOOK - TENDER BUILD-UP
A3: Project | B3: ='Cover & Instructions'!B38
A4: Pricing status | B4: ='Cover & Instructions'!B42
A5: GST | B5: Optional GST display via Commercial Inputs CA21.
A6: Retention | B6: Cashflow only by default.
A7: No direct-cost values are entered on this sheet. Base costs flow from QS Takeoff; commercial provisions flow from Commercial Inputs.
A9: Base direct estimate (by QS section) | B9: Amount excl. GST | C9: Source | D9: Treatment | E9: Notes
B10: =IF(A10="",0,SUMIF('QS Takeoff'!$A$3:$A$202,A10,'QS Takeoff'!$G$3:$G$202)) | C10: QS Takeoff (type the section name exactly as used on QS Takeoff) | D10: Priced / provisional | E10: Linked QS section total; confirm current project scope, classification, source and firm-up action.
B11: =IF(A11="",0,SUMIF('QS Takeoff'!$A$3:$A$202,A11,'QS Takeoff'!$G$3:$G$202)) | C11: QS Takeoff (type the section name exactly as used on QS Takeoff) | D11: Priced / provisional | E11: Linked QS section total; confirm current project ESC scope and requirements.
B12: =IF(A12="",0,SUMIF('QS Takeoff'!$A$3:$A$202,A12,'QS Takeoff'!$G$3:$G$202)) | C12: QS Takeoff (type the section name exactly as used on QS Takeoff) | D12: Priced / provisional | E12: Linked QS section total; confirm current project quantities, ground basis, haul and disposal assumptions.
B13: =IF(A13="",0,SUMIF('QS Takeoff'!$A$3:$A$202,A13,'QS Takeoff'!$G$3:$G$202)) | C13: QS Takeoff (type the section name exactly as used on QS Takeoff) | D13: Priced / provisional | E13: Linked QS section total; confirm current project stormwater / detention design and supplier requirements.
B14: =IF(A14="",0,SUMIF('QS Takeoff'!$A$3:$A$202,A14,'QS Takeoff'!$G$3:$G$202)) | C14: QS Takeoff (type the section name exactly as used on QS Takeoff) | D14: Priced / provisional | E14: Linked QS section total; confirm current project wastewater / water scope and authority interfaces.
B15: =IF(A15="",0,SUMIF('QS Takeoff'!$A$3:$A$202,A15,'QS Takeoff'!$G$3:$G$202)) | C15: QS Takeoff (type the section name exactly as used on QS Takeoff) | D15: Priced / provisional | E15: Linked QS section total; confirm current project pavement / concrete scope and specification.
B16: =IF(A16="",0,SUMIF('QS Takeoff'!$A$3:$A$202,A16,'QS Takeoff'!$G$3:$G$202)) | C16: QS Takeoff (type the section name exactly as used on QS Takeoff) | D16: Priced / provisional | E16: Linked QS section total; confirm current project kerb / external sitework scope.
B17: =IF(A17="",0,SUMIF('QS Takeoff'!$A$3:$A$202,A17,'QS Takeoff'!$G$3:$G$202)) | C17: QS Takeoff (type the section name exactly as used on QS Takeoff) | D17: Priced / provisional | E17: Linked QS section total; confirm current project retaining-wall design, quantities and temporary works.
B18: =IF(A18="",0,SUMIF('QS Takeoff'!$A$3:$A$202,A18,'QS Takeoff'!$G$3:$G$202)) | C18: QS Takeoff (type the section name exactly as used on QS Takeoff) | D18: Priced / provisional | E18: Linked QS section total; confirm current testing, survey, as-built and compliance obligations.
B19: =IF(A19="",0,SUMIF('QS Takeoff'!$A$3:$A$202,A19,'QS Takeoff'!$G$3:$G$202)) | C19: QS Takeoff (type the section name exactly as used on QS Takeoff) | D19: Priced / provisional | E19: Linked QS section total; confirm current reinstatement, defects and handover obligations.
A20: Base direct estimate excl. GST | B20: =SUM('QS Takeoff'!$G$3:$G$202) | D20: Subtotal | E20: Direct cost sourced from Resource Build-Up through QS Takeoff; includes measured, provisional, allowance and PC items.
A21: Check: QS sections not listed above (must be zero) | B21: =ROUND(B20-SUM(B10:B19),2) | C21: =IF(B21=0,"OK","CHECK - list every QS section above")
A22: Pre-margin additions | B22: Calculated amount excl. GST | C22: Input source | D22: Include? | E22: Basis / Notes
A23: CA01 - Design / scope residual risk - Risk Truth | B23: =IF('Commercial Inputs'!$F$5<>"Yes",0,IF(OR('Commercial Inputs'!$C$5="Risk Engine",'Commercial Inputs'!$C$5="Weather Engine"),N('Commercial Inputs'!$L$5),IF('Commercial Inputs'!$C$5="PC Sum",N('Commercial Inputs'!$E$5),IF('Commercial Inputs'!$C$5="%",$B$20*N('Commercial Inputs'!$D$5),0)))) | C23: ='Commercial Inputs'!C5 | D23: ='Commercial Inputs'!F5 | E23: CA01 defaults to Risk Truth. PC Sum or % may be selected as a stated adjudication override; Include? controls whether the selected treatment enters the tender.
A24: CA02 - Construction / execution residual risk - Risk Truth | B24: =IF('Commercial Inputs'!$F$6<>"Yes",0,IF(OR('Commercial Inputs'!$C$6="Risk Engine",'Commercial Inputs'!$C$6="Weather Engine"),N('Commercial Inputs'!$L$6),IF('Commercial Inputs'!$C$6="PC Sum",N('Commercial Inputs'!$E$6),IF('Commercial Inputs'!$C$6="%",$B$20*N('Commercial Inputs'!$D$6),0)))) | C24: ='Commercial Inputs'!C6 | D24: ='Commercial Inputs'!F6 | E24: CA02 defaults to Risk Truth. PC Sum or % may be selected as a stated adjudication override; Include? controls whether the selected treatment enters the tender.
A25: ='Commercial Inputs'!A7&" - "&'Commercial Inputs'!B7 | B25: =IF('Commercial Inputs'!$F$7<>"Yes",0,IF(OR('Commercial Inputs'!$C$7="Risk Engine",'Commercial Inputs'!$C$7="Weather Engine"),N('Commercial Inputs'!$L$7),IF('Commercial Inputs'!$C$7="PC Sum",N('Commercial Inputs'!$E$7),IF('Commercial Inputs'!$C$7="%",$B$20*N('Commercial Inputs'!$D$7),0)))) | C25: ='Commercial Inputs'!C7 | D25: ='Commercial Inputs'!F7 | E25: ='Commercial Inputs'!I7
A26: ='Commercial Inputs'!A8&" - "&'Commercial Inputs'!B8 | B26: =IF('Commercial Inputs'!$F$8<>"Yes",0,IF(OR('Commercial Inputs'!$C$8="Risk Engine",'Commercial Inputs'!$C$8="Weather Engine"),N('Commercial Inputs'!$L$8),IF('Commercial Inputs'!$C$8="PC Sum",N('Commercial Inputs'!$E$8),IF('Commercial Inputs'!$C$8="%",$B$20*N('Commercial Inputs'!$D$8),0)))) | C26: ='Commercial Inputs'!C8 | D26: ='Commercial Inputs'!F8 | E26: ='Commercial Inputs'!I8
A27: ='Commercial Inputs'!A9&" - "&'Commercial Inputs'!B9 | B27: =IF('Commercial Inputs'!$F$9<>"Yes",0,IF(OR('Commercial Inputs'!$C$9="Risk Engine",'Commercial Inputs'!$C$9="Weather Engine"),N('Commercial Inputs'!$L$9),IF('Commercial Inputs'!$C$9="PC Sum",N('Commercial Inputs'!$E$9),IF('Commercial Inputs'!$C$9="%",$B$20*N('Commercial Inputs'!$D$9),0)))) | C27: ='Commercial Inputs'!C9 | D27: ='Commercial Inputs'!F9 | E27: ='Commercial Inputs'!I9
A28: ='Commercial Inputs'!A10&" - "&'Commercial Inputs'!B10 | B28: =IF('Commercial Inputs'!$F$10<>"Yes",0,IF(OR('Commercial Inputs'!$C$10="Risk Engine",'Commercial Inputs'!$C$10="Weather Engine"),N('Commercial Inputs'!$L$10),IF('Commercial Inputs'!$C$10="PC Sum",N('Commercial Inputs'!$E$10),IF('Commercial Inputs'!$C$10="%",$B$20*N('Commercial Inputs'!$D$10),0)))) | C28: ='Commercial Inputs'!C10 | D28: ='Commercial Inputs'!F10 | E28: ='Commercial Inputs'!I10
A29: ='Commercial Inputs'!A11&" - "&'Commercial Inputs'!B11 | B29: =IF('Commercial Inputs'!$F$11<>"Yes",0,IF(OR('Commercial Inputs'!$C$11="Risk Engine",'Commercial Inputs'!$C$11="Weather Engine"),N('Commercial Inputs'!$L$11),IF('Commercial Inputs'!$C$11="PC Sum",N('Commercial Inputs'!$E$11),IF('Commercial Inputs'!$C$11="%",$B$20*N('Commercial Inputs'!$D$11),0)))) | C29: ='Commercial Inputs'!C11 | D29: ='Commercial Inputs'!F11 | E29: ='Commercial Inputs'!I11
A30: CA08 - Abnormal ground / contamination / rock allowance | B30: =IF('Commercial Inputs'!$F$12<>"Yes",0,IF(OR('Commercial Inputs'!$C$12="Risk Engine",'Commercial Inputs'!$C$12="Weather Engine"),N('Commercial Inputs'!$L$12),IF('Commercial Inputs'!$C$12="PC Sum",N('Commercial Inputs'!$E$12),IF('Commercial Inputs'!$C$12="%",$B$20*N('Commercial Inputs'!$D$12),0)))) | C30: ='Commercial Inputs'!C12 | D30: ='Commercial Inputs'!F12 | E30: No generic ground percentage. Use only an explicit evidence-based provision not more truthfully placed in QS or a specialist engine.
A31: ='Commercial Inputs'!A13&" - "&'Commercial Inputs'!B13 | B31: =IF('Commercial Inputs'!$F$13<>"Yes",0,IF(OR('Commercial Inputs'!$C$13="Risk Engine",'Commercial Inputs'!$C$13="Weather Engine"),N('Commercial Inputs'!$L$13),IF('Commercial Inputs'!$C$13="PC Sum",N('Commercial Inputs'!$E$13),IF('Commercial Inputs'!$C$13="%",$B$20*N('Commercial Inputs'!$D$13),0)))) | C31: ='Commercial Inputs'!C13 | D31: ='Commercial Inputs'!F13 | E31: Project-specific construction water-control provision only; check overlap with Weather / Ground risk treatment.
A32: ='Commercial Inputs'!A14&" - "&'Commercial Inputs'!B14 | B32: =IF('Commercial Inputs'!$F$14<>"Yes",0,IF(OR('Commercial Inputs'!$C$14="Risk Engine",'Commercial Inputs'!$C$14="Weather Engine"),N('Commercial Inputs'!$L$14),IF('Commercial Inputs'!$C$14="PC Sum",N('Commercial Inputs'!$E$14),IF('Commercial Inputs'!$C$14="%",$B$20*N('Commercial Inputs'!$D$14),0)))) | C32: ='Commercial Inputs'!C14 | D32: ='Commercial Inputs'!F14 | E32: CA10 defaults to Weather Engine. PC Sum or % may be selected explicitly; Include? can turn the weather allowance off while the engine output remains retained for audit.
A33: ='Commercial Inputs'!A15&" - "&'Commercial Inputs'!B15 | B33: =IF('Commercial Inputs'!$F$15<>"Yes",0,IF(OR('Commercial Inputs'!$C$15="Risk Engine",'Commercial Inputs'!$C$15="Weather Engine"),N('Commercial Inputs'!$L$15),IF('Commercial Inputs'!$C$15="PC Sum",N('Commercial Inputs'!$E$15),IF('Commercial Inputs'!$C$15="%",$B$20*N('Commercial Inputs'!$D$15),0)))) | C33: ='Commercial Inputs'!C15 | D33: ='Commercial Inputs'!F15 | E33: ='Commercial Inputs'!I15
A34: ='Commercial Inputs'!A16&" - "&'Commercial Inputs'!B16 | B34: =IF('Commercial Inputs'!$F$16<>"Yes",0,IF(OR('Commercial Inputs'!$C$16="Risk Engine",'Commercial Inputs'!$C$16="Weather Engine"),N('Commercial Inputs'!$L$16),IF('Commercial Inputs'!$C$16="PC Sum",N('Commercial Inputs'!$E$16),IF('Commercial Inputs'!$C$16="%",$B$20*N('Commercial Inputs'!$D$16),0)))) | C34: ='Commercial Inputs'!C16 | D34: ='Commercial Inputs'!F16 | E34: Reasonable defects / closeout attendance is included under RH01.
A35: ='Commercial Inputs'!A17&" - "&'Commercial Inputs'!B17 | B35: =IF('Commercial Inputs'!$F$17<>"Yes",0,IF(OR('Commercial Inputs'!$C$17="Risk Engine",'Commercial Inputs'!$C$17="Weather Engine"),N('Commercial Inputs'!$L$17),IF('Commercial Inputs'!$C$17="PC Sum",N('Commercial Inputs'!$E$17),IF('Commercial Inputs'!$C$17="%",$B$20*N('Commercial Inputs'!$D$17),0)))) | C35: ='Commercial Inputs'!C17 | D35: ='Commercial Inputs'!F17 | E35: Basic Siteworks traffic / pedestrian / access controls are included within the itemised PG01 preliminaries.
A36: ='Commercial Inputs'!A18&" - "&'Commercial Inputs'!B18 | B36: =IF('Commercial Inputs'!$F$18<>"Yes",0,IF(OR('Commercial Inputs'!$C$18="Risk Engine",'Commercial Inputs'!$C$18="Weather Engine"),N('Commercial Inputs'!$L$18),IF('Commercial Inputs'!$C$18="PC Sum",N('Commercial Inputs'!$E$18),IF('Commercial Inputs'!$C$18="%",$B$20*N('Commercial Inputs'!$D$18),0)))) | C36: ='Commercial Inputs'!C18 | D36: ='Commercial Inputs'!F18 | E36: ='Commercial Inputs'!I18
A37: ='Commercial Inputs'!A19&" - "&'Commercial Inputs'!B19 | B37: =IF('Commercial Inputs'!$F$19<>"Yes",0,IF(OR('Commercial Inputs'!$C$19="Risk Engine",'Commercial Inputs'!$C$19="Weather Engine"),N('Commercial Inputs'!$L$19),IF('Commercial Inputs'!$C$19="PC Sum",N('Commercial Inputs'!$E$19),IF('Commercial Inputs'!$C$19="%",$B$20*N('Commercial Inputs'!$D$19),0)))) | C37: ='Commercial Inputs'!C19 | D37: ='Commercial Inputs'!F19 | E37: ='Commercial Inputs'!I19
A38: ='Commercial Inputs'!A20&" - "&'Commercial Inputs'!B20 | B38: =IF('Commercial Inputs'!$F$20<>"Yes",0,IF(OR('Commercial Inputs'!$C$20="Risk Engine",'Commercial Inputs'!$C$20="Weather Engine"),N('Commercial Inputs'!$L$20),IF(OR('Commercial Inputs'!$C$20="PC Sum",'Commercial Inputs'!$C$20="Fixed Amount"),N('Commercial Inputs'!$E$20),IF('Commercial Inputs'!$C$20="%",$B$20*N('Commercial Inputs'!$D$20),0)))) | C38: ='Commercial Inputs'!C20 | D38: ='Commercial Inputs'!F20 | E38: PROVIDED / AMBER management adjudication reserve
A39: Pre-margin additions subtotal | B39: =SUM(B23:B38)
A40: Subtotal before commercial adjustments | B40: =B20+B39
A41: Overhead, profit and other commercial adjustments | B41: Calculated amount excl. GST | C41: Input source | D41: Include? | E41: Basis / Notes
A42: ='Commercial Inputs'!A21&" - "&'Commercial Inputs'!B21 | B42: =IF('Commercial Inputs'!$F$21<>"Yes",0,IF('Commercial Inputs'!$C$21="Markup %",$B$40*N('Commercial Inputs'!$D$21),IF('Commercial Inputs'!$C$21="Fixed Amount",N('Commercial Inputs'!$E$21),0))) | C42: ='Commercial Inputs'!C21 | D42: ='Commercial Inputs'!F21
...

Sheet Commercial Inputs
A1: COMMERCIAL INPUTS - BELOW-THE-LINE SOURCE OF TRUTH | H1: Profit method | I1: =C22
H2: CA18 method (linked) | I2: =IF(C22="Margin %","Margin",IF(C22="Markup %","Markup",IF(C22="Fixed Amount","Fixed Amount",C22))) | J2: The calculation method is selected in column C. There is no second profit-method selector.
A3: CA01/CA02: Risk Engine, PC Sum or %. CA10: Weather Engine, PC Sum or %. Other pre-margin allowances: PC Sum or %. Column F Include? is the on/off switch. Engine outputs remain live in column L even when another method is selected, preserving the audit trail.
A4: Ref | B4: Allowance / adjustment | C4: Input method | D4: Input % | E4: PC Sum excl. GST | F4: Include? | G4: Pricing stage | H4: Calculation / treatment | I4: Notes / basis | J4: Firm-up action | K4: Pricing method / flag shown in QS | L4: Engine Amount excl. GST | M4: Engine Source / Status
A5: CA01 | B5: Design / scope residual risk - Risk Truth linked | C5: Risk Engine | F5: Yes | G5: Pre-margin addition | H5: =IF(C5="Risk Engine","Uses linked Risk Truth engine amount in L5",IF(C5="Weather Engine","Uses linked Weather Risk amount in L5",IF(C5="PC Sum","Uses manual PC Sum in E5",IF(C5="%","Uses Input % in D5 against base direct cost","CHECK METHOD")))) | I5: Residual design/scope risk only where the consequence cannot be more truthfully placed in Resource Build-Up/QS or a specialist engine. | J5: Close Risk Truth RED items and confirm residual is distinct / integration complete. | K5: =IF(F5<>"Yes",C5&" - OFF",C5) | L5: ='Risk Truth'!$B$12
A6: CA02 | B6: Construction / execution residual risk - Risk Truth linked | C6: Risk Engine | F6: Yes | G6: Pre-margin addition | H6: =IF(C6="Risk Engine","Uses linked Risk Truth engine amount in L6",IF(C6="Weather Engine","Uses linked Weather Risk amount in L6",IF(C6="PC Sum","Uses manual PC Sum in E6",IF(C6="%","Uses Input % in D6 against base direct cost","CHECK METHOD")))) | I6: Residual construction/execution risk only where the consequence cannot be more truthfully placed in Resource Build-Up/QS or a specialist engine. | J6: Close Risk Truth RED items and confirm residual is distinct / integration complete. | K6: =IF(F6<>"Yes",C6&" - OFF",C6) | L6: ='Risk Truth'!$B$13
A7: CA03 | B7: Escalation / tender validity allowance | C7: % | F7: No | G7: Pre-margin addition | H7: =IF(C7="Risk Engine","Uses linked Risk Truth engine amount in L7",IF(C7="Weather Engine","Uses linked Weather Risk amount in L7",IF(C7="PC Sum","Uses manual PC Sum in E7",IF(C7="%","Uses Input % in D7 against base direct cost","CHECK METHOD")))) | I7: Enter only where escalation is evidence-based; do not default to a generic percentage. | J7: Confirm construction start and validity. | K7: =IF(F7<>"Yes",C7&" - OFF",C7)
A8: CA04 | B8: Final subcontractor quote gap / market adjustment | C8: PC Sum | F8: No | G8: Pre-margin addition | H8: =IF(C8="Risk Engine","Uses linked Risk Truth engine amount in L8",IF(C8="Weather Engine","Uses linked Weather Risk amount in L8",IF(C8="PC Sum","Uses manual PC Sum in E8",IF(C8="%","Uses Input % in D8 against base direct cost","CHECK METHOD")))) | I8: Use only for a distinct reconciled live-quote gap not already included in QS/PC items or Risk Truth. | J8: Use only after supplier quote returns are reconciled and a distinct uncovered market gap is evidenced. | K8: =IF(F8<>"Yes",C8&" - OFF",C8)
A9: CA05 | B9: Council / authority consent and inspection fees | C9: PC Sum | F9: No | G9: Pre-margin addition | H9: =IF(C9="Risk Engine","Uses linked Risk Truth engine amount in L9",IF(C9="Weather Engine","Uses linked Weather Risk amount in L9",IF(C9="PC Sum","Uses manual PC Sum in E9",IF(C9="%","Uses Input % in D9 against base direct cost","CHECK METHOD")))) | I9: Confirm contractual responsibility before inclusion. | J9: Confirm fee responsibility. | K9: =IF(F9<>"Yes",C9&" - OFF",C9)
A10: CA06 | B10: Utility authority fees / relocations | C10: PC Sum | F10: No | G10: Pre-margin addition | H10: =IF(C10="Risk Engine","Uses linked Risk Truth engine amount in L10",IF(C10="Weather Engine","Uses linked Weather Risk amount in L10",IF(C10="PC Sum","Uses manual PC Sum in E10",IF(C10="%","Uses Input % in D10 against base direct cost","CHECK METHOD")))) | I10: Confirm contractual responsibility; physical construction scope should normally sit in QS. | J10: Confirm utilities. | K10: =IF(F10<>"Yes",C10&" - OFF",C10)
A11: CA07 | B11: Temporary works engineering / PS documentation | C11: PC Sum | F11: No | G11: Pre-margin addition | H11: =IF(C11="Risk Engine","Uses linked Risk Truth engine amount in L11",IF(C11="Weather Engine","Uses linked Weather Risk amount in L11",IF(C11="PC Sum","Uses manual PC Sum in E11",IF(C11="%","Uses Input % in D11 against base direct cost","CHECK METHOD")))) | I11: Use only for temporary-works engineering / documentation not already in direct scope. | J11: Avoid duplication. | K11: =IF(F11<>"Yes",C11&" - OFF",C11)
A12: CA08 | B12: Abnormal ground / contamination / rock allowance | C12: PC Sum | F12: No | G12: Pre-margin addition | H12: =IF(C12="Risk Engine","Uses linked Risk Truth engine amount in L12",IF(C12="Weather Engine","Uses linked Weather Risk amount in L12",IF(C12="PC Sum","Uses manual PC Sum in E12",IF(C12="%","Uses Input % in D12 against base direct cost","CHECK METHOD")))) | I12: Do not use as a generic ground-risk percentage. Quantifiable ground consequences belong in QS or an approved specialist risk treatment. | J12: Review geotech/contamination data. | K12: =IF(F12<>"Yes",C12&" - OFF",C12)
A13: CA09 | B13: Construction dewatering / groundwater control | C13: PC Sum | F13: No | G13: Pre-margin addition | H13: =IF(C13="Risk Engine","Uses linked Risk Truth engine amount in L13",IF(C13="Weather Engine","Uses linked Weather Risk amount in L13",IF(C13="PC Sum","Uses manual PC Sum in E13",IF(C13="%","Uses Input % in D13 against base direct cost","CHECK METHOD")))) | I13: Construction water / dewatering PC pending final programme/groundwater conditions. Distinct from normal weather CA10. | J13: Firm methodology after earthworks programme and site conditions are confirmed. | K13: =IF(F13<>"Yes",C13&" - OFF",C13)
A14: CA10 | B14: Weather risk allowance - linked approved engine | C14: Weather Engine | F14: Yes | G14: Pre-margin addition | H14: =IF(C14="Risk Engine","Uses linked Risk Truth engine amount in L14",IF(C14="Weather Engine","Uses linked Weather Risk amount in L14",IF(C14="PC Sum","Uses manual PC Sum in E14",IF(C14="%","Uses Input % in D14 against base direct cost","CHECK METHOD")))) | I14: Weather Risk engine feeds this line when the method is Weather Engine. | J14: Rerun the weather tool when the start date, programme or weather-exposed scope changes. | K14: Weather Engine - AMBER / CURRENT TENDER SCENARIO | L14: ='Weather Risk'!$B$40 | M14: Weather tool run recorded on Weather Risk (CA10 engine feed)
A15: CA11 | B15: Extended preliminaries beyond weather-adjusted tender baseline | C15: PC Sum | F15: No | G15: Pre-margin addition | H15: =IF(C15="Risk Engine","Uses linked Risk Truth engine amount in L15",IF(C15="Weather Engine","Uses linked Weather Risk amount in L15",IF(C15="PC Sum","Uses manual PC Sum in E15",IF(C15="%","Uses Input % in D15 against base direct cost","CHECK METHOD")))) | I15: Do not use for weather delay already treated through CA10. | J15: Add only for non-weather instructed extension or revised contract programme after checking CA10 overlap. | K15: =IF(F15<>"Yes",C15&" - OFF",C15)
A16: CA12 | B16: Defects liability / maintenance beyond base | C16: PC Sum | F16: No | G16: Pre-margin addition | H16: =IF(C16="Risk Engine","Uses linked Risk Truth engine amount in L16",IF(C16="Weather Engine","Uses linked Weather Risk amount in L16",IF(C16="PC Sum","Uses manual PC Sum in E16",IF(C16="%","Uses Input % in D16 against base direct cost","CHECK METHOD")))) | I16: Reasonable defects / closeout attendance is carried in RH01. | J16: Confirm special maintenance obligations. | K16: =IF(F16<>"Yes",C16&" - OFF",C16)
A17: CA13 | B17: Stakeholder liaison / access marshals beyond base | C17: PC Sum | F17: No | G17: Pre-margin addition | H17: =IF(C17="Risk Engine","Uses linked Risk Truth engine amount in L17",IF(C17="Weather Engine","Uses linked Weather Risk amount in L17",IF(C17="PC Sum","Uses manual PC Sum in E17",IF(C17="%","Uses Input % in D17 against base direct cost","CHECK METHOD")))) | I17: Basic Siteworks traffic / pedestrian / access controls are carried within the itemised PG01 preliminaries. | J17: Confirm restricted operations. | K17: =IF(F17<>"Yes",C17&" - OFF",C17)
A18: CA14 | B18: Out-of-hours / restricted access premium | C18: PC Sum | F18: No | G18: Pre-margin addition | H18: =IF(C18="Risk Engine","Uses linked Risk Truth engine amount in L18",IF(C18="Weather Engine","Uses linked Weather Risk amount in L18",IF(C18="PC Sum","Uses manual PC Sum in E18",IF(C18="%","Uses Input % in D18 against base direct cost","CHECK METHOD")))) | I18: Normal weekday access assumed. | J18: Confirm work windows. | K18: =IF(F18<>"Yes",C18&" - OFF",C18)
A19: CA15 | B19: Unforeseen post-tender client scope additions | C19: PC Sum | F19: No | G19: Pre-margin addition | H19: =IF(C19="Risk Engine","Uses linked Risk Truth engine amount in L19",IF(C19="Weather Engine","Uses linked Weather Risk amount in L19",IF(C19="PC Sum","Uses manual PC Sum in E19",IF(C19="%","Uses Input % in D19 against base direct cost","CHECK METHOD")))) | I19: No allowance for later scope changes. | J19: Include only if instructed. | K19: =IF(F19<>"Yes",C19&" - OFF",C19)
A20: CA16 | B20: Management Reserve - residual tender-stage uncertainty (adjudication) | C20: Fixed Amount | F20: No | G20: Pre-margin adjudication provision | H20: =IF(C20="Fixed Amount","Uses fixed management reserve in E20",IF(C20="Risk Engine","Uses linked Risk Truth engine amount in L20",IF(C20="Weather Engine","Uses linked Weather Risk amount in L20",IF(C20="PC Sum","Uses manual PC Sum in E20",IF(C20="%","Uses Input % in D20 against base direct cost","CHECK METHOD"))))) | I20: PROVIDED management reserve selected at tender adjudication. Purpose: protect the tender against aggregate residual tender-stage uncertainty and unknown-unknowns that remain after known/measurable scope, PCs, quoted packages, Weather Risk and Risk Truth treatments have already been allowed. It is not a Risk Truth contingency and does not close or downgrade any RED item. | J20: Reassess whenever a RED is resolved, a material scope/quantity/rate changes, or before contract award. If an exposure becomes measurable, price the actual consequence in the correct cost line and reassess the reserve rather than automatically consuming it. | K20: Fixed Amount - PROVIDED / AMBER / 4.0% ADJUDICATION BASIS
A21: CA17 | B21: Company overhead recovery | C21: Markup % | D21: 0.1 | F21: Yes | G21: Commercial adjustment | H21: 10% markup applied to subtotal before profit | I21: Company overhead recovery, applied as markup to the subtotal before profit. Set per job. | J21: Review against Siteworks actual overhead recovery when company financial basis is available; no tender hold created by this user-provided input. | K21: Markup % - PROVIDED / WORKING BASIS
A22: CA18 | B22: Contractor profit | C22: Margin % | D22: 0.15 | F22: Yes | G22: Commercial adjustment | H22: 15% TRUE MARGIN after overhead and other selected commercial costs | I22: Contractor profit as true margin after overhead and other selected allowances. Set per job. | J22: Change only if Siteworks instructs a different profit method/rate. | K22: Margin % - PROVIDED / WORKING BASIS
A23: CA19 | B23: Bonds / contract securities allowance | C23: % | F23: No | G23: Commercial adjustment | H23: Applied if selected | I23: Include only where contract securities create a genuine contractor cost. | J23: Confirm security terms. | K23: % user input provision
A24: CA20 | B24: Retention finance / cashflow cost allowance | C24: % | F24: No | G24: Commercial adjustment | H24: Applied if selected | I24: Finance cost only; retention withholding itself is a cashflow item. | J24: Confirm retention terms. | K24: % user input provision
A25: CA21 | B25: GST | C25: % | D25: 0.15 | F25: No | G25: Tax | H25: Applied to tender total if selected | I25: Optional tax display. Set 15% for NZ GST or 10% for Australian GST when applicable; estimate control total remains ex tax. | J25: Confirm submission format. | K25: % user input provision
A26: CA22 | B26: Contract retention withholding | C26: % | D26: 0 | F26: No | G26: Cashflow only | H26: Visibility only | I26: Not added to tender price. | J26: Confirm retention cap/terms. | K26: User input
A27: CA23 | B27: Retention holding period | C27: Months | D27: 0 | F27: No | G27: Cashflow only | H27: Times retention release | I27: No retention holding period assumed; CA23 remains 0 until contract terms are supplied. | J27: Confirm contract. | K27: % user input provision
A28: CA24 | B28: Deposit / advance payment | I28: Used as first cashflow stage. | J28: Confirm whether permitted. | K28: User selection
A29: CA25 | B29: Retention applies to deposit | I29: Normally No. | J29: Confirm contract.
A30: Notes
A31: 1 | B31: Leave Include? as No for any provision that is not to be included. Enter Input % or PC Sum depending on the intended basis; PC Sum overrides % where populated.
A32: MANAGEMENT RESERVE - ADJUDICATION BASIS
A33: Control | B33: Value | C33: Classification | D33: Basis / meaning | E33: Unresolved item 1 RED | F33: Unresolved item 2 RED | G33: Unresolved item 3 RED | H33: Unresolved item 4 RED
A34: Reserve base
A35: Selected reserve rate
A36: Pre-OH/profit Management Reserve
A37: Tender effect of reserve
A38: Probability note | B38: N/A | D38: Do not weight any item with a probability unless it is evidenced. Unknown probability = sensitivity only, never an expected value.
A39: Consumption rule | B39: N/A | D39: Do not automatically consume the reserve when a risk resolves; Rick adjudicates any change under change control.

Sheet QS Takeoff
A1: QS TAKEOFF - MASTER ESTIMATE WORKBOOK - RESOURCE-LINKED | L1: Rate and Amount are linked from Resource Build-Up. One row per priced item; the section name goes on every row. Do not type over the grey formula columns.
A2: Civil Scope / WBS | B2: Code | C2: Description | D2: Unit | E2: Quantity | F2: Rate excl. GST | G2: Amount excl. GST | H2: Quantity Basis | I2: Source drawing / scope | J2: Status | K2: Notes / Assumptions | L2: Pricing Method | M2: Pricing Basis / Build-up | N2: Source Type | O2: Source URL(s) | P2: Pricing Flag | Q2: Confidence / Firm-up Action | R2: Owner | S2: Verification Status | T2: Quote / Reference
F3: =IF(B3="","",IF(E3=0,0,G3/E3)) | G3: =IF(B3="","",SUMIF('Resource Build-Up'!$B$7:$B$306,B3,'Resource Build-Up'!$Z$7:$Z$306)) | L3: =IF(B3="","",IF(J3="Excluded","Excluded","Resource-linked")) | M3: =IF(B3="","",IF(G3=0,"No resource cost / review","Resource Build-Up -> "&B3)) | N3: =IF(B3="","","Resource Build-Up") | O3: =IF(B3="","","See Resource Build-Up / Resource Rate Library") | R3: =IF(OR(ISNUMBER(SEARCH("PC",P3)),ISNUMBER(SEARCH("quote",Q3))),"Jason","Rick")
F4: =IF(B4="","",IF(E4=0,0,G4/E4)) | G4: =IF(B4="","",SUMIF('Resource Build-Up'!$B$7:$B$306,B4,'Resource Build-Up'!$Z$7:$Z$306)) | L4: =IF(B4="","",IF(J4="Excluded","Excluded","Resource-linked")) | M4: =IF(B4="","",IF(G4=0,"No resource cost / review","Resource Build-Up -> "&B4)) | N4: =IF(B4="","","Resource Build-Up") | O4: =IF(B4="","","See Resource Build-Up / Resource Rate Library") | R4: =IF(OR(ISNUMBER(SEARCH("PC",P4)),ISNUMBER(SEARCH("quote",Q4))),"Jason","Rick")
F5: =IF(B5="","",IF(E5=0,0,G5/E5)) | G5: =IF(B5="","",SUMIF('Resource Build-Up'!$B$7:$B$306,B5,'Resource Build-Up'!$Z$7:$Z$306)) | L5: =IF(B5="","",IF(J5="Excluded","Excluded","Resource-linked")) | M5: =IF(B5="","",IF(G5=0,"No resource cost / review","Resource Build-Up -> "&B5)) | N5: =IF(B5="","","Resource Build-Up") | O5: =IF(B5="","","See Resource Build-Up / Resource Rate Library") | R5: =IF(OR(ISNUMBER(SEARCH("PC",P5)),ISNUMBER(SEARCH("quote",Q5))),"Jason","Rick")
F6: =IF(B6="","",IF(E6=0,0,G6/E6)) | G6: =IF(B6="","",SUMIF('Resource Build-Up'!$B$7:$B$306,B6,'Resource Build-Up'!$Z$7:$Z$306)) | L6: =IF(B6="","",IF(J6="Excluded","Excluded","Resource-linked")) | M6: =IF(B6="","",IF(G6=0,"No resource cost / review","Resource Build-Up -> "&B6)) | N6: =IF(B6="","","Resource Build-Up") | O6: =IF(B6="","","See Resource Build-Up / Resource Rate Library") | R6: =IF(OR(ISNUMBER(SEARCH("PC",P6)),ISNUMBER(SEARCH("quote",Q6))),"Jason","Rick")
F7: =IF(B7="","",IF(E7=0,0,G7/E7)) | G7: =IF(B7="","",SUMIF('Resource Build-Up'!$B$7:$B$306,B7,'Resource Build-Up'!$Z$7:$Z$306)) | L7: =IF(B7="","",IF(J7="Excluded","Excluded","Resource-linked")) | M7: =IF(B7="","",IF(G7=0,"No resource cost / review","Resource Build-Up -> "&B7)) | N7: =IF(B7="","","Resource Build-Up") | O7: =IF(B7="","","See Resource Build-Up / Resource Rate Library") | R7: =IF(OR(ISNUMBER(SEARCH("PC",P7)),ISNUMBER(SEARCH("quote",Q7))),"Jason","Rick")
F8: =IF(B8="","",IF(E8=0,0,G8/E8)) | G8: =IF(B8="","",SUMIF('Resource Build-Up'!$B$7:$B$306,B8,'Resource Build-Up'!$Z$7:$Z$306)) | L8: =IF(B8="","",IF(J8="Excluded","Excluded","Resource-linked")) | M8: =IF(B8="","",IF(G8=0,"No resource cost / review","Resource Build-Up -> "&B8)) | N8: =IF(B8="","","Resource Build-Up") | O8: =IF(B8="","","See Resource Build-Up / Resource Rate Library") | R8: =IF(OR(ISNUMBER(SEARCH("PC",P8)),ISNUMBER(SEARCH("quote",Q8))),"Jason","Rick")
F9: =IF(B9="","",IF(E9=0,0,G9/E9)) | G9: =IF(B9="","",SUMIF('Resource Build-Up'!$B$7:$B$306,B9,'Resource Build-Up'!$Z$7:$Z$306)) | L9: =IF(B9="","",IF(J9="Excluded","Excluded","Resource-linked")) | M9: =IF(B9="","",IF(G9=0,"No resource cost / review","Resource Build-Up -> "&B9)) | N9: =IF(B9="","","Resource Build-Up") | O9: =IF(B9="","","See Resource Build-Up / Resource Rate Library") | R9: =IF(OR(ISNUMBER(SEARCH("PC",P9)),ISNUMBER(SEARCH("quote",Q9))),"Jason","Rick")
F10: =IF(B10="","",IF(E10=0,0,G10/E10)) | G10: =IF(B10="","",SUMIF('Resource Build-Up'!$B$7:$B$306,B10,'Resource Build-Up'!$Z$7:$Z$306)) | L10: =IF(B10="","",IF(J10="Excluded","Excluded","Resource-linked")) | M10: =IF(B10="","",IF(G10=0,"No resource cost / review","Resource Build-Up -> "&B10)) | N10: =IF(B10="","","Resource Build-Up") | O10: =IF(B10="","","See Resource Build-Up / Resource Rate Library") | R10: =IF(OR(ISNUMBER(SEARCH("PC",P10)),ISNUMBER(SEARCH("quote",Q10))),"Jason","Rick")
F11: =IF(B11="","",IF(E11=0,0,G11/E11)) | G11: =IF(B11="","",SUMIF('Resource Build-Up'!$B$7:$B$306,B11,'Resource Build-Up'!$Z$7:$Z$306)) | L11: =IF(B11="","",IF(J11="Excluded","Excluded","Resource-linked")) | M11: =IF(B11="","",IF(G11=0,"No resource cost / review","Resource Build-Up -> "&B11)) | N11: =IF(B11="","","Resource Build-Up") | O11: =IF(B11="","","See Resource Build-Up / Resource Rate Library") | R11: =IF(OR(ISNUMBER(SEARCH("PC",P11)),ISNUMBER(SEARCH("quote",Q11))),"Jason","Rick")
F12: =IF(B12="","",IF(E12=0,0,G12/E12)) | G12: =IF(B12="","",SUMIF('Resource Build-Up'!$B$7:$B$306,B12,'Resource Build-Up'!$Z$7:$Z$306)) | L12: =IF(B12="","",IF(J12="Excluded","Excluded","Resource-linked")) | M12: =IF(B12="","",IF(G12=0,"No resource cost / review","Resource Build-Up -> "&B12)) | N12: =IF(B12="","","Resource Build-Up") | O12: =IF(B12="","","See Resource Build-Up / Resource Rate Library") | R12: =IF(OR(ISNUMBER(SEARCH("PC",P12)),ISNUMBER(SEARCH("quote",Q12))),"Jason","Rick")
F13: =IF(B13="","",IF(E13=0,0,G13/E13)) | G13: =IF(B13="","",SUMIF('Resource Build-Up'!$B$7:$B$306,B13,'Resource Build-Up'!$Z$7:$Z$306)) | L13: =IF(B13="","",IF(J13="Excluded","Excluded","Resource-linked")) | M13: =IF(B13="","",IF(G13=0,"No resource cost / review","Resource Build-Up -> "&B13)) | N13: =IF(B13="","","Resource Build-Up") | O13: =IF(B13="","","See Resource Build-Up / Resource Rate Library") | R13: =IF(OR(ISNUMBER(SEARCH("PC",P13)),ISNUMBER(SEARCH("quote",Q13))),"Jason","Rick")
F14: =IF(B14="","",IF(E14=0,0,G14/E14)) | G14: =IF(B14="","",SUMIF('Resource Build-Up'!$B$7:$B$306,B14,'Resource Build-Up'!$Z$7:$Z$306)) | L14: =IF(B14="","",IF(J14="Excluded","Excluded","Resource-linked")) | M14: =IF(B14="","",IF(G14=0,"No resource cost / review","Resource Build-Up -> "&B14)) | N14: =IF(B14="","","Resource Build-Up") | O14: =IF(B14="","","See Resource Build-Up / Resource Rate Library") | R14: =IF(OR(ISNUMBER(SEARCH("PC",P14)),ISNUMBER(SEARCH("quote",Q14))),"Jason","Rick")
... F202: =IF(B202="","",IF(E202=0,0,G202/E202)) | G202: =IF(B202="","",SUMIF('Resource Build-Up'!$B$7:$B$306,B202,'Resource Build-Up'!$Z$7:$Z$306)) | L202: =IF(B202="","",IF(J202="Excluded","Excluded","Resource-linked")) | M202: =IF(B202="","",IF(G202=0,"No resource cost / review","Resource Build-Up -> "&B202)) | N202: =IF(B202="","","Resource Build-Up") | O202: =IF(B202="","","See Resource Build-Up / Resource Rate Library") | R202: =IF(OR(ISNUMBER(SEARCH("PC",P202)),ISNUMBER(SEARCH("quote",Q202))),"Jason","Rick")
A203: TOTAL DIRECT COST | G203: =SUM(G3:G202)

Sheet Resource Build-Up
A1: RESOURCE BUILD-UP - MASTER ESTIMATE WORKBOOK - LINKED COST / DURATION FORMULAS
A2: Every active QS Code must have resource rows here. Extended Cost totals by QS Code are pulled into QS Takeoff; do not type a second QS rate or amount.
A3: Ordinary civil plant stays Plant whether owned or hired. Specialist delivered capability such as mobile cranes is normally Subcontract. Wet hire must record operator/fuel inclusions to stop double counting.
A4: Calculation modes: Time x Count; QS Qty x Factor; Direct Qty; Lump Sum / Quote. Duration is derived from quantity/productivity or explicitly overridden where sequencing requires it.
A5: Weather controls: AK:AM are estimator inputs; AN is formula-controlled exposed Labour/Plant cost feeding Weather Risk. Materials, fixed subcontract and Other costs are excluded from direct weather productivity by default.
A6: Build-Up Row ID | B6: QS Code | C6: WBS / Section | D6: Task Description | E6: QS Qty | F6: QS Unit | G6: Estimate Class | H6: Methodology / Work Step | I6: Productivity Rate | J6: Productivity Unit | K6: Calc Duration hrs | L6: Duration Override hrs | M6: Applied Duration hrs | N6: Calculation Mode | O6: Resource Type | P6: Resource Code | Q6: Resource Description | R6: Resource Count / Factor | S6: Manual Resource Qty | T6: Resource Unit | U6: Utilisation % | V6: Waste % | W6: Library Rate | X6: Job Rate Override | Y6: Applied Rate | Z6: Extended Cost | AA6: Library Source | AB6: Job Quote / Source Ref | AC6: Source Date | AD6: Operator Included? | AE6: Fuel Included? | AF6: Confidence | AG6: Assumption / RFI | AH6: Verified? | AI6: QA / Double-Count Check | AJ6: Notes | AK6: Weather Exposed? | AL6: Weather Task Type | AM6: Weather Basis / Status | AN6: Weather-Exposed Labour + Plant Cost
A7: =IF(B7="","",B7&"-"&TEXT(COUNTIF($B$7:B7,B7),"000")) | C7: =IFERROR(INDEX('QS Takeoff'!$A$3:$A$202,MATCH(B7,'QS Takeoff'!$B$3:$B$202,0)),"") | D7: =IFERROR(INDEX('QS Takeoff'!$C$3:$C$202,MATCH(B7,'QS Takeoff'!$B$3:$B$202,0)),"") | E7: =IFERROR(INDEX('QS Takeoff'!$E$3:$E$202,MATCH(B7,'QS Takeoff'!$B$3:$B$202,0)),"") | F7: =IFERROR(INDEX('QS Takeoff'!$D$3:$D$202,MATCH(B7,'QS Takeoff'!$B$3:$B$202,0)),"") | G7: =IFERROR(INDEX('QS Takeoff'!$J$3:$J$202,MATCH(B7,'QS Takeoff'!$B$3:$B$202,0)),"") | K7: =IF(OR(B7="",I7="",I7=0),"",E7/I7) | M7: =IF(L7>0,L7,K7) | Q7: =IFERROR(INDEX('Resource Rate Library'!$C$5:$C$200,MATCH(P7,'Resource Rate Library'!$A$5:$A$200,0)),"") | T7: =IFERROR(INDEX('Resource Rate Library'!$E$5:$E$200,MATCH(P7,'Resource Rate Library'!$A$5:$A$200,0)),"") | W7: =IFERROR(INDEX('Resource Rate Library'!$I$5:$I$200,MATCH(P7,'Resource Rate Library'!$A$5:$A$200,0)),0) | Y7: =IF(X7>0,X7,W7) | Z7: =IF(B7="","",IF(N7="Time x Count",M7*R7*IF(U7="",1,U7)*Y7,IF(N7="QS Qty x Factor",E7*R7*(1+IF(V7="",0,V7))*Y7,IF(N7="Direct Qty",S7*(1+IF(V7="",0,V7))*Y7,IF(N7="Lump Sum / Quote",S7*Y7,0))))) | AA7: =IFERROR(INDEX('Resource Rate Library'!$N$5:$N$200,MATCH(P7,'Resource Rate Library'!$A$5:$A$200,0)),"") | AD7: =IFERROR(INDEX('Resource Rate Library'!$G$5:$G$200,MATCH(P7,'Resource Rate Library'!$A$5:$A$200,0)),"") | AE7: =IFERROR(INDEX('Resource Rate Library'!$H$5:$H$200,MATCH(P7,'Resource Rate Library'!$A$5:$A$200,0)),"") | AI7: =IF(B7="","",IF(AND(P7="",N7<>"Lump Sum / Quote"),"RESOURCE CODE",IF(Y7=0,"RATE MISSING",IF(AND(O7="Plant",AD7="Yes",COUNTIFS($B$7:$B$306,B7,$O$7:$O$306,"Labour",$Q$7:$Q$306,"*Operator*")>0),"OPERATOR DOUBLE-COUNT",IF(AND(O7="Plant",AE7="Yes",COUNTIFS($B$7:$B$306,B7,$Q$7:$Q$306,"*Fuel*")>0),"FUEL DOUBLE-COUNT",IF(AH7<>"Yes","VERIFY","OK")))))) | AN7: =IF(AND(AK7="Yes",OR(O7="Labour",O7="Plant")),Z7,0)
A8: =IF(B8="","",B8&"-"&TEXT(COUNTIF($B$7:B8,B8),"000")) | C8: =IFERROR(INDEX('QS Takeoff'!$A$3:$A$202,MATCH(B8,'QS Takeoff'!$B$3:$B$202,0)),"") | D8: =IFERROR(INDEX('QS Takeoff'!$C$3:$C$202,MATCH(B8,'QS Takeoff'!$B$3:$B$202,0)),"") | E8: =IFERROR(INDEX('QS Takeoff'!$E$3:$E$202,MATCH(B8,'QS Takeoff'!$B$3:$B$202,0)),"") | F8: =IFERROR(INDEX('QS Takeoff'!$D$3:$D$202,MATCH(B8,'QS Takeoff'!$B$3:$B$202,0)),"") | G8: =IFERROR(INDEX('QS Takeoff'!$J$3:$J$202,MATCH(B8,'QS Takeoff'!$B$3:$B$202,0)),"") | K8: =IF(OR(B8="",I8="",I8=0),"",E8/I8) | M8: =IF(L8>0,L8,K8) | Q8: =IFERROR(INDEX('Resource Rate Library'!$C$5:$C$200,MATCH(P8,'Resource Rate Library'!$A$5:$A$200,0)),"") | T8: =IFERROR(INDEX('Resource Rate Library'!$E$5:$E$200,MATCH(P8,'Resource Rate Library'!$A$5:$A$200,0)),"") | W8: =IFERROR(INDEX('Resource Rate Library'!$I$5:$I$200,MATCH(P8,'Resource Rate Library'!$A$5:$A$200,0)),0) | Y8: =IF(X8>0,X8,W8) | Z8: =IF(B8="","",IF(N8="Time x Count",M8*R8*IF(U8="",1,U8)*Y8,IF(N8="QS Qty x Factor",E8*R8*(1+IF(V8="",0,V8))*Y8,IF(N8="Direct Qty",S8*(1+IF(V8="",0,V8))*Y8,IF(N8="Lump Sum / Quote",S8*Y8,0))))) | AA8: =IFERROR(INDEX('Resource Rate Library'!$N$5:$N$200,MATCH(P8,'Resource Rate Library'!$A$5:$A$200,0)),"") | AD8: =IFERROR(INDEX('Resource Rate Library'!$G$5:$G$200,MATCH(P8,'Resource Rate Library'!$A$5:$A$200,0)),"") | AE8: =IFERROR(INDEX('Resource Rate Library'!$H$5:$H$200,MATCH(P8,'Resource Rate Library'!$A$5:$A$200,0)),"") | AI8: =IF(B8="","",IF(AND(P8="",N8<>"Lump Sum / Quote"),"RESOURCE CODE",IF(Y8=0,"RATE MISSING",IF(AND(O8="Plant",AD8="Yes",COUNTIFS($B$7:$B$306,B8,$O$7:$O$306,"Labour",$Q$7:$Q$306,"*Operator*")>0),"OPERATOR DOUBLE-COUNT",IF(AND(O8="Plant",AE8="Yes",COUNTIFS($B$7:$B$306,B8,$Q$7:$Q$306,"*Fuel*")>0),"FUEL DOUBLE-COUNT",IF(AH8<>"Yes","VERIFY","OK")))))) | AN8: =IF(AND(AK8="Yes",OR(O8="Labour",O8="Plant")),Z8,0)
A9: =IF(B9="","",B9&"-"&TEXT(COUNTIF($B$7:B9,B9),"000")) | C9: =IFERROR(INDEX('QS Takeoff'!$A$3:$A$202,MATCH(B9,'QS Takeoff'!$B$3:$B$202,0)),"") | D9: =IFERROR(INDEX('QS Takeoff'!$C$3:$C$202,MATCH(B9,'QS Takeoff'!$B$3:$B$202,0)),"") | E9: =IFERROR(INDEX('QS Takeoff'!$E$3:$E$202,MATCH(B9,'QS Takeoff'!$B$3:$B$202,0)),"") | F9: =IFERROR(INDEX('QS Takeoff'!$D$3:$D$202,MATCH(B9,'QS Takeoff'!$B$3:$B$202,0)),"") | G9: =IFERROR(INDEX('QS Takeoff'!$J$3:$J$202,MATCH(B9,'QS Takeoff'!$B$3:$B$202,0)),"") | K9: =IF(OR(B9="",I9="",I9=0),"",E9/I9) | M9: =IF(L9>0,L9,K9) | Q9: =IFERROR(INDEX('Resource Rate Library'!$C$5:$C$200,MATCH(P9,'Resource Rate Library'!$A$5:$A$200,0)),"") | T9: =IFERROR(INDEX('Resource Rate Library'!$E$5:$E$200,MATCH(P9,'Resource Rate Library'!$A$5:$A$200,0)),"") | W9: =IFERROR(INDEX('Resource Rate Library'!$I$5:$I$200,MATCH(P9,'Resource Rate Library'!$A$5:$A$200,0)),0) | Y9: =IF(X9>0,X9,W9) | Z9: =IF(B9="","",IF(N9="Time x Count",M9*R9*IF(U9="",1,U9)*Y9,IF(N9="QS Qty x Factor",E9*R9*(1+IF(V9="",0,V9))*Y9,IF(N9="Direct Qty",S9*(1+IF(V9="",0,V9))*Y9,IF(N9="Lump Sum / Quote",S9*Y9,0))))) | AA9: =IFERROR(INDEX('Resource Rate Library'!$N$5:$N$200,MATCH(P9,'Resource Rate Library'!$A$5:$A$200,0)),"") | AD9: =IFERROR(INDEX('Resource Rate Library'!$G$5:$G$200,MATCH(P9,'Resource Rate Library'!$A$5:$A$200,0)),"") | AE9: =IFERROR(INDEX('Resource Rate Library'!$H$5:$H$200,MATCH(P9,'Resource Rate Library'!$A$5:$A$200,0)),"") | AI9: =IF(B9="","",IF(AND(P9="",N9<>"Lump Sum / Quote"),"RESOURCE CODE",IF(Y9=0,"RATE MISSING",IF(AND(O9="Plant",AD9="Yes",COUNTIFS($B$7:$B$306,B9,$O$7:$O$306,"Labour",$Q$7:$Q$306,"*Operator*")>0),"OPERATOR DOUBLE-COUNT",IF(AND(O9="Plant",AE9="Yes",COUNTIFS($B$7:$B$306,B9,$Q$7:$Q$306,"*Fuel*")>0),"FUEL DOUBLE-COUNT",IF(AH9<>"Yes","VERIFY","OK")))))) | AN9: =IF(AND(AK9="Yes",OR(O9="Labour",O9="Plant")),Z9,0)
A10: =IF(B10="","",B10&"-"&TEXT(COUNTIF($B$7:B10,B10),"000")) | C10: =IFERROR(INDEX('QS Takeoff'!$A$3:$A$202,MATCH(B10,'QS Takeoff'!$B$3:$B$202,0)),"") | D10: =IFERROR(INDEX('QS Takeoff'!$C$3:$C$202,MATCH(B10,'QS Takeoff'!$B$3:$B$202,0)),"") | E10: =IFERROR(INDEX('QS Takeoff'!$E$3:$E$202,MATCH(B10,'QS Takeoff'!$B$3:$B$202,0)),"") | F10: =IFERROR(INDEX('QS Takeoff'!$D$3:$D$202,MATCH(B10,'QS Takeoff'!$B$3:$B$202,0)),"") | G10: =IFERROR(INDEX('QS Takeoff'!$J$3:$J$202,MATCH(B10,'QS Takeoff'!$B$3:$B$202,0)),"") | K10: =IF(OR(B10="",I10="",I10=0),"",E10/I10) | M10: =IF(L10>0,L10,K10) | Q10: =IFERROR(INDEX('Resource Rate Library'!$C$5:$C$200,MATCH(P10,'Resource Rate Library'!$A$5:$A$200,0)),"") | T10: =IFERROR(INDEX('Resource Rate Library'!$E$5:$E$200,MATCH(P10,'Resource Rate Library'!$A$5:$A$200,0)),"") | W10: =IFERROR(INDEX('Resource Rate Library'!$I$5:$I$200,MATCH(P10,'Resource Rate Library'!$A$5:$A$200,0)),0) | Y10: =IF(X10>0,X10,W10) | Z10: =IF(B10="","",IF(N10="Time x Count",M10*R10*IF(U10="",1,U10)*Y10,IF(N10="QS Qty x Factor",E10*R10*(1+IF(V10="",0,V10))*Y10,IF(N10="Direct Qty",S10*(1+IF(V10="",0,V10))*Y10,IF(N10="Lump Sum / Quote",S10*Y10,0))))) | AA10: =IFERROR(INDEX('Resource Rate Library'!$N$5:$N$200,MATCH(P10,'Resource Rate Library'!$A$5:$A$200,0)),"") | AD10: =IFERROR(INDEX('Resource Rate Library'!$G$5:$G$200,MATCH(P10,'Resource Rate Library'!$A$5:$A$200,0)),"") | AE10: =IFERROR(INDEX('Resource Rate Library'!$H$5:$H$200,MATCH(P10,'Resource Rate Library'!$A$5:$A$200,0)),"") | AI10: =IF(B10="","",IF(AND(P10="",N10<>"Lump Sum / Quote"),"RESOURCE CODE",IF(Y10=0,"RATE MISSING",IF(AND(O10="Plant",AD10="Yes",COUNTIFS($B$7:$B$306,B10,$O$7:$O$306,"Labour",$Q$7:$Q$306,"*Operator*")>0),"OPERATOR DOUBLE-COUNT",IF(AND(O10="Plant",AE10="Yes",COUNTIFS($B$7:$B$306,B10,$Q$7:$Q$306,"*Fuel*")>0),"FUEL DOUBLE-COUNT",IF(AH10<>"Yes","VERIFY","OK")))))) | AN10: =IF(AND(AK10="Yes",OR(O10="Labour",O10="Plant")),Z10,0)
A11: =IF(B11="","",B11&"-"&TEXT(COUNTIF($B$7:B11,B11),"000")) | C11: =IFERROR(INDEX('QS Takeoff'!$A$3:$A$202,MATCH(B11,'QS Takeoff'!$B$3:$B$202,0)),"") | D11: =IFERROR(INDEX('QS Takeoff'!$C$3:$C$202,MATCH(B11,'QS Takeoff'!$B$3:$B$202,0)),"") | E11: =IFERROR(INDEX('QS Takeoff'!$E$3:$E$202,MATCH(B11,'QS Takeoff'!$B$3:$B$202,0)),"") | F11: =IFERROR(INDEX('QS Takeoff'!$D$3:$D$202,MATCH(B11,'QS Takeoff'!$B$3:$B$202,0)),"") | G11: =IFERROR(INDEX('QS Takeoff'!$J$3:$J$202,MATCH(B11,'QS Takeoff'!$B$3:$B$202,0)),"") | K11: =IF(OR(B11="",I11="",I11=0),"",E11/I11) | M11: =IF(L11>0,L11,K11) | Q11: =IFERROR(INDEX('Resource Rate Library'!$C$5:$C$200,MATCH(P11,'Resource Rate Library'!$A$5:$A$200,0)),"") | T11: =IFERROR(INDEX('Resource Rate Library'!$E$5:$E$200,MATCH(P11,'Resource Rate Library'!$A$5:$A$200,0)),"") | W11: =IFERROR(INDEX('Resource Rate Library'!$I$5:$I$200,MATCH(P11,'Resource Rate Library'!$A$5:$A$200,0)),0) | Y11: =IF(X11>0,X11,W11) | Z11: =IF(B11="","",IF(N11="Time x Count",M11*R11*IF(U11="",1,U11)*Y11,IF(N11="QS Qty x Factor",E11*R11*(1+IF(V11="",0,V11))*Y11,IF(N11="Direct Qty",S11*(1+IF(V11="",0,V11))*Y11,IF(N11="Lump Sum / Quote",S11*Y11,0))))) | AA11: =IFERROR(INDEX('Resource Rate Library'!$N$5:$N$200,MATCH(P11,'Resource Rate Library'!$A$5:$A$200,0)),"") | AD11: =IFERROR(INDEX('Resource Rate Library'!$G$5:$G$200,MATCH(P11,'Resource Rate Library'!$A$5:$A$200,0)),"") | AE11: =IFERROR(INDEX('Resource Rate Library'!$H$5:$H$200,MATCH(P11,'Resource Rate Library'!$A$5:$A$200,0)),"") | AI11: =IF(B11="","",IF(AND(P11="",N11<>"Lump Sum / Quote"),"RESOURCE CODE",IF(Y11=0,"RATE MISSING",IF(AND(O11="Plant",AD11="Yes",COUNTIFS($B$7:$B$306,B11,$O$7:$O$306,"Labour",$Q$7:$Q$306,"*Operator*")>0),"OPERATOR DOUBLE-COUNT",IF(AND(O11="Plant",AE11="Yes",COUNTIFS($B$7:$B$306,B11,$Q$7:$Q$306,"*Fuel*")>0),"FUEL DOUBLE-COUNT",IF(AH11<>"Yes","VERIFY","OK")))))) | AN11: =IF(AND(AK11="Yes",OR(O11="Labour",O11="Plant")),Z11,0)
A12: =IF(B12="","",B12&"-"&TEXT(COUNTIF($B$7:B12,B12),"000")) | C12: =IFERROR(INDEX('QS Takeoff'!$A$3:$A$202,MATCH(B12,'QS Takeoff'!$B$3:$B$202,0)),"") | D12: =IFERROR(INDEX('QS Takeoff'!$C$3:$C$202,MATCH(B12,'QS Takeoff'!$B$3:$B$202,0)),"") | E12: =IFERROR(INDEX('QS Takeoff'!$E$3:$E$202,MATCH(B12,'QS Takeoff'!$B$3:$B$202,0)),"") | F12: =IFERROR(INDEX('QS Takeoff'!$D$3:$D$202,MATCH(B12,'QS Takeoff'!$B$3:$B$202,0)),"") | G12: =IFERROR(INDEX('QS Takeoff'!$J$3:$J$202,MATCH(B12,'QS Takeoff'!$B$3:$B$202,0)),"") | K12: =IF(OR(B12="",I12="",I12=0),"",E12/I12) | M12: =IF(L12>0,L12,K12) | Q12: =IFERROR(INDEX('Resource Rate Library'!$C$5:$C$200,MATCH(P12,'Resource Rate Library'!$A$5:$A$200,0)),"") | T12: =IFERROR(INDEX('Resource Rate Library'!$E$5:$E$200,MATCH(P12,'Resource Rate Library'!$A$5:$A$200,0)),"") | W12: =IFERROR(INDEX('Resource Rate Library'!$I$5:$I$200,MATCH(P12,'Resource Rate Library'!$A$5:$A$200,0)),0) | Y12: =IF(X12>0,X12,W12) | Z12: =IF(B12="","",IF(N12="Time x Count",M12*R12*IF(U12="",1,U12)*Y12,IF(N12="QS Qty x Factor",E12*R12*(1+IF(V12="",0,V12))*Y12,IF(N12="Direct Qty",S12*(1+IF(V12="",0,V12))*Y12,IF(N12="Lump Sum / Quote",S12*Y12,0))))) | AA12: =IFERROR(INDEX('Resource Rate Library'!$N$5:$N$200,MATCH(P12,'Resource Rate Library'!$A$5:$A$200,0)),"") | AD12: =IFERROR(INDEX('Resource Rate Library'!$G$5:$G$200,MATCH(P12,'Resource Rate Library'!$A$5:$A$200,0)),"") | AE12: =IFERROR(INDEX('Resource Rate Library'!$H$5:$H$200,MATCH(P12,'Resource Rate Library'!$A$5:$A$200,0)),"") | AI12: =IF(B12="","",IF(AND(P12="",N12<>"Lump Sum / Quote"),"RESOURCE CODE",IF(Y12=0,"RATE MISSING",IF(AND(O12="Plant",AD12="Yes",COUNTIFS($B$7:$B$306,B12,$O$7:$O$306,"Labour",$Q$7:$Q$306,"*Operator*")>0),"OPERATOR DOUBLE-COUNT",IF(AND(O12="Plant",AE12="Yes",COUNTIFS($B$7:$B$306,B12,$Q$7:$Q$306,"*Fuel*")>0),"FUEL DOUBLE-COUNT",IF(AH12<>"Yes","VERIFY","OK")))))) | AN12: =IF(AND(AK12="Yes",OR(O12="Labour",O12="Plant")),Z12,0)
